WARNING:tensorflow:Mapping types may not work well with tf.nest. Prefer using MutableMapping for <class 'tensorflow_gnn.graph.graph_tensor._ImmutableMapping'>
WARNING:tensorflow:Mapping types may not work well with tf.nest. Prefer using MutableMapping for <class 'tensorflow_gnn.graph.graph_tensor._ImmutableMapping'>
WARNING:tensorflow:Mapping types may not work well with tf.nest. Prefer using MutableMapping for <class 'tensorflow_gnn.graph.graph_tensor._ImmutableMapping'>
WARNING:tensorflow:Mapping types may not work well with tf.nest. Prefer using MutableMapping for <class 'tensorflow_gnn.graph.graph_tensor._ImmutableMapping'>
WARNING:tensorflow:Mapping types may not work well with tf.nest. Prefer using MutableMapping for <class 'tensorflow_gnn.graph.graph_tensor._ImmutableMapping'>
WARNING:tensorflow:Mapping types may not work well with tf.nest. Prefer using MutableMapping for <class 'tensorflow_gnn.graph.graph_tensor._ImmutableMapping'>
WARNING:tensorflow:Mapping types may not work well with tf.nest. Prefer using MutableMapping for <class 'tensorflow_gnn.graph.graph_tensor._ImmutableMapping'>
WARNING:tensorflow:Mapping types may not work well with tf.nest. Prefer using MutableMapping for <class 'tensorflow_gnn.graph.graph_tensor._ImmutableMapping'>
WARNING:tensorflow:Mapping types may not work well with tf.nest. Prefer using MutableMapping for <class 'tensorflow_gnn.graph.graph_tensor._ImmutableMapping'>
WARNING:tensorflow:Mapping types may not work well with tf.nest. Prefer using MutableMapping for <class 'tensorflow_gnn.graph.graph_tensor._ImmutableMapping'>
WARNING:tensorflow:Mapping types may not work well with tf.nest. Prefer using MutableMapping for <class 'tensorflow_gnn.graph.graph_tensor._ImmutableMapping'>
WARNING:tensorflow:Mapping types may not work well with tf.nest. Prefer using MutableMapping for <class 'tensorflow_gnn.graph.graph_tensor._ImmutableMapping'>
Traceback (most recent call last):
  File "/home/fidels/miniconda3/envs/graph2tac/bin/g2t-server", line 33, in <module>
    sys.exit(load_entry_point('graph2tac', 'console_scripts', 'g2t-server')())
  File "/home/fidels/graph2tac/graph2tac/loader/predict_server.py", line 712, in main
    main_loop(reader, sock, predict, args.debug_dir,
  File "/home/fidels/graph2tac/graph2tac/loader/predict_server.py", line 372, in main_loop
    predict.compute_new_definitions([cluster_state])
  File "/home/fidels/graph2tac/graph2tac/predict.py", line 38, in api_call_with_debug
    return api_call(self, *args, **kwargs)
  File "/home/fidels/graph2tac/graph2tac/tfgnn/predict.py", line 273, in compute_new_definitions
    definition_embeddings = self.definition_task(scalar_definition_graph).flat_values
  File "/home/fidels/miniconda3/envs/graph2tac/lib/python3.10/site-packages/keras/utils/traceback_utils.py", line 67, in error_handler
    raise e.with_traceback(filtered_tb) from None
  File "/home/fidels/graph2tac/graph2tac/tfgnn/tasks.py", line 740, in call
    hidden_graph = self._gnn(masked_embedded_graph, training=training)
  File "/home/fidels/graph2tac/graph2tac/tfgnn/models.py", line 551, in call
    embedded_graph = convolution(embedded_graph, training=training)
  File "/home/fidels/miniconda3/envs/graph2tac/lib/python3.10/site-packages/tensorflow_gnn/keras/layers/graph_update.py", line 235, in call
    update_fn(graph, node_set_name=node_set_name)))
  File "/home/fidels/miniconda3/envs/graph2tac/lib/python3.10/site-packages/tensorflow_gnn/keras/layers/graph_update.py", line 417, in call
    input_from_edge_sets[edge_set_name] = input_fn(
  File "/home/fidels/miniconda3/envs/graph2tac/lib/python3.10/site-packages/tensorflow_gnn/keras/layers/convolution_base.py", line 311, in call
    return self.convolve(
  File "/home/fidels/miniconda3/envs/graph2tac/lib/python3.10/site-packages/tensorflow_gnn/keras/layers/convolutions.py", line 126, in convolve
    messages = self._message_fn(combined_input)
tensorflow.python.framework.errors_impl.InternalError: Exception encountered when calling layer "dense" (type Dense).

Attempting to perform BLAS operation using StreamExecutor without BLAS support [Op:MatMul]

Call arguments received by layer "dense" (type Dense):
  • inputs=tf.Tensor(shape=(7, 384), dtype=float32)
Traceback (most recent call last):
  File "/home/fidels/miniconda3/envs/graph2tac/bin/g2t-server", line 33, in <module>
    sys.exit(load_entry_point('graph2tac', 'console_scripts', 'g2t-server')())
  File "/home/fidels/graph2tac/graph2tac/loader/predict_server.py", line 712, in main
    main_loop(reader, sock, predict, args.debug_dir,
  File "/home/fidels/graph2tac/graph2tac/loader/predict_server.py", line 372, in main_loop
    predict.compute_new_definitions([cluster_state])
  File "/home/fidels/graph2tac/graph2tac/predict.py", line 38, in api_call_with_debug
    return api_call(self, *args, **kwargs)
  File "/home/fidels/graph2tac/graph2tac/tfgnn/predict.py", line 273, in compute_new_definitions
    definition_embeddings = self.definition_task(scalar_definition_graph).flat_values
  File "/home/fidels/miniconda3/envs/graph2tac/lib/python3.10/site-packages/keras/utils/traceback_utils.py", line 67, in error_handler
    raise e.with_traceback(filtered_tb) from None
  File "/home/fidels/graph2tac/graph2tac/tfgnn/tasks.py", line 740, in call
    hidden_graph = self._gnn(masked_embedded_graph, training=training)
  File "/home/fidels/graph2tac/graph2tac/tfgnn/models.py", line 551, in call
    embedded_graph = convolution(embedded_graph, training=training)
  File "/home/fidels/miniconda3/envs/graph2tac/lib/python3.10/site-packages/tensorflow_gnn/keras/layers/graph_update.py", line 235, in call
    update_fn(graph, node_set_name=node_set_name)))
  File "/home/fidels/miniconda3/envs/graph2tac/lib/python3.10/site-packages/tensorflow_gnn/keras/layers/graph_update.py", line 417, in call
    input_from_edge_sets[edge_set_name] = input_fn(
  File "/home/fidels/miniconda3/envs/graph2tac/lib/python3.10/site-packages/tensorflow_gnn/keras/layers/convolution_base.py", line 311, in call
    return self.convolve(
  File "/home/fidels/miniconda3/envs/graph2tac/lib/python3.10/site-packages/tensorflow_gnn/keras/layers/convolutions.py", line 126, in convolve
    messages = self._message_fn(combined_input)
tensorflow.python.framework.errors_impl.InternalError: Exception encountered when calling layer "dense" (type Dense).

Attempting to perform BLAS operation using StreamExecutor without BLAS support [Op:MatMul]

Call arguments received by layer "dense" (type Dense):
  • inputs=tf.Tensor(shape=(7, 384), dtype=float32)
Traceback (most recent call last):
  File "/home/fidels/miniconda3/envs/graph2tac/bin/g2t-server", line 33, in <module>
    sys.exit(load_entry_point('graph2tac', 'console_scripts', 'g2t-server')())
  File "/home/fidels/graph2tac/graph2tac/loader/predict_server.py", line 712, in main
    main_loop(reader, sock, predict, args.debug_dir,
  File "/home/fidels/graph2tac/graph2tac/loader/predict_server.py", line 372, in main_loop
    predict.compute_new_definitions([cluster_state])
  File "/home/fidels/graph2tac/graph2tac/predict.py", line 38, in api_call_with_debug
    return api_call(self, *args, **kwargs)
  File "/home/fidels/graph2tac/graph2tac/tfgnn/predict.py", line 273, in compute_new_definitions
    definition_embeddings = self.definition_task(scalar_definition_graph).flat_values
  File "/home/fidels/miniconda3/envs/graph2tac/lib/python3.10/site-packages/keras/utils/traceback_utils.py", line 67, in error_handler
    raise e.with_traceback(filtered_tb) from None
  File "/home/fidels/graph2tac/graph2tac/tfgnn/tasks.py", line 740, in call
    hidden_graph = self._gnn(masked_embedded_graph, training=training)
  File "/home/fidels/graph2tac/graph2tac/tfgnn/models.py", line 551, in call
    embedded_graph = convolution(embedded_graph, training=training)
  File "/home/fidels/miniconda3/envs/graph2tac/lib/python3.10/site-packages/tensorflow_gnn/keras/layers/graph_update.py", line 235, in call
    update_fn(graph, node_set_name=node_set_name)))
  File "/home/fidels/miniconda3/envs/graph2tac/lib/python3.10/site-packages/tensorflow_gnn/keras/layers/graph_update.py", line 417, in call
    input_from_edge_sets[edge_set_name] = input_fn(
  File "/home/fidels/miniconda3/envs/graph2tac/lib/python3.10/site-packages/tensorflow_gnn/keras/layers/convolution_base.py", line 311, in call
    return self.convolve(
  File "/home/fidels/miniconda3/envs/graph2tac/lib/python3.10/site-packages/tensorflow_gnn/keras/layers/convolutions.py", line 126, in convolve
    messages = self._message_fn(combined_input)
tensorflow.python.framework.errors_impl.InternalError: Exception encountered when calling layer "dense" (type Dense).

Attempting to perform BLAS operation using StreamExecutor without BLAS support [Op:MatMul]

Call arguments received by layer "dense" (type Dense):
  • inputs=tf.Tensor(shape=(21, 384), dtype=float32)
Traceback (most recent call last):
  File "/home/fidels/miniconda3/envs/graph2tac/bin/g2t-server", line 33, in <module>
    sys.exit(load_entry_point('graph2tac', 'console_scripts', 'g2t-server')())
  File "/home/fidels/graph2tac/graph2tac/loader/predict_server.py", line 712, in main
    main_loop(reader, sock, predict, args.debug_dir,
  File "/home/fidels/graph2tac/graph2tac/loader/predict_server.py", line 372, in main_loop
    predict.compute_new_definitions([cluster_state])
  File "/home/fidels/graph2tac/graph2tac/predict.py", line 38, in api_call_with_debug
    return api_call(self, *args, **kwargs)
  File "/home/fidels/graph2tac/graph2tac/tfgnn/predict.py", line 273, in compute_new_definitions
    definition_embeddings = self.definition_task(scalar_definition_graph).flat_values
  File "/home/fidels/miniconda3/envs/graph2tac/lib/python3.10/site-packages/keras/utils/traceback_utils.py", line 67, in error_handler
    raise e.with_traceback(filtered_tb) from None
  File "/home/fidels/graph2tac/graph2tac/tfgnn/tasks.py", line 740, in call
    hidden_graph = self._gnn(masked_embedded_graph, training=training)
  File "/home/fidels/graph2tac/graph2tac/tfgnn/models.py", line 551, in call
    embedded_graph = convolution(embedded_graph, training=training)
  File "/home/fidels/miniconda3/envs/graph2tac/lib/python3.10/site-packages/tensorflow_gnn/keras/layers/graph_update.py", line 235, in call
    update_fn(graph, node_set_name=node_set_name)))
  File "/home/fidels/miniconda3/envs/graph2tac/lib/python3.10/site-packages/tensorflow_gnn/keras/layers/graph_update.py", line 417, in call
    input_from_edge_sets[edge_set_name] = input_fn(
  File "/home/fidels/miniconda3/envs/graph2tac/lib/python3.10/site-packages/tensorflow_gnn/keras/layers/convolution_base.py", line 311, in call
    return self.convolve(
  File "/home/fidels/miniconda3/envs/graph2tac/lib/python3.10/site-packages/tensorflow_gnn/keras/layers/convolutions.py", line 126, in convolve
    messages = self._message_fn(combined_input)
tensorflow.python.framework.errors_impl.InternalError: Exception encountered when calling layer "dense" (type Dense).

Attempting to perform BLAS operation using StreamExecutor without BLAS support [Op:MatMul]

Call arguments received by layer "dense" (type Dense):
  • inputs=tf.Tensor(shape=(21, 384), dtype=float32)
File "./theories/Init/Logic.v", line 69, characters 4-24:
Error: Anomaly "Capnp protocol error 1"
Please report at http://coq.inria.fr/bugs/.

File "./theories/Init/Logic.v", line 74, characters 4-24:
Error: Anomaly "Capnp protocol error 1"
Please report at http://coq.inria.fr/bugs/.

File "./theories/Init/Logic.v", line 106, characters 4-16:
Error: Anomaly "Capnp protocol error 1"
Please report at http://coq.inria.fr/bugs/.

File "./theories/Init/Logic.v", line 111, characters 4-46:
Error: Anomaly "Capnp protocol error 1"
Please report at http://coq.inria.fr/bugs/.

