Traceback (most recent call last):
  File "/home/fidels/miniconda3/envs/graph2tac/bin/g2t-server", line 33, in <module>
    sys.exit(load_entry_point('graph2tac', 'console_scripts', 'g2t-server')())
  File "/home/fidels/graph2tac/graph2tac/loader/predict_server.py", line 674, in main
    predict = TFGNNPredict(log_dir=Path(args.model).expanduser().absolute(), debug_dir=args.debug_predict)
  File "/home/fidels/graph2tac/graph2tac/tfgnn/predict.py", line 156, in __init__
    super().__init__(graph_constants=graph_constants, debug_dir=debug_dir)
  File "/home/fidels/graph2tac/graph2tac/predict.py", line 56, in __init__
    self._debug_dir.mkdir(exist_ok=True)
  File "/home/fidels/miniconda3/envs/graph2tac/lib/python3.10/pathlib.py", line 1173, in mkdir
    self._accessor.mkdir(self, mode)
FileNotFoundError: [Errno 2] No such file or directory: '~/debug_test'
Traceback (most recent call last):
  File "/home/fidels/miniconda3/envs/graph2tac/bin/g2t-server", line 33, in <module>
    sys.exit(load_entry_point('graph2tac', 'console_scripts', 'g2t-server')())
  File "/home/fidels/graph2tac/graph2tac/loader/predict_server.py", line 674, in main
    predict = TFGNNPredict(log_dir=Path(args.model).expanduser().absolute(), debug_dir=args.debug_predict)
  File "/home/fidels/graph2tac/graph2tac/tfgnn/predict.py", line 156, in __init__
    super().__init__(graph_constants=graph_constants, debug_dir=debug_dir)
  File "/home/fidels/graph2tac/graph2tac/predict.py", line 56, in __init__
    self._debug_dir.mkdir(exist_ok=True)
  File "/home/fidels/miniconda3/envs/graph2tac/lib/python3.10/pathlib.py", line 1173, in mkdir
    self._accessor.mkdir(self, mode)
FileNotFoundError: [Errno 2] No such file or directory: '~/debug_test'
Traceback (most recent call last):
  File "/home/fidels/miniconda3/envs/graph2tac/bin/g2t-server", line 33, in <module>
    sys.exit(load_entry_point('graph2tac', 'console_scripts', 'g2t-server')())
  File "/home/fidels/graph2tac/graph2tac/loader/predict_server.py", line 674, in main
    predict = TFGNNPredict(log_dir=Path(args.model).expanduser().absolute(), debug_dir=args.debug_predict)
  File "/home/fidels/graph2tac/graph2tac/tfgnn/predict.py", line 156, in __init__
    super().__init__(graph_constants=graph_constants, debug_dir=debug_dir)
  File "/home/fidels/graph2tac/graph2tac/predict.py", line 56, in __init__
    self._debug_dir.mkdir(exist_ok=True)
  File "/home/fidels/miniconda3/envs/graph2tac/lib/python3.10/pathlib.py", line 1173, in mkdir
    self._accessor.mkdir(self, mode)
FileNotFoundError: [Errno 2] No such file or directory: '~/debug_test'
Traceback (most recent call last):
  File "/home/fidels/miniconda3/envs/graph2tac/bin/g2t-server", line 33, in <module>
    sys.exit(load_entry_point('graph2tac', 'console_scripts', 'g2t-server')())
  File "/home/fidels/graph2tac/graph2tac/loader/predict_server.py", line 674, in main
    predict = TFGNNPredict(log_dir=Path(args.model).expanduser().absolute(), debug_dir=args.debug_predict)
  File "/home/fidels/graph2tac/graph2tac/tfgnn/predict.py", line 156, in __init__
    super().__init__(graph_constants=graph_constants, debug_dir=debug_dir)
  File "/home/fidels/graph2tac/graph2tac/predict.py", line 56, in __init__
    self._debug_dir.mkdir(exist_ok=True)
  File "/home/fidels/miniconda3/envs/graph2tac/lib/python3.10/pathlib.py", line 1173, in mkdir
    self._accessor.mkdir(self, mode)
FileNotFoundError: [Errno 2] No such file or directory: '~/debug_test'
File "./theories/Init/Logic.v", line 74, characters 4-24:
Error:
Anomaly "Uncaught exception Unix.Unix_error(Unix.ECONNRESET, "read", "")."
Please report at http://coq.inria.fr/bugs/.

File "./theories/Init/Logic.v", line 106, characters 4-16:
Error:
Anomaly "Uncaught exception Unix.Unix_error(Unix.ECONNRESET, "read", "")."
Please report at http://coq.inria.fr/bugs/.

File "./theories/Init/Logic.v", line 69, characters 4-24:
Error:
Anomaly "Uncaught exception Unix.Unix_error(Unix.ECONNRESET, "read", "")."
Please report at http://coq.inria.fr/bugs/.

File "./theories/Init/Logic.v", line 111, characters 4-46:
Error:
Anomaly "Uncaught exception Unix.Unix_error(Unix.ECONNRESET, "read", "")."
Please report at http://coq.inria.fr/bugs/.

