Traceback (most recent call last):
  File "/home/fidels/miniconda3/envs/graph2tac/bin/g2t-server", line 33, in <module>
    sys.exit(load_entry_point('graph2tac', 'console_scripts', 'g2t-server')())
  File "/home/fidels/graph2tac/graph2tac/loader/predict_server.py", line 695, in main
    predict = TFGNNPredict(log_dir=Path(args.model).expanduser().absolute(),
  File "/home/fidels/graph2tac/graph2tac/tfgnn/predict.py", line 153, in __init__
    dataset = Dataset(**yaml.load(yml_file, Loader=yaml.SafeLoader))
  File "/home/fidels/graph2tac/graph2tac/tfgnn/dataset.py", line 65, in __init__
    self._label_tokenizer.adapt(self._graph_constants.label_to_names)
AttributeError: 'Dataset' object has no attribute '_graph_constants'. Did you mean: 'graph_constants'?
Traceback (most recent call last):
  File "/home/fidels/miniconda3/envs/graph2tac/bin/g2t-server", line 33, in <module>
    sys.exit(load_entry_point('graph2tac', 'console_scripts', 'g2t-server')())
  File "/home/fidels/graph2tac/graph2tac/loader/predict_server.py", line 695, in main
    predict = TFGNNPredict(log_dir=Path(args.model).expanduser().absolute(),
  File "/home/fidels/graph2tac/graph2tac/tfgnn/predict.py", line 153, in __init__
    dataset = Dataset(**yaml.load(yml_file, Loader=yaml.SafeLoader))
  File "/home/fidels/graph2tac/graph2tac/tfgnn/dataset.py", line 65, in __init__
    self._label_tokenizer.adapt(self._graph_constants.label_to_names)
AttributeError: 'Dataset' object has no attribute '_graph_constants'. Did you mean: 'graph_constants'?
Traceback (most recent call last):
  File "/home/fidels/miniconda3/envs/graph2tac/bin/g2t-server", line 33, in <module>
    sys.exit(load_entry_point('graph2tac', 'console_scripts', 'g2t-server')())
  File "/home/fidels/graph2tac/graph2tac/loader/predict_server.py", line 695, in main
    predict = TFGNNPredict(log_dir=Path(args.model).expanduser().absolute(),
  File "/home/fidels/graph2tac/graph2tac/tfgnn/predict.py", line 153, in __init__
    dataset = Dataset(**yaml.load(yml_file, Loader=yaml.SafeLoader))
  File "/home/fidels/graph2tac/graph2tac/tfgnn/dataset.py", line 65, in __init__
    self._label_tokenizer.adapt(self._graph_constants.label_to_names)
AttributeError: 'Dataset' object has no attribute '_graph_constants'. Did you mean: 'graph_constants'?
Traceback (most recent call last):
  File "/home/fidels/miniconda3/envs/graph2tac/bin/g2t-server", line 33, in <module>
    sys.exit(load_entry_point('graph2tac', 'console_scripts', 'g2t-server')())
  File "/home/fidels/graph2tac/graph2tac/loader/predict_server.py", line 695, in main
    predict = TFGNNPredict(log_dir=Path(args.model).expanduser().absolute(),
  File "/home/fidels/graph2tac/graph2tac/tfgnn/predict.py", line 153, in __init__
    dataset = Dataset(**yaml.load(yml_file, Loader=yaml.SafeLoader))
  File "/home/fidels/graph2tac/graph2tac/tfgnn/dataset.py", line 65, in __init__
    self._label_tokenizer.adapt(self._graph_constants.label_to_names)
AttributeError: 'Dataset' object has no attribute '_graph_constants'. Did you mean: 'graph_constants'?
File "./theories/Init/Logic.v", line 106, characters 4-16:
Error:
Anomaly "Uncaught exception Unix.Unix_error(Unix.ECONNRESET, "read", "")."
Please report at http://coq.inria.fr/bugs/.

File "./theories/Init/Logic.v", line 69, characters 4-24:
Error:
Anomaly "Uncaught exception Unix.Unix_error(Unix.ECONNRESET, "read", "")."
Please report at http://coq.inria.fr/bugs/.

File "./theories/Init/Logic.v", line 111, characters 4-46:
Error:
Anomaly "Uncaught exception Unix.Unix_error(Unix.ECONNRESET, "read", "")."
Please report at http://coq.inria.fr/bugs/.

File "./theories/Init/Logic.v", line 74, characters 4-24:
Error:
Anomaly "Uncaught exception Unix.Unix_error(Unix.ECONNRESET, "read", "")."
Please report at http://coq.inria.fr/bugs/.

