WARNING:tensorflow:Mapping types may not work well with tf.nest. Prefer using MutableMapping for <class 'tensorflow_gnn.graph.graph_tensor._ImmutableMapping'>
WARNING:tensorflow:Mapping types may not work well with tf.nest. Prefer using MutableMapping for <class 'tensorflow_gnn.graph.graph_tensor._ImmutableMapping'>
WARNING:tensorflow:Mapping types may not work well with tf.nest. Prefer using MutableMapping for <class 'tensorflow_gnn.graph.graph_tensor._ImmutableMapping'>
Traceback (most recent call last):
  File "/home/fidels/miniconda3/envs/graph2tac/bin/g2t-server", line 33, in <module>
    sys.exit(load_entry_point('graph2tac', 'console_scripts', 'g2t-server')())
  File "/home/fidels/graph2tac/graph2tac/loader/predict_server.py", line 716, in main
    main_loop(reader, sock, predict, args.debug_dir,
  File "/home/fidels/graph2tac/graph2tac/loader/predict_server.py", line 379, in main_loop
    predict.initialize(global_context)
  File "/home/fidels/graph2tac/graph2tac/tfgnn/predict.py", line 232, in initialize
    self.prediction_task.graph_embedding = self._extend_graph_embedding(self.prediction_task.graph_embedding, new_node_label_num)
  File "/home/fidels/graph2tac/graph2tac/tfgnn/predict.py", line 218, in _extend_graph_embedding
    new_labels = graph_embedding._node_label_num + tf.range(new_node_label_num - graph_embedding._node_label_num)
  File "/home/fidels/miniconda3/envs/graph2tac/lib/python3.10/site-packages/tensorflow/python/util/traceback_utils.py", line 153, in error_handler
    raise e.with_traceback(filtered_tb) from None
  File "/home/fidels/miniconda3/envs/graph2tac/lib/python3.10/site-packages/tensorflow/python/framework/ops.py", line 7164, in raise_from_not_ok_status
    raise core._status_to_exception(e) from None  # pylint: disable=protected-access
tensorflow.python.framework.errors_impl.InvalidArgumentError: Requires start <= limit when delta > 0: 0/-3 [Op:Range]
File "./theories/Init/Logic.v", line 106, characters 4-16:
Error: Anomaly "Capnp protocol error 1"
Please report at http://coq.inria.fr/bugs/.

File "./theories/Init/Logic.v", line 111, characters 4-46:
Error:
Anomaly "Uncaught exception Unix.Unix_error(Unix.EPIPE, "single_write", "")."
Please report at http://coq.inria.fr/bugs/.

File "./theories/Init/Logic.v", line 116, characters 4-36:
Error:
Anomaly "Uncaught exception Unix.Unix_error(Unix.EPIPE, "single_write", "")."
Please report at http://coq.inria.fr/bugs/.

