File "/tmp/tactician.tmp.KzuMtE/opam-root/bench/lib/coq/user-contrib/Tactician/Graph2TacConfig.v", line 1, characters 0-32:
Warning: There is no option Tactician Neural Truncate.
[unknown-option,option]
File "/tmp/tactician.tmp.KzuMtE/opam-root/bench/lib/coq/user-contrib/Tactician/Graph2TacConfig.v", line 1, characters 0-32:
Warning: There is no option Tactician Neural Truncate.
[unknown-option,option]
File "/tmp/tactician.tmp.KzuMtE/opam-root/bench/lib/coq/user-contrib/Tactician/Graph2TacConfig.v", line 1, characters 0-32:
Warning: There is no option Tactician Neural Truncate.
[unknown-option,option]
File "/tmp/tactician.tmp.KzuMtE/opam-root/bench/lib/coq/user-contrib/Tactician/Graph2TacConfig.v", line 1, characters 0-32:
Warning: There is no option Tactician Neural Truncate.
[unknown-option,option]
File "/tmp/tactician.tmp.KzuMtE/opam-root/bench/lib/coq/user-contrib/Tactician/Graph2TacConfig.v", line 1, characters 0-32:
Warning: There is no option Tactician Neural Truncate.
[unknown-option,option]
File "/tmp/tactician.tmp.KzuMtE/opam-root/bench/lib/coq/user-contrib/Tactician/Graph2TacConfig.v", line 1, characters 0-32:
Warning: There is no option Tactician Neural Truncate.
[unknown-option,option]
File "/tmp/tactician.tmp.KzuMtE/opam-root/bench/lib/coq/user-contrib/Tactician/Graph2TacConfig.v", line 1, characters 0-32:
Warning: There is no option Tactician Neural Truncate.
[unknown-option,option]
File "/tmp/tactician.tmp.KzuMtE/opam-root/bench/lib/coq/user-contrib/Tactician/Graph2TacConfig.v", line 1, characters 0-32:
Warning: There is no option Tactician Neural Truncate.
[unknown-option,option]
File "/tmp/tactician.tmp.KzuMtE/opam-root/bench/lib/coq/user-contrib/Tactician/Graph2TacConfig.v", line 1, characters 0-32:
Warning: There is no option Tactician Neural Truncate.
[unknown-option,option]
File "/tmp/tactician.tmp.KzuMtE/opam-root/bench/lib/coq/user-contrib/Tactician/Graph2TacConfig.v", line 1, characters 0-32:
Warning: There is no option Tactician Neural Truncate.
[unknown-option,option]
Traceback (most recent call last):
  File "/tmp/tactician.tmp.KzuMtE/target-source/venv/bin/g2t-server", line 33, in <module>
    sys.exit(load_entry_point('graph2tac==0.1.0', 'console_scripts', 'g2t-server')())
  File "/tmp/tactician.tmp.KzuMtE/target-source/venv/lib/python3.10/site-packages/graph2tac/loader/predict_server.py", line 967, in main
    main_with_return_value()
  File "/tmp/tactician.tmp.KzuMtE/target-source/venv/lib/python3.10/site-packages/graph2tac/loader/predict_server.py", line 922, in main_with_return_value
    model = load_model(config, log_levels)
  File "/tmp/tactician.tmp.KzuMtE/target-source/venv/lib/python3.10/site-packages/graph2tac/loader/predict_server.py", line 871, in load_model
    model = TFGNNPredict(log_dir=Path(config.model).expanduser().absolute(),
  File "/tmp/tactician.tmp.KzuMtE/target-source/venv/lib/python3.10/site-packages/graph2tac/tfgnn/predict.py", line 620, in __init__
    self._compile_network()
  File "/tmp/tactician.tmp.KzuMtE/target-source/venv/lib/python3.10/site-packages/graph2tac/tfgnn/predict.py", line 685, in _compile_network
    inference_model_bare = self.prediction_task.create_inference_model(
  File "/tmp/tactician.tmp.KzuMtE/target-source/venv/lib/python3.10/site-packages/graph2tac/tfgnn/tasks.py", line 1343, in create_inference_model
    tactic, top_k_values = self._top_k_tactics(tactic_logits=tactic_logits,
  File "/tmp/tactician.tmp.KzuMtE/target-source/venv/lib/python3.10/site-packages/graph2tac/tfgnn/tasks.py", line 561, in _top_k_tactics
    top_k = tf.math.top_k(tactic_logits, k=tactic_expand_bound)
  File "/tmp/tactician.tmp.KzuMtE/target-source/venv/lib/python3.10/site-packages/tensorflow/python/util/traceback_utils.py", line 153, in error_handler
    raise e.with_traceback(filtered_tb) from None
  File "/tmp/tactician.tmp.KzuMtE/target-source/venv/lib/python3.10/site-packages/keras/layers/core/tf_op_layer.py", line 107, in handle
    return TFOpLambda(op)(*args, **kwargs)
  File "/tmp/tactician.tmp.KzuMtE/target-source/venv/lib/python3.10/site-packages/keras/utils/traceback_utils.py", line 67, in error_handler
    raise e.with_traceback(filtered_tb) from None
ValueError: Exception encountered when calling layer "tf.math.top_k" (type TFOpLambda).

input must have last dimension >= k = 2048 but is 1247 for '{{node tf.math.top_k/TopKV2}} = TopKV2[T=DT_FLOAT, sorted=true](Placeholder, tf.math.top_k/TopKV2/k)' with input shapes: [?,1247], [] and with computed input tensors: input[1] = <2048>.

Call arguments received by layer "tf.math.top_k" (type TFOpLambda):
  • input=tf.Tensor(shape=(None, 1247), dtype=float32)
  • k=2048
  • sorted=True
  • name=None
Traceback (most recent call last):
  File "/tmp/tactician.tmp.KzuMtE/target-source/venv/bin/g2t-server", line 33, in <module>
    sys.exit(load_entry_point('graph2tac==0.1.0', 'console_scripts', 'g2t-server')())
  File "/tmp/tactician.tmp.KzuMtE/target-source/venv/lib/python3.10/site-packages/graph2tac/loader/predict_server.py", line 967, in main
    main_with_return_value()
  File "/tmp/tactician.tmp.KzuMtE/target-source/venv/lib/python3.10/site-packages/graph2tac/loader/predict_server.py", line 922, in main_with_return_value
    model = load_model(config, log_levels)
  File "/tmp/tactician.tmp.KzuMtE/target-source/venv/lib/python3.10/site-packages/graph2tac/loader/predict_server.py", line 871, in load_model
Traceback (most recent call last):
  File "/tmp/tactician.tmp.KzuMtE/target-source/venv/bin/g2t-server", line 33, in <module>
    sys.exit(load_entry_point('graph2tac==0.1.0', 'console_scripts', 'g2t-server')())
  File "/tmp/tactician.tmp.KzuMtE/target-source/venv/lib/python3.10/site-packages/graph2tac/loader/predict_server.py", line 967, in main
    main_with_return_value()
  File "/tmp/tactician.tmp.KzuMtE/target-source/venv/lib/python3.10/site-packages/graph2tac/loader/predict_server.py", line 922, in main_with_return_value
    model = load_model(config, log_levels)
  File "/tmp/tactician.tmp.KzuMtE/target-source/venv/lib/python3.10/site-packages/graph2tac/loader/predict_server.py", line 871, in load_model
    model = TFGNNPredict(log_dir=Path(config.model).expanduser().absolute(),
  File "/tmp/tactician.tmp.KzuMtE/target-source/venv/lib/python3.10/site-packages/graph2tac/tfgnn/predict.py", line 620, in __init__
    self._compile_network()
  File "/tmp/tactician.tmp.KzuMtE/target-source/venv/lib/python3.10/site-packages/graph2tac/tfgnn/predict.py", line 685, in _compile_network
    inference_model_bare = self.prediction_task.create_inference_model(
  File "/tmp/tactician.tmp.KzuMtE/target-source/venv/lib/python3.10/site-packages/graph2tac/tfgnn/tasks.py", line 1343, in create_inference_model
    tactic, top_k_values = self._top_k_tactics(tactic_logits=tactic_logits,
  File "/tmp/tactician.tmp.KzuMtE/target-source/venv/lib/python3.10/site-packages/graph2tac/tfgnn/tasks.py", line 561, in _top_k_tactics
    top_k = tf.math.top_k(tactic_logits, k=tactic_expand_bound)
  File "/tmp/tactician.tmp.KzuMtE/target-source/venv/lib/python3.10/site-packages/tensorflow/python/util/traceback_utils.py", line 153, in error_handler
    raise e.with_traceback(filtered_tb) from None
  File "/tmp/tactician.tmp.KzuMtE/target-source/venv/lib/python3.10/site-packages/keras/layers/core/tf_op_layer.py", line 107, in handle
    return TFOpLambda(op)(*args, **kwargs)
  File "/tmp/tactician.tmp.KzuMtE/target-source/venv/lib/python3.10/site-packages/keras/utils/traceback_utils.py", line 67, in error_handler
    raise e.with_traceback(filtered_tb) from None
ValueError: Exception encountered when calling layer "tf.math.top_k" (type TFOpLambda).

input must have last dimension >= k = 2048 but is 1247 for '{{node tf.math.top_k/TopKV2}} = TopKV2[T=DT_FLOAT, sorted=true](Placeholder, tf.math.top_k/TopKV2/k)' with input shapes: [?,1247], [] and with computed input tensors: input[1] = <2048>.

Call arguments received by layer "tf.math.top_k" (type TFOpLambda):
  • input=tf.Tensor(shape=(None, 1247), dtype=float32)
  • k=2048
  • sorted=True
  • name=None
    model = TFGNNPredict(log_dir=Path(config.model).expanduser().absolute(),
  File "/tmp/tactician.tmp.KzuMtE/target-source/venv/lib/python3.10/site-packages/graph2tac/tfgnn/predict.py", line 620, in __init__
    self._compile_network()
  File "/tmp/tactician.tmp.KzuMtE/target-source/venv/lib/python3.10/site-packages/graph2tac/tfgnn/predict.py", line 685, in _compile_network
    inference_model_bare = self.prediction_task.create_inference_model(
  File "/tmp/tactician.tmp.KzuMtE/target-source/venv/lib/python3.10/site-packages/graph2tac/tfgnn/tasks.py", line 1343, in create_inference_model
    tactic, top_k_values = self._top_k_tactics(tactic_logits=tactic_logits,
  File "/tmp/tactician.tmp.KzuMtE/target-source/venv/lib/python3.10/site-packages/graph2tac/tfgnn/tasks.py", line 561, in _top_k_tactics
    top_k = tf.math.top_k(tactic_logits, k=tactic_expand_bound)
  File "/tmp/tactician.tmp.KzuMtE/target-source/venv/lib/python3.10/site-packages/tensorflow/python/util/traceback_utils.py", line 153, in error_handler
    raise e.with_traceback(filtered_tb) from None
  File "/tmp/tactician.tmp.KzuMtE/target-source/venv/lib/python3.10/site-packages/keras/layers/core/tf_op_layer.py", line 107, in handle
    return TFOpLambda(op)(*args, **kwargs)
  File "/tmp/tactician.tmp.KzuMtE/target-source/venv/lib/python3.10/site-packages/keras/utils/traceback_utils.py", line 67, in error_handler
    raise e.with_traceback(filtered_tb) from None
ValueError: Exception encountered when calling layer "tf.math.top_k" (type TFOpLambda).

input must have last dimension >= k = 2048 but is 1247 for '{{node tf.math.top_k/TopKV2}} = TopKV2[T=DT_FLOAT, sorted=true](Placeholder, tf.math.top_k/TopKV2/k)' with input shapes: [?,1247], [] and with computed input tensors: input[1] = <2048>.

Call arguments received by layer "tf.math.top_k" (type TFOpLambda):
  • input=tf.Tensor(shape=(None, 1247), dtype=float32)
  • k=2048
  • sorted=True
  • name=None
Traceback (most recent call last):
  File "/tmp/tactician.tmp.KzuMtE/target-source/venv/bin/g2t-server", line 33, in <module>
    sys.exit(load_entry_point('graph2tac==0.1.0', 'console_scripts', 'g2t-server')())
  File "/tmp/tactician.tmp.KzuMtE/target-source/venv/lib/python3.10/site-packages/graph2tac/loader/predict_server.py", line 967, in main
    main_with_return_value()
  File "/tmp/tactician.tmp.KzuMtE/target-source/venv/lib/python3.10/site-packages/graph2tac/loader/predict_server.py", line 922, in main_with_return_value
    model = load_model(config, log_levels)
  File "/tmp/tactician.tmp.KzuMtE/target-source/venv/lib/python3.10/site-packages/graph2tac/loader/predict_server.py", line 871, in load_model
    model = TFGNNPredict(log_dir=Path(config.model).expanduser().absolute(),
  File "/tmp/tactician.tmp.KzuMtE/target-source/venv/lib/python3.10/site-packages/graph2tac/tfgnn/predict.py", line 620, in __init__
    self._compile_network()
  File "/tmp/tactician.tmp.KzuMtE/target-source/venv/lib/python3.10/site-packages/graph2tac/tfgnn/predict.py", line 685, in _compile_network
    inference_model_bare = self.prediction_task.create_inference_model(
  File "/tmp/tactician.tmp.KzuMtE/target-source/venv/lib/python3.10/site-packages/graph2tac/tfgnn/tasks.py", line 1343, in create_inference_model
    tactic, top_k_values = self._top_k_tactics(tactic_logits=tactic_logits,
  File "/tmp/tactician.tmp.KzuMtE/target-source/venv/lib/python3.10/site-packages/graph2tac/tfgnn/tasks.py", line 561, in _top_k_tactics
    top_k = tf.math.top_k(tactic_logits, k=tactic_expand_bound)
  File "/tmp/tactician.tmp.KzuMtE/target-source/venv/lib/python3.10/site-packages/tensorflow/python/util/traceback_utils.py", line 153, in error_handler
    raise e.with_traceback(filtered_tb) from None
  File "/tmp/tactician.tmp.KzuMtE/target-source/venv/lib/python3.10/site-packages/keras/layers/core/tf_op_layer.py", line 107, in handle
    return TFOpLambda(op)(*args, **kwargs)
  File "/tmp/tactician.tmp.KzuMtE/target-source/venv/lib/python3.10/site-packages/keras/utils/traceback_utils.py", line 67, in error_handler
    raise e.with_traceback(filtered_tb) from None
ValueError: Exception encountered when calling layer "tf.math.top_k" (type TFOpLambda).

input must have last dimension >= k = 2048 but is 1247 for '{{node tf.math.top_k/TopKV2}} = TopKV2[T=DT_FLOAT, sorted=true](Placeholder, tf.math.top_k/TopKV2/k)' with input shapes: [?,1247], [] and with computed input tensors: input[1] = <2048>.

Call arguments received by layer "tf.math.top_k" (type TFOpLambda):
  • input=tf.Tensor(shape=(None, 1247), dtype=float32)
  • k=2048
  • sorted=True
  • name=None
Traceback (most recent call last):
  File "/tmp/tactician.tmp.KzuMtE/target-source/venv/bin/g2t-server", line 33, in <module>
    sys.exit(load_entry_point('graph2tac==0.1.0', 'console_scripts', 'g2t-server')())
  File "/tmp/tactician.tmp.KzuMtE/target-source/venv/lib/python3.10/site-packages/graph2tac/loader/predict_server.py", line 967, in main
    main_with_return_value()
  File "/tmp/tactician.tmp.KzuMtE/target-source/venv/lib/python3.10/site-packages/graph2tac/loader/predict_server.py", line 922, in main_with_return_value
    model = load_model(config, log_levels)
  File "/tmp/tactician.tmp.KzuMtE/target-source/venv/lib/python3.10/site-packages/graph2tac/loader/predict_server.py", line 871, in load_model
    model = TFGNNPredict(log_dir=Path(config.model).expanduser().absolute(),
  File "/tmp/tactician.tmp.KzuMtE/target-source/venv/lib/python3.10/site-packages/graph2tac/tfgnn/predict.py", line 620, in __init__
    self._compile_network()
  File "/tmp/tactician.tmp.KzuMtE/target-source/venv/lib/python3.10/site-packages/graph2tac/tfgnn/predict.py", line 685, in _compile_network
    inference_model_bare = self.prediction_task.create_inference_model(
  File "/tmp/tactician.tmp.KzuMtE/target-source/venv/lib/python3.10/site-packages/graph2tac/tfgnn/tasks.py", line 1343, in create_inference_model
    tactic, top_k_values = self._top_k_tactics(tactic_logits=tactic_logits,
  File "/tmp/tactician.tmp.KzuMtE/target-source/venv/lib/python3.10/site-packages/graph2tac/tfgnn/tasks.py", line 561, in _top_k_tactics
    top_k = tf.math.top_k(tactic_logits, k=tactic_expand_bound)
  File "/tmp/tactician.tmp.KzuMtE/target-source/venv/lib/python3.10/site-packages/tensorflow/python/util/traceback_utils.py", line 153, in error_handler
    raise e.with_traceback(filtered_tb) from None
  File "/tmp/tactician.tmp.KzuMtE/target-source/venv/lib/python3.10/site-packages/keras/layers/core/tf_op_layer.py", line 107, in handle
    return TFOpLambda(op)(*args, **kwargs)
  File "/tmp/tactician.tmp.KzuMtE/target-source/venv/lib/python3.10/site-packages/keras/utils/traceback_utils.py", line 67, in error_handler
    raise e.with_traceback(filtered_tb) from None
ValueError: Exception encountered when calling layer "tf.math.top_k" (type TFOpLambda).

input must have last dimension >= k = 2048 but is 1247 for '{{node tf.math.top_k/TopKV2}} = TopKV2[T=DT_FLOAT, sorted=true](Placeholder, tf.math.top_k/TopKV2/k)' with input shapes: [?,1247], [] and with computed input tensors: input[1] = <2048>.

Call arguments received by layer "tf.math.top_k" (type TFOpLambda):
  • input=tf.Tensor(shape=(None, 1247), dtype=float32)
  • k=2048
  • sorted=True
  • name=None
Traceback (most recent call last):
  File "/tmp/tactician.tmp.KzuMtE/target-source/venv/bin/g2t-server", line 33, in <module>
    sys.exit(load_entry_point('graph2tac==0.1.0', 'console_scripts', 'g2t-server')())
  File "/tmp/tactician.tmp.KzuMtE/target-source/venv/lib/python3.10/site-packages/graph2tac/loader/predict_server.py", line 967, in main
    main_with_return_value()
  File "/tmp/tactician.tmp.KzuMtE/target-source/venv/lib/python3.10/site-packages/graph2tac/loader/predict_server.py", line 922, in main_with_return_value
    model = load_model(config, log_levels)
  File "/tmp/tactician.tmp.KzuMtE/target-source/venv/lib/python3.10/site-packages/graph2tac/loader/predict_server.py", line 871, in load_model
    model = TFGNNPredict(log_dir=Path(config.model).expanduser().absolute(),
  File "/tmp/tactician.tmp.KzuMtE/target-source/venv/lib/python3.10/site-packages/graph2tac/tfgnn/predict.py", line 620, in __init__
    self._compile_network()
  File "/tmp/tactician.tmp.KzuMtE/target-source/venv/lib/python3.10/site-packages/graph2tac/tfgnn/predict.py", line 685, in _compile_network
    inference_model_bare = self.prediction_task.create_inference_model(
  File "/tmp/tactician.tmp.KzuMtE/target-source/venv/lib/python3.10/site-packages/graph2tac/tfgnn/tasks.py", line 1343, in create_inference_model
    tactic, top_k_values = self._top_k_tactics(tactic_logits=tactic_logits,
  File "/tmp/tactician.tmp.KzuMtE/target-source/venv/lib/python3.10/site-packages/graph2tac/tfgnn/tasks.py", line 561, in _top_k_tactics
    top_k = tf.math.top_k(tactic_logits, k=tactic_expand_bound)
  File "/tmp/tactician.tmp.KzuMtE/target-source/venv/lib/python3.10/site-packages/tensorflow/python/util/traceback_utils.py", line 153, in error_handler
    raise e.with_traceback(filtered_tb) from None
  File "/tmp/tactician.tmp.KzuMtE/target-source/venv/lib/python3.10/site-packages/keras/layers/core/tf_op_layer.py", line 107, in handle
    return TFOpLambda(op)(*args, **kwargs)
  File "/tmp/tactician.tmp.KzuMtE/target-source/venv/lib/python3.10/site-packages/keras/utils/traceback_utils.py", line 67, in error_handler
    raise e.with_traceback(filtered_tb) from None
ValueError: Exception encountered when calling layer "tf.math.top_k" (type TFOpLambda).

input must have last dimension >= k = 2048 but is 1247 for '{{node tf.math.top_k/TopKV2}} = TopKV2[T=DT_FLOAT, sorted=true](Placeholder, tf.math.top_k/TopKV2/k)' with input shapes: [?,1247], [] and with computed input tensors: input[1] = <2048>.

Call arguments received by layer "tf.math.top_k" (type TFOpLambda):
  • input=tf.Tensor(shape=(None, 1247), dtype=float32)
  • k=2048
  • sorted=True
  • name=None
Traceback (most recent call last):
  File "/tmp/tactician.tmp.KzuMtE/target-source/venv/bin/g2t-server", line 33, in <module>
    sys.exit(load_entry_point('graph2tac==0.1.0', 'console_scripts', 'g2t-server')())
  File "/tmp/tactician.tmp.KzuMtE/target-source/venv/lib/python3.10/site-packages/graph2tac/loader/predict_server.py", line 967, in main
    main_with_return_value()
  File "/tmp/tactician.tmp.KzuMtE/target-source/venv/lib/python3.10/site-packages/graph2tac/loader/predict_server.py", line 922, in main_with_return_value
    model = load_model(config, log_levels)
  File "/tmp/tactician.tmp.KzuMtE/target-source/venv/lib/python3.10/site-packages/graph2tac/loader/predict_server.py", line 871, in load_model
    model = TFGNNPredict(log_dir=Path(config.model).expanduser().absolute(),
  File "/tmp/tactician.tmp.KzuMtE/target-source/venv/lib/python3.10/site-packages/graph2tac/tfgnn/predict.py", line 620, in __init__
    self._compile_network()
  File "/tmp/tactician.tmp.KzuMtE/target-source/venv/lib/python3.10/site-packages/graph2tac/tfgnn/predict.py", line 685, in _compile_network
    inference_model_bare = self.prediction_task.create_inference_model(
  File "/tmp/tactician.tmp.KzuMtE/target-source/venv/lib/python3.10/site-packages/graph2tac/tfgnn/tasks.py", line 1343, in create_inference_model
    tactic, top_k_values = self._top_k_tactics(tactic_logits=tactic_logits,
  File "/tmp/tactician.tmp.KzuMtE/target-source/venv/lib/python3.10/site-packages/graph2tac/tfgnn/tasks.py", line 561, in _top_k_tactics
    top_k = tf.math.top_k(tactic_logits, k=tactic_expand_bound)
  File "/tmp/tactician.tmp.KzuMtE/target-source/venv/lib/python3.10/site-packages/tensorflow/python/util/traceback_utils.py", line 153, in error_handler
    raise e.with_traceback(filtered_tb) from None
  File "/tmp/tactician.tmp.KzuMtE/target-source/venv/lib/python3.10/site-packages/keras/layers/core/tf_op_layer.py", line 107, in handle
    return TFOpLambda(op)(*args, **kwargs)
  File "/tmp/tactician.tmp.KzuMtE/target-source/venv/lib/python3.10/site-packages/keras/utils/traceback_utils.py", line 67, in error_handler
    raise e.with_traceback(filtered_tb) from None
ValueError: Exception encountered when calling layer "tf.math.top_k" (type TFOpLambda).

input must have last dimension >= k = 2048 but is 1247 for '{{node tf.math.top_k/TopKV2}} = TopKV2[T=DT_FLOAT, sorted=true](Placeholder, tf.math.top_k/TopKV2/k)' with input shapes: [?,1247], [] and with computed input tensors: input[1] = <2048>.

Call arguments received by layer "tf.math.top_k" (type TFOpLambda):
  • input=tf.Tensor(shape=(None, 1247), dtype=float32)
  • k=2048
  • sorted=True
  • name=None
Traceback (most recent call last):
  File "/tmp/tactician.tmp.KzuMtE/target-source/venv/bin/g2t-server", line 33, in <module>
    sys.exit(load_entry_point('graph2tac==0.1.0', 'console_scripts', 'g2t-server')())
  File "/tmp/tactician.tmp.KzuMtE/target-source/venv/lib/python3.10/site-packages/graph2tac/loader/predict_server.py", line 967, in main
    main_with_return_value()
  File "/tmp/tactician.tmp.KzuMtE/target-source/venv/lib/python3.10/site-packages/graph2tac/loader/predict_server.py", line 922, in main_with_return_value
    model = load_model(config, log_levels)
  File "/tmp/tactician.tmp.KzuMtE/target-source/venv/lib/python3.10/site-packages/graph2tac/loader/predict_server.py", line 871, in load_model
    model = TFGNNPredict(log_dir=Path(config.model).expanduser().absolute(),
  File "/tmp/tactician.tmp.KzuMtE/target-source/venv/lib/python3.10/site-packages/graph2tac/tfgnn/predict.py", line 620, in __init__
    self._compile_network()
  File "/tmp/tactician.tmp.KzuMtE/target-source/venv/lib/python3.10/site-packages/graph2tac/tfgnn/predict.py", line 685, in _compile_network
    inference_model_bare = self.prediction_task.create_inference_model(
  File "/tmp/tactician.tmp.KzuMtE/target-source/venv/lib/python3.10/site-packages/graph2tac/tfgnn/tasks.py", line 1343, in create_inference_model
    tactic, top_k_values = self._top_k_tactics(tactic_logits=tactic_logits,
  File "/tmp/tactician.tmp.KzuMtE/target-source/venv/lib/python3.10/site-packages/graph2tac/tfgnn/tasks.py", line 561, in _top_k_tactics
    top_k = tf.math.top_k(tactic_logits, k=tactic_expand_bound)
  File "/tmp/tactician.tmp.KzuMtE/target-source/venv/lib/python3.10/site-packages/tensorflow/python/util/traceback_utils.py", line 153, in error_handler
    raise e.with_traceback(filtered_tb) from None
  File "/tmp/tactician.tmp.KzuMtE/target-source/venv/lib/python3.10/site-packages/keras/layers/core/tf_op_layer.py", line 107, in handle
    return TFOpLambda(op)(*args, **kwargs)
  File "/tmp/tactician.tmp.KzuMtE/target-source/venv/lib/python3.10/site-packages/keras/utils/traceback_utils.py", line 67, in error_handler
    raise e.with_traceback(filtered_tb) from None
ValueError: Exception encountered when calling layer "tf.math.top_k" (type TFOpLambda).

input must have last dimension >= k = 2048 but is 1247 for '{{node tf.math.top_k/TopKV2}} = TopKV2[T=DT_FLOAT, sorted=true](Placeholder, tf.math.top_k/TopKV2/k)' with input shapes: [?,1247], [] and with computed input tensors: input[1] = <2048>.

Call arguments received by layer "tf.math.top_k" (type TFOpLambda):
  • input=tf.Tensor(shape=(None, 1247), dtype=float32)
  • k=2048
  • sorted=True
  • name=None
Traceback (most recent call last):
  File "/tmp/tactician.tmp.KzuMtE/target-source/venv/bin/g2t-server", line 33, in <module>
    sys.exit(load_entry_point('graph2tac==0.1.0', 'console_scripts', 'g2t-server')())
  File "/tmp/tactician.tmp.KzuMtE/target-source/venv/lib/python3.10/site-packages/graph2tac/loader/predict_server.py", line 967, in main
    main_with_return_value()
  File "/tmp/tactician.tmp.KzuMtE/target-source/venv/lib/python3.10/site-packages/graph2tac/loader/predict_server.py", line 922, in main_with_return_value
    model = load_model(config, log_levels)
  File "/tmp/tactician.tmp.KzuMtE/target-source/venv/lib/python3.10/site-packages/graph2tac/loader/predict_server.py", line 871, in load_model
    model = TFGNNPredict(log_dir=Path(config.model).expanduser().absolute(),
  File "/tmp/tactician.tmp.KzuMtE/target-source/venv/lib/python3.10/site-packages/graph2tac/tfgnn/predict.py", line 620, in __init__
    self._compile_network()
  File "/tmp/tactician.tmp.KzuMtE/target-source/venv/lib/python3.10/site-packages/graph2tac/tfgnn/predict.py", line 685, in _compile_network
    inference_model_bare = self.prediction_task.create_inference_model(
  File "/tmp/tactician.tmp.KzuMtE/target-source/venv/lib/python3.10/site-packages/graph2tac/tfgnn/tasks.py", line 1343, in create_inference_model
    tactic, top_k_values = self._top_k_tactics(tactic_logits=tactic_logits,
  File "/tmp/tactician.tmp.KzuMtE/target-source/venv/lib/python3.10/site-packages/graph2tac/tfgnn/tasks.py", line 561, in _top_k_tactics
    top_k = tf.math.top_k(tactic_logits, k=tactic_expand_bound)
  File "/tmp/tactician.tmp.KzuMtE/target-source/venv/lib/python3.10/site-packages/tensorflow/python/util/traceback_utils.py", line 153, in error_handler
    raise e.with_traceback(filtered_tb) from None
  File "/tmp/tactician.tmp.KzuMtE/target-source/venv/lib/python3.10/site-packages/keras/layers/core/tf_op_layer.py", line 107, in handle
    return TFOpLambda(op)(*args, **kwargs)
  File "/tmp/tactician.tmp.KzuMtE/target-source/venv/lib/python3.10/site-packages/keras/utils/traceback_utils.py", line 67, in error_handler
    raise e.with_traceback(filtered_tb) from None
ValueError: Exception encountered when calling layer "tf.math.top_k" (type TFOpLambda).

input must have last dimension >= k = 2048 but is 1247 for '{{node tf.math.top_k/TopKV2}} = TopKV2[T=DT_FLOAT, sorted=true](Placeholder, tf.math.top_k/TopKV2/k)' with input shapes: [?,1247], [] and with computed input tensors: input[1] = <2048>.

Call arguments received by layer "tf.math.top_k" (type TFOpLambda):
  • input=tf.Tensor(shape=(None, 1247), dtype=float32)
  • k=2048
  • sorted=True
  • name=None
Traceback (most recent call last):
  File "/tmp/tactician.tmp.KzuMtE/target-source/venv/bin/g2t-server", line 33, in <module>
    sys.exit(load_entry_point('graph2tac==0.1.0', 'console_scripts', 'g2t-server')())
  File "/tmp/tactician.tmp.KzuMtE/target-source/venv/lib/python3.10/site-packages/graph2tac/loader/predict_server.py", line 967, in main
    main_with_return_value()
  File "/tmp/tactician.tmp.KzuMtE/target-source/venv/lib/python3.10/site-packages/graph2tac/loader/predict_server.py", line 922, in main_with_return_value
    model = load_model(config, log_levels)
  File "/tmp/tactician.tmp.KzuMtE/target-source/venv/lib/python3.10/site-packages/graph2tac/loader/predict_server.py", line 871, in load_model
    model = TFGNNPredict(log_dir=Path(config.model).expanduser().absolute(),
  File "/tmp/tactician.tmp.KzuMtE/target-source/venv/lib/python3.10/site-packages/graph2tac/tfgnn/predict.py", line 620, in __init__
    self._compile_network()
  File "/tmp/tactician.tmp.KzuMtE/target-source/venv/lib/python3.10/site-packages/graph2tac/tfgnn/predict.py", line 685, in _compile_network
    inference_model_bare = self.prediction_task.create_inference_model(
  File "/tmp/tactician.tmp.KzuMtE/target-source/venv/lib/python3.10/site-packages/graph2tac/tfgnn/tasks.py", line 1343, in create_inference_model
    tactic, top_k_values = self._top_k_tactics(tactic_logits=tactic_logits,
  File "/tmp/tactician.tmp.KzuMtE/target-source/venv/lib/python3.10/site-packages/graph2tac/tfgnn/tasks.py", line 561, in _top_k_tactics
    top_k = tf.math.top_k(tactic_logits, k=tactic_expand_bound)
  File "/tmp/tactician.tmp.KzuMtE/target-source/venv/lib/python3.10/site-packages/tensorflow/python/util/traceback_utils.py", line 153, in error_handler
    raise e.with_traceback(filtered_tb) from None
  File "/tmp/tactician.tmp.KzuMtE/target-source/venv/lib/python3.10/site-packages/keras/layers/core/tf_op_layer.py", line 107, in handle
    return TFOpLambda(op)(*args, **kwargs)
  File "/tmp/tactician.tmp.KzuMtE/target-source/venv/lib/python3.10/site-packages/keras/utils/traceback_utils.py", line 67, in error_handler
    raise e.with_traceback(filtered_tb) from None
ValueError: Exception encountered when calling layer "tf.math.top_k" (type TFOpLambda).

input must have last dimension >= k = 2048 but is 1247 for '{{node tf.math.top_k/TopKV2}} = TopKV2[T=DT_FLOAT, sorted=true](Placeholder, tf.math.top_k/TopKV2/k)' with input shapes: [?,1247], [] and with computed input tensors: input[1] = <2048>.

Call arguments received by layer "tf.math.top_k" (type TFOpLambda):
  • input=tf.Tensor(shape=(None, 1247), dtype=float32)
  • k=2048
  • sorted=True
  • name=None
File "./contact.v", line 160, characters 0-7:
Error:
Anomaly "Uncaught exception Unix.Unix_error(Unix.EPIPE, "single_write", "")."
Please report at http://coq.inria.fr/bugs/.

File "./equations_cercles.v", line 48, characters 0-8:
Error:
Anomaly "Uncaught exception Unix.Unix_error(Unix.EPIPE, "single_write", "")."
Please report at http://coq.inria.fr/bugs/.

File "./applications_cocyclicite.v", line 380, characters 0-7:
Error:
Anomaly "Uncaught exception Unix.Unix_error(Unix.EPIPE, "single_write", "")."
Please report at http://coq.inria.fr/bugs/.

File "./homoth_Euler.v", line 193, characters 0-7:
Error:
Anomaly "Uncaught exception Unix.Unix_error(Unix.EPIPE, "single_write", "")."
Please report at http://coq.inria.fr/bugs/.

File "./exercice_morley.v", line 121, characters 0-7:
Error:
Anomaly "Uncaught exception Unix.Unix_error(Unix.EPIPE, "single_write", "")."
Please report at http://coq.inria.fr/bugs/.

File "./inversion.v", line 65, characters 0-7:
Error:
Anomaly "Uncaught exception Unix.Unix_error(Unix.EPIPE, "single_write", "")."
Please report at http://coq.inria.fr/bugs/.

File "./complements_cercle.v", line 91, characters 0-7:
Error:
Anomaly "Uncaught exception Unix.Unix_error(Unix.EPIPE, "single_write", "")."
Please report at http://coq.inria.fr/bugs/.

File "./transformations_contact.v", line 358, characters 0-8:
Error:
Anomaly "Uncaught exception Unix.Unix_error(Unix.EPIPE, "single_write", "")."
Please report at http://coq.inria.fr/bugs/.

File "./orientation.v", line 195, characters 0-34:
Error:
Anomaly "Uncaught exception Unix.Unix_error(Unix.EPIPE, "single_write", "")."
Please report at http://coq.inria.fr/bugs/.

File "./triangles_semblables.v", line 40, characters 0-24:
Error:
Anomaly "Uncaught exception Unix.Unix_error(Unix.EPIPE, "single_write", "")."
Please report at http://coq.inria.fr/bugs/.

File "/tmp/tactician.tmp.KzuMtE/opam-root/bench/lib/coq/user-contrib/Tactician/Graph2TacConfig.v", line 1, characters 0-32:
Warning: There is no option Tactician Neural Truncate.
[unknown-option,option]
File "/tmp/tactician.tmp.KzuMtE/opam-root/bench/lib/coq/user-contrib/Tactician/Graph2TacConfig.v", line 1, characters 0-32:
Warning: There is no option Tactician Neural Truncate.
[unknown-option,option]
Traceback (most recent call last):
  File "/tmp/tactician.tmp.KzuMtE/target-source/venv/bin/g2t-server", line 33, in <module>
    sys.exit(load_entry_point('graph2tac==0.1.0', 'console_scripts', 'g2t-server')())
  File "/tmp/tactician.tmp.KzuMtE/target-source/venv/lib/python3.10/site-packages/graph2tac/loader/predict_server.py", line 967, in main
    main_with_return_value()
  File "/tmp/tactician.tmp.KzuMtE/target-source/venv/lib/python3.10/site-packages/graph2tac/loader/predict_server.py", line 922, in main_with_return_value
    model = load_model(config, log_levels)
  File "/tmp/tactician.tmp.KzuMtE/target-source/venv/lib/python3.10/site-packages/graph2tac/loader/predict_server.py", line 871, in load_model
    model = TFGNNPredict(log_dir=Path(config.model).expanduser().absolute(),
  File "/tmp/tactician.tmp.KzuMtE/target-source/venv/lib/python3.10/site-packages/graph2tac/tfgnn/predict.py", line 620, in __init__
    self._compile_network()
  File "/tmp/tactician.tmp.KzuMtE/target-source/venv/lib/python3.10/site-packages/graph2tac/tfgnn/predict.py", line 685, in _compile_network
    inference_model_bare = self.prediction_task.create_inference_model(
  File "/tmp/tactician.tmp.KzuMtE/target-source/venv/lib/python3.10/site-packages/graph2tac/tfgnn/tasks.py", line 1343, in create_inference_model
    tactic, top_k_values = self._top_k_tactics(tactic_logits=tactic_logits,
  File "/tmp/tactician.tmp.KzuMtE/target-source/venv/lib/python3.10/site-packages/graph2tac/tfgnn/tasks.py", line 561, in _top_k_tactics
    top_k = tf.math.top_k(tactic_logits, k=tactic_expand_bound)
  File "/tmp/tactician.tmp.KzuMtE/target-source/venv/lib/python3.10/site-packages/tensorflow/python/util/traceback_utils.py", line 153, in error_handler
    raise e.with_traceback(filtered_tb) from None
  File "/tmp/tactician.tmp.KzuMtE/target-source/venv/lib/python3.10/site-packages/keras/layers/core/tf_op_layer.py", line 107, in handle
    return TFOpLambda(op)(*args, **kwargs)
  File "/tmp/tactician.tmp.KzuMtE/target-source/venv/lib/python3.10/site-packages/keras/utils/traceback_utils.py", line 67, in error_handler
    raise e.with_traceback(filtered_tb) from None
ValueError: Exception encountered when calling layer "tf.math.top_k" (type TFOpLambda).

input must have last dimension >= k = 2048 but is 1247 for '{{node tf.math.top_k/TopKV2}} = TopKV2[T=DT_FLOAT, sorted=true](Placeholder, tf.math.top_k/TopKV2/k)' with input shapes: [?,1247], [] and with computed input tensors: input[1] = <2048>.

Call arguments received by layer "tf.math.top_k" (type TFOpLambda):
  • input=tf.Tensor(shape=(None, 1247), dtype=float32)
  • k=2048
  • sorted=True
  • name=None
Traceback (most recent call last):
  File "/tmp/tactician.tmp.KzuMtE/target-source/venv/bin/g2t-server", line 33, in <module>
    sys.exit(load_entry_point('graph2tac==0.1.0', 'console_scripts', 'g2t-server')())
  File "/tmp/tactician.tmp.KzuMtE/target-source/venv/lib/python3.10/site-packages/graph2tac/loader/predict_server.py", line 967, in main
    main_with_return_value()
  File "/tmp/tactician.tmp.KzuMtE/target-source/venv/lib/python3.10/site-packages/graph2tac/loader/predict_server.py", line 922, in main_with_return_value
    model = load_model(config, log_levels)
  File "/tmp/tactician.tmp.KzuMtE/target-source/venv/lib/python3.10/site-packages/graph2tac/loader/predict_server.py", line 871, in load_model
    model = TFGNNPredict(log_dir=Path(config.model).expanduser().absolute(),
  File "/tmp/tactician.tmp.KzuMtE/target-source/venv/lib/python3.10/site-packages/graph2tac/tfgnn/predict.py", line 620, in __init__
    self._compile_network()
  File "/tmp/tactician.tmp.KzuMtE/target-source/venv/lib/python3.10/site-packages/graph2tac/tfgnn/predict.py", line 685, in _compile_network
    inference_model_bare = self.prediction_task.create_inference_model(
  File "/tmp/tactician.tmp.KzuMtE/target-source/venv/lib/python3.10/site-packages/graph2tac/tfgnn/tasks.py", line 1343, in create_inference_model
    tactic, top_k_values = self._top_k_tactics(tactic_logits=tactic_logits,
  File "/tmp/tactician.tmp.KzuMtE/target-source/venv/lib/python3.10/site-packages/graph2tac/tfgnn/tasks.py", line 561, in _top_k_tactics
    top_k = tf.math.top_k(tactic_logits, k=tactic_expand_bound)
  File "/tmp/tactician.tmp.KzuMtE/target-source/venv/lib/python3.10/site-packages/tensorflow/python/util/traceback_utils.py", line 153, in error_handler
    raise e.with_traceback(filtered_tb) from None
  File "/tmp/tactician.tmp.KzuMtE/target-source/venv/lib/python3.10/site-packages/keras/layers/core/tf_op_layer.py", line 107, in handle
    return TFOpLambda(op)(*args, **kwargs)
  File "/tmp/tactician.tmp.KzuMtE/target-source/venv/lib/python3.10/site-packages/keras/utils/traceback_utils.py", line 67, in error_handler
    raise e.with_traceback(filtered_tb) from None
ValueError: Exception encountered when calling layer "tf.math.top_k" (type TFOpLambda).

input must have last dimension >= k = 2048 but is 1247 for '{{node tf.math.top_k/TopKV2}} = TopKV2[T=DT_FLOAT, sorted=true](Placeholder, tf.math.top_k/TopKV2/k)' with input shapes: [?,1247], [] and with computed input tensors: input[1] = <2048>.

Call arguments received by layer "tf.math.top_k" (type TFOpLambda):
  • input=tf.Tensor(shape=(None, 1247), dtype=float32)
  • k=2048
  • sorted=True
  • name=None
File "./complements_cercle.v", line 133, characters 0-38:
Error:
Anomaly "Uncaught exception Unix.Unix_error(Unix.EPIPE, "single_write", "")."
Please report at http://coq.inria.fr/bugs/.

File "./exercice_morley.v", line 272, characters 0-7:
Error:
Anomaly "Uncaught exception Unix.Unix_error(Unix.EPIPE, "single_write", "")."
Please report at http://coq.inria.fr/bugs/.

File "./contact.v", line 406, characters 0-8:
Error:
Anomaly "Uncaught exception Unix.Unix_error(Unix.EPIPE, "single_write", "")."
Please report at http://coq.inria.fr/bugs/.

File "./transformations_contact.v", line 377, characters 0-7:
Error:
Anomaly "Uncaught exception Unix.Unix_error(Unix.EPIPE, "single_write", "")."
Please report at http://coq.inria.fr/bugs/.

File "./applications_cocyclicite.v", line 477, characters 0-61:
Error:
Anomaly "Uncaught exception Unix.Unix_error(Unix.EPIPE, "single_write", "")."
Please report at http://coq.inria.fr/bugs/.

File "/tmp/tactician.tmp.KzuMtE/opam-root/bench/lib/coq/user-contrib/Tactician/Graph2TacConfig.v", line 1, characters 0-32:
Warning: There is no option Tactician Neural Truncate.
[unknown-option,option]
File "./orientation.v", line 205, characters 0-34:
Error:
Anomaly "Uncaught exception Unix.Unix_error(Unix.EPIPE, "single_write", "")."
Please report at http://coq.inria.fr/bugs/.

File "./triangles_semblables.v", line 49, characters 0-24:
Error:
Anomaly "Uncaught exception Unix.Unix_error(Unix.EPIPE, "single_write", "")."
Please report at http://coq.inria.fr/bugs/.

Traceback (most recent call last):
  File "/tmp/tactician.tmp.KzuMtE/target-source/venv/bin/g2t-server", line 33, in <module>
    sys.exit(load_entry_point('graph2tac==0.1.0', 'console_scripts', 'g2t-server')())
  File "/tmp/tactician.tmp.KzuMtE/target-source/venv/lib/python3.10/site-packages/graph2tac/loader/predict_server.py", line 967, in main
    main_with_return_value()
  File "/tmp/tactician.tmp.KzuMtE/target-source/venv/lib/python3.10/site-packages/graph2tac/loader/predict_server.py", line 922, in main_with_return_value
    model = load_model(config, log_levels)
  File "/tmp/tactician.tmp.KzuMtE/target-source/venv/lib/python3.10/site-packages/graph2tac/loader/predict_server.py", line 871, in load_model
    model = TFGNNPredict(log_dir=Path(config.model).expanduser().absolute(),
  File "/tmp/tactician.tmp.KzuMtE/target-source/venv/lib/python3.10/site-packages/graph2tac/tfgnn/predict.py", line 620, in __init__
    self._compile_network()
  File "/tmp/tactician.tmp.KzuMtE/target-source/venv/lib/python3.10/site-packages/graph2tac/tfgnn/predict.py", line 685, in _compile_network
    inference_model_bare = self.prediction_task.create_inference_model(
  File "/tmp/tactician.tmp.KzuMtE/target-source/venv/lib/python3.10/site-packages/graph2tac/tfgnn/tasks.py", line 1343, in create_inference_model
    tactic, top_k_values = self._top_k_tactics(tactic_logits=tactic_logits,
  File "/tmp/tactician.tmp.KzuMtE/target-source/venv/lib/python3.10/site-packages/graph2tac/tfgnn/tasks.py", line 561, in _top_k_tactics
    top_k = tf.math.top_k(tactic_logits, k=tactic_expand_bound)
  File "/tmp/tactician.tmp.KzuMtE/target-source/venv/lib/python3.10/site-packages/tensorflow/python/util/traceback_utils.py", line 153, in error_handler
    raise e.with_traceback(filtered_tb) from None
  File "/tmp/tactician.tmp.KzuMtE/target-source/venv/lib/python3.10/site-packages/keras/layers/core/tf_op_layer.py", line 107, in handle
    return TFOpLambda(op)(*args, **kwargs)
  File "/tmp/tactician.tmp.KzuMtE/target-source/venv/lib/python3.10/site-packages/keras/utils/traceback_utils.py", line 67, in error_handler
    raise e.with_traceback(filtered_tb) from None
ValueError: Exception encountered when calling layer "tf.math.top_k" (type TFOpLambda).

input must have last dimension >= k = 2048 but is 1247 for '{{node tf.math.top_k/TopKV2}} = TopKV2[T=DT_FLOAT, sorted=true](Placeholder, tf.math.top_k/TopKV2/k)' with input shapes: [?,1247], [] and with computed input tensors: input[1] = <2048>.

Call arguments received by layer "tf.math.top_k" (type TFOpLambda):
  • input=tf.Tensor(shape=(None, 1247), dtype=float32)
  • k=2048
  • sorted=True
  • name=None
File "./homothetie_plane.v", line 108, characters 0-7:
Error:
Anomaly "Uncaught exception Unix.Unix_error(Unix.EPIPE, "single_write", "")."
Please report at http://coq.inria.fr/bugs/.

File "./cocyclicite.v", line 252, characters 0-44:
Error:
Anomaly "Uncaught exception Unix.Unix_error(Unix.EPIPE, "single_write", "")."
Please report at http://coq.inria.fr/bugs/.

File "./complexes_dilatations.v", line 415, characters 0-7:
Error:
Anomaly "Uncaught exception Unix.Unix_error(Unix.EPIPE, "single_write", "")."
Please report at http://coq.inria.fr/bugs/.

File "/tmp/tactician.tmp.KzuMtE/opam-root/bench/lib/coq/user-contrib/Tactician/Graph2TacConfig.v", line 1, characters 0-32:
Warning: There is no option Tactician Neural Truncate.
[unknown-option,option]
File "/tmp/tactician.tmp.KzuMtE/opam-root/bench/lib/coq/user-contrib/Tactician/Graph2TacConfig.v", line 1, characters 0-32:
Warning: There is no option Tactician Neural Truncate.
[unknown-option,option]
File "/tmp/tactician.tmp.KzuMtE/opam-root/bench/lib/coq/user-contrib/Tactician/Graph2TacConfig.v", line 1, characters 0-32:
Warning: There is no option Tactician Neural Truncate.
[unknown-option,option]
File "./complements_cercle.v", line 149, characters 0-8:
Error:
Anomaly "Uncaught exception Unix.Unix_error(Unix.EPIPE, "single_write", "")."
Please report at http://coq.inria.fr/bugs/.

Traceback (most recent call last):
  File "/tmp/tactician.tmp.KzuMtE/target-source/venv/bin/g2t-server", line 33, in <module>
    sys.exit(load_entry_point('graph2tac==0.1.0', 'console_scripts', 'g2t-server')())
  File "/tmp/tactician.tmp.KzuMtE/target-source/venv/lib/python3.10/site-packages/graph2tac/loader/predict_server.py", line 967, in main
    main_with_return_value()
  File "/tmp/tactician.tmp.KzuMtE/target-source/venv/lib/python3.10/site-packages/graph2tac/loader/predict_server.py", line 922, in main_with_return_value
    model = load_model(config, log_levels)
  File "/tmp/tactician.tmp.KzuMtE/target-source/venv/lib/python3.10/site-packages/graph2tac/loader/predict_server.py", line 871, in load_model
    model = TFGNNPredict(log_dir=Path(config.model).expanduser().absolute(),
  File "/tmp/tactician.tmp.KzuMtE/target-source/venv/lib/python3.10/site-packages/graph2tac/tfgnn/predict.py", line 620, in __init__
    self._compile_network()
  File "/tmp/tactician.tmp.KzuMtE/target-source/venv/lib/python3.10/site-packages/graph2tac/tfgnn/predict.py", line 685, in _compile_network
    inference_model_bare = self.prediction_task.create_inference_model(
  File "/tmp/tactician.tmp.KzuMtE/target-source/venv/lib/python3.10/site-packages/graph2tac/tfgnn/tasks.py", line 1343, in create_inference_model
    tactic, top_k_values = self._top_k_tactics(tactic_logits=tactic_logits,
  File "/tmp/tactician.tmp.KzuMtE/target-source/venv/lib/python3.10/site-packages/graph2tac/tfgnn/tasks.py", line 561, in _top_k_tactics
    top_k = tf.math.top_k(tactic_logits, k=tactic_expand_bound)
  File "/tmp/tactician.tmp.KzuMtE/target-source/venv/lib/python3.10/site-packages/tensorflow/python/util/traceback_utils.py", line 153, in error_handler
    raise e.with_traceback(filtered_tb) from None
  File "/tmp/tactician.tmp.KzuMtE/target-source/venv/lib/python3.10/site-packages/keras/layers/core/tf_op_layer.py", line 107, in handle
    return TFOpLambda(op)(*args, **kwargs)
  File "/tmp/tactician.tmp.KzuMtE/target-source/venv/lib/python3.10/site-packages/keras/utils/traceback_utils.py", line 67, in error_handler
    raise e.with_traceback(filtered_tb) from None
ValueError: Exception encountered when calling layer "tf.math.top_k" (type TFOpLambda).

input must have last dimension >= k = 2048 but is 1247 for '{{node tf.math.top_k/TopKV2}} = TopKV2[T=DT_FLOAT, sorted=true](Placeholder, tf.math.top_k/TopKV2/k)' with input shapes: [?,1247], [] and with computed input tensors: input[1] = <2048>.

Call arguments received by layer "tf.math.top_k" (type TFOpLambda):
  • input=tf.Tensor(shape=(None, 1247), dtype=float32)
  • k=2048
  • sorted=True
  • name=None
Traceback (most recent call last):
  File "/tmp/tactician.tmp.KzuMtE/target-source/venv/bin/g2t-server", line 33, in <module>
    sys.exit(load_entry_point('graph2tac==0.1.0', 'console_scripts', 'g2t-server')())
  File "/tmp/tactician.tmp.KzuMtE/target-source/venv/lib/python3.10/site-packages/graph2tac/loader/predict_server.py", line 967, in main
    main_with_return_value()
  File "/tmp/tactician.tmp.KzuMtE/target-source/venv/lib/python3.10/site-packages/graph2tac/loader/predict_server.py", line 922, in main_with_return_value
    model = load_model(config, log_levels)
  File "/tmp/tactician.tmp.KzuMtE/target-source/venv/lib/python3.10/site-packages/graph2tac/loader/predict_server.py", line 871, in load_model
    model = TFGNNPredict(log_dir=Path(config.model).expanduser().absolute(),
  File "/tmp/tactician.tmp.KzuMtE/target-source/venv/lib/python3.10/site-packages/graph2tac/tfgnn/predict.py", line 620, in __init__
    self._compile_network()
  File "/tmp/tactician.tmp.KzuMtE/target-source/venv/lib/python3.10/site-packages/graph2tac/tfgnn/predict.py", line 685, in _compile_network
    inference_model_bare = self.prediction_task.create_inference_model(
  File "/tmp/tactician.tmp.KzuMtE/target-source/venv/lib/python3.10/site-packages/graph2tac/tfgnn/tasks.py", line 1343, in create_inference_model
    tactic, top_k_values = self._top_k_tactics(tactic_logits=tactic_logits,
  File "/tmp/tactician.tmp.KzuMtE/target-source/venv/lib/python3.10/site-packages/graph2tac/tfgnn/tasks.py", line 561, in _top_k_tactics
    top_k = tf.math.top_k(tactic_logits, k=tactic_expand_bound)
  File "/tmp/tactician.tmp.KzuMtE/target-source/venv/lib/python3.10/site-packages/tensorflow/python/util/traceback_utils.py", line 153, in error_handler
    raise e.with_traceback(filtered_tb) from None
  File "/tmp/tactician.tmp.KzuMtE/target-source/venv/lib/python3.10/site-packages/keras/layers/core/tf_op_layer.py", line 107, in handle
    return TFOpLambda(op)(*args, **kwargs)
  File "/tmp/tactician.tmp.KzuMtE/target-source/venv/lib/python3.10/site-packages/keras/utils/traceback_utils.py", line 67, in error_handler
    raise e.with_traceback(filtered_tb) from None
ValueError: Exception encountered when calling layer "tf.math.top_k" (type TFOpLambda).

input must have last dimension >= k = 2048 but is 1247 for '{{node tf.math.top_k/TopKV2}} = TopKV2[T=DT_FLOAT, sorted=true](Placeholder, tf.math.top_k/TopKV2/k)' with input shapes: [?,1247], [] and with computed input tensors: input[1] = <2048>.

Call arguments received by layer "tf.math.top_k" (type TFOpLambda):
  • input=tf.Tensor(shape=(None, 1247), dtype=float32)
  • k=2048
  • sorted=True
  • name=None
Traceback (most recent call last):
  File "/tmp/tactician.tmp.KzuMtE/target-source/venv/bin/g2t-server", line 33, in <module>
    sys.exit(load_entry_point('graph2tac==0.1.0', 'console_scripts', 'g2t-server')())
  File "/tmp/tactician.tmp.KzuMtE/target-source/venv/lib/python3.10/site-packages/graph2tac/loader/predict_server.py", line 967, in main
    main_with_return_value()
  File "/tmp/tactician.tmp.KzuMtE/target-source/venv/lib/python3.10/site-packages/graph2tac/loader/predict_server.py", line 922, in main_with_return_value
    model = load_model(config, log_levels)
  File "/tmp/tactician.tmp.KzuMtE/target-source/venv/lib/python3.10/site-packages/graph2tac/loader/predict_server.py", line 871, in load_model
    model = TFGNNPredict(log_dir=Path(config.model).expanduser().absolute(),
  File "/tmp/tactician.tmp.KzuMtE/target-source/venv/lib/python3.10/site-packages/graph2tac/tfgnn/predict.py", line 620, in __init__
    self._compile_network()
  File "/tmp/tactician.tmp.KzuMtE/target-source/venv/lib/python3.10/site-packages/graph2tac/tfgnn/predict.py", line 685, in _compile_network
    inference_model_bare = self.prediction_task.create_inference_model(
  File "/tmp/tactician.tmp.KzuMtE/target-source/venv/lib/python3.10/site-packages/graph2tac/tfgnn/tasks.py", line 1343, in create_inference_model
    tactic, top_k_values = self._top_k_tactics(tactic_logits=tactic_logits,
  File "/tmp/tactician.tmp.KzuMtE/target-source/venv/lib/python3.10/site-packages/graph2tac/tfgnn/tasks.py", line 561, in _top_k_tactics
    top_k = tf.math.top_k(tactic_logits, k=tactic_expand_bound)
  File "/tmp/tactician.tmp.KzuMtE/target-source/venv/lib/python3.10/site-packages/tensorflow/python/util/traceback_utils.py", line 153, in error_handler
    raise e.with_traceback(filtered_tb) from None
  File "/tmp/tactician.tmp.KzuMtE/target-source/venv/lib/python3.10/site-packages/keras/layers/core/tf_op_layer.py", line 107, in handle
    return TFOpLambda(op)(*args, **kwargs)
  File "/tmp/tactician.tmp.KzuMtE/target-source/venv/lib/python3.10/site-packages/keras/utils/traceback_utils.py", line 67, in error_handler
    raise e.with_traceback(filtered_tb) from None
ValueError: Exception encountered when calling layer "tf.math.top_k" (type TFOpLambda).

input must have last dimension >= k = 2048 but is 1247 for '{{node tf.math.top_k/TopKV2}} = TopKV2[T=DT_FLOAT, sorted=true](Placeholder, tf.math.top_k/TopKV2/k)' with input shapes: [?,1247], [] and with computed input tensors: input[1] = <2048>.

Call arguments received by layer "tf.math.top_k" (type TFOpLambda):
  • input=tf.Tensor(shape=(None, 1247), dtype=float32)
  • k=2048
  • sorted=True
  • name=None
File "./exercice_morley.v", line 770, characters 0-7:
Error:
Anomaly "Uncaught exception Unix.Unix_error(Unix.EPIPE, "single_write", "")."
Please report at http://coq.inria.fr/bugs/.

File "./orientation.v", line 218, characters 0-34:
Error:
Anomaly "Uncaught exception Unix.Unix_error(Unix.EPIPE, "single_write", "")."
Please report at http://coq.inria.fr/bugs/.

File "/tmp/tactician.tmp.KzuMtE/opam-root/bench/lib/coq/user-contrib/Tactician/Graph2TacConfig.v", line 1, characters 0-32:
Warning: There is no option Tactician Neural Truncate.
[unknown-option,option]
File "./triangles_semblables.v", line 116, characters 0-14:
Error:
Anomaly "Uncaught exception Unix.Unix_error(Unix.EPIPE, "single_write", "")."
Please report at http://coq.inria.fr/bugs/.

Traceback (most recent call last):
  File "/tmp/tactician.tmp.KzuMtE/target-source/venv/bin/g2t-server", line 33, in <module>
    sys.exit(load_entry_point('graph2tac==0.1.0', 'console_scripts', 'g2t-server')())
  File "/tmp/tactician.tmp.KzuMtE/target-source/venv/lib/python3.10/site-packages/graph2tac/loader/predict_server.py", line 967, in main
    main_with_return_value()
  File "/tmp/tactician.tmp.KzuMtE/target-source/venv/lib/python3.10/site-packages/graph2tac/loader/predict_server.py", line 922, in main_with_return_value
    model = load_model(config, log_levels)
  File "/tmp/tactician.tmp.KzuMtE/target-source/venv/lib/python3.10/site-packages/graph2tac/loader/predict_server.py", line 871, in load_model
    model = TFGNNPredict(log_dir=Path(config.model).expanduser().absolute(),
  File "/tmp/tactician.tmp.KzuMtE/target-source/venv/lib/python3.10/site-packages/graph2tac/tfgnn/predict.py", line 620, in __init__
    self._compile_network()
  File "/tmp/tactician.tmp.KzuMtE/target-source/venv/lib/python3.10/site-packages/graph2tac/tfgnn/predict.py", line 685, in _compile_network
    inference_model_bare = self.prediction_task.create_inference_model(
  File "/tmp/tactician.tmp.KzuMtE/target-source/venv/lib/python3.10/site-packages/graph2tac/tfgnn/tasks.py", line 1343, in create_inference_model
    tactic, top_k_values = self._top_k_tactics(tactic_logits=tactic_logits,
  File "/tmp/tactician.tmp.KzuMtE/target-source/venv/lib/python3.10/site-packages/graph2tac/tfgnn/tasks.py", line 561, in _top_k_tactics
    top_k = tf.math.top_k(tactic_logits, k=tactic_expand_bound)
  File "/tmp/tactician.tmp.KzuMtE/target-source/venv/lib/python3.10/site-packages/tensorflow/python/util/traceback_utils.py", line 153, in error_handler
    raise e.with_traceback(filtered_tb) from None
  File "/tmp/tactician.tmp.KzuMtE/target-source/venv/lib/python3.10/site-packages/keras/layers/core/tf_op_layer.py", line 107, in handle
    return TFOpLambda(op)(*args, **kwargs)
  File "/tmp/tactician.tmp.KzuMtE/target-source/venv/lib/python3.10/site-packages/keras/utils/traceback_utils.py", line 67, in error_handler
    raise e.with_traceback(filtered_tb) from None
ValueError: Exception encountered when calling layer "tf.math.top_k" (type TFOpLambda).

input must have last dimension >= k = 2048 but is 1247 for '{{node tf.math.top_k/TopKV2}} = TopKV2[T=DT_FLOAT, sorted=true](Placeholder, tf.math.top_k/TopKV2/k)' with input shapes: [?,1247], [] and with computed input tensors: input[1] = <2048>.

Call arguments received by layer "tf.math.top_k" (type TFOpLambda):
  • input=tf.Tensor(shape=(None, 1247), dtype=float32)
  • k=2048
  • sorted=True
  • name=None
File "./cercle.v", line 30, characters 0-36:
Error:
Anomaly "Uncaught exception Unix.Unix_error(Unix.EPIPE, "single_write", "")."
Please report at http://coq.inria.fr/bugs/.

File "/tmp/tactician.tmp.KzuMtE/opam-root/bench/lib/coq/user-contrib/Tactician/Graph2TacConfig.v", line 1, characters 0-32:
Warning: There is no option Tactician Neural Truncate.
[unknown-option,option]
File "./operations_complexes.v", line 72, characters 0-7:
Error:
Anomaly "Uncaught exception Unix.Unix_error(Unix.EPIPE, "single_write", "")."
Please report at http://coq.inria.fr/bugs/.

File "/tmp/tactician.tmp.KzuMtE/opam-root/bench/lib/coq/user-contrib/Tactician/Graph2TacConfig.v", line 1, characters 0-32:
Warning: There is no option Tactician Neural Truncate.
[unknown-option,option]
File "./reflexion_plane.v", line 725, characters 0-32:
Error:
Anomaly "Uncaught exception Unix.Unix_error(Unix.EPIPE, "single_write", "")."
Please report at http://coq.inria.fr/bugs/.

Traceback (most recent call last):
  File "/tmp/tactician.tmp.KzuMtE/target-source/venv/bin/g2t-server", line 33, in <module>
    sys.exit(load_entry_point('graph2tac==0.1.0', 'console_scripts', 'g2t-server')())
  File "/tmp/tactician.tmp.KzuMtE/target-source/venv/lib/python3.10/site-packages/graph2tac/loader/predict_server.py", line 967, in main
    main_with_return_value()
  File "/tmp/tactician.tmp.KzuMtE/target-source/venv/lib/python3.10/site-packages/graph2tac/loader/predict_server.py", line 922, in main_with_return_value
    model = load_model(config, log_levels)
  File "/tmp/tactician.tmp.KzuMtE/target-source/venv/lib/python3.10/site-packages/graph2tac/loader/predict_server.py", line 871, in load_model
    model = TFGNNPredict(log_dir=Path(config.model).expanduser().absolute(),
  File "/tmp/tactician.tmp.KzuMtE/target-source/venv/lib/python3.10/site-packages/graph2tac/tfgnn/predict.py", line 620, in __init__
    self._compile_network()
  File "/tmp/tactician.tmp.KzuMtE/target-source/venv/lib/python3.10/site-packages/graph2tac/tfgnn/predict.py", line 685, in _compile_network
    inference_model_bare = self.prediction_task.create_inference_model(
  File "/tmp/tactician.tmp.KzuMtE/target-source/venv/lib/python3.10/site-packages/graph2tac/tfgnn/tasks.py", line 1343, in create_inference_model
    tactic, top_k_values = self._top_k_tactics(tactic_logits=tactic_logits,
  File "/tmp/tactician.tmp.KzuMtE/target-source/venv/lib/python3.10/site-packages/graph2tac/tfgnn/tasks.py", line 561, in _top_k_tactics
    top_k = tf.math.top_k(tactic_logits, k=tactic_expand_bound)
  File "/tmp/tactician.tmp.KzuMtE/target-source/venv/lib/python3.10/site-packages/tensorflow/python/util/traceback_utils.py", line 153, in error_handler
    raise e.with_traceback(filtered_tb) from None
  File "/tmp/tactician.tmp.KzuMtE/target-source/venv/lib/python3.10/site-packages/keras/layers/core/tf_op_layer.py", line 107, in handle
    return TFOpLambda(op)(*args, **kwargs)
  File "/tmp/tactician.tmp.KzuMtE/target-source/venv/lib/python3.10/site-packages/keras/utils/traceback_utils.py", line 67, in error_handler
    raise e.with_traceback(filtered_tb) from None
ValueError: Exception encountered when calling layer "tf.math.top_k" (type TFOpLambda).

input must have last dimension >= k = 2048 but is 1247 for '{{node tf.math.top_k/TopKV2}} = TopKV2[T=DT_FLOAT, sorted=true](Placeholder, tf.math.top_k/TopKV2/k)' with input shapes: [?,1247], [] and with computed input tensors: input[1] = <2048>.

Call arguments received by layer "tf.math.top_k" (type TFOpLambda):
  • input=tf.Tensor(shape=(None, 1247), dtype=float32)
  • k=2048
  • sorted=True
  • name=None
Traceback (most recent call last):
  File "/tmp/tactician.tmp.KzuMtE/target-source/venv/bin/g2t-server", line 33, in <module>
    sys.exit(load_entry_point('graph2tac==0.1.0', 'console_scripts', 'g2t-server')())
  File "/tmp/tactician.tmp.KzuMtE/target-source/venv/lib/python3.10/site-packages/graph2tac/loader/predict_server.py", line 967, in main
    main_with_return_value()
  File "/tmp/tactician.tmp.KzuMtE/target-source/venv/lib/python3.10/site-packages/graph2tac/loader/predict_server.py", line 922, in main_with_return_value
    model = load_model(config, log_levels)
  File "/tmp/tactician.tmp.KzuMtE/target-source/venv/lib/python3.10/site-packages/graph2tac/loader/predict_server.py", line 871, in load_model
    model = TFGNNPredict(log_dir=Path(config.model).expanduser().absolute(),
  File "/tmp/tactician.tmp.KzuMtE/target-source/venv/lib/python3.10/site-packages/graph2tac/tfgnn/predict.py", line 620, in __init__
    self._compile_network()
  File "/tmp/tactician.tmp.KzuMtE/target-source/venv/lib/python3.10/site-packages/graph2tac/tfgnn/predict.py", line 685, in _compile_network
    inference_model_bare = self.prediction_task.create_inference_model(
  File "/tmp/tactician.tmp.KzuMtE/target-source/venv/lib/python3.10/site-packages/graph2tac/tfgnn/tasks.py", line 1343, in create_inference_model
    tactic, top_k_values = self._top_k_tactics(tactic_logits=tactic_logits,
  File "/tmp/tactician.tmp.KzuMtE/target-source/venv/lib/python3.10/site-packages/graph2tac/tfgnn/tasks.py", line 561, in _top_k_tactics
    top_k = tf.math.top_k(tactic_logits, k=tactic_expand_bound)
  File "/tmp/tactician.tmp.KzuMtE/target-source/venv/lib/python3.10/site-packages/tensorflow/python/util/traceback_utils.py", line 153, in error_handler
    raise e.with_traceback(filtered_tb) from None
  File "/tmp/tactician.tmp.KzuMtE/target-source/venv/lib/python3.10/site-packages/keras/layers/core/tf_op_layer.py", line 107, in handle
    return TFOpLambda(op)(*args, **kwargs)
  File "/tmp/tactician.tmp.KzuMtE/target-source/venv/lib/python3.10/site-packages/keras/utils/traceback_utils.py", line 67, in error_handler
    raise e.with_traceback(filtered_tb) from None
ValueError: Exception encountered when calling layer "tf.math.top_k" (type TFOpLambda).

input must have last dimension >= k = 2048 but is 1247 for '{{node tf.math.top_k/TopKV2}} = TopKV2[T=DT_FLOAT, sorted=true](Placeholder, tf.math.top_k/TopKV2/k)' with input shapes: [?,1247], [] and with computed input tensors: input[1] = <2048>.

Call arguments received by layer "tf.math.top_k" (type TFOpLambda):
  • input=tf.Tensor(shape=(None, 1247), dtype=float32)
  • k=2048
  • sorted=True
  • name=None
File "./equations_droites.v", line 109, characters 0-71:
Error:
Anomaly "Uncaught exception Unix.Unix_error(Unix.EPIPE, "single_write", "")."
Please report at http://coq.inria.fr/bugs/.

File "./rotation_plane.v", line 392, characters 0-7:
Error:
Anomaly "Uncaught exception Unix.Unix_error(Unix.EPIPE, "single_write", "")."
Please report at http://coq.inria.fr/bugs/.

File "./determinant.v", line 30, characters 0-14:
Error:
Anomaly "Uncaught exception Unix.Unix_error(Unix.EPIPE, "single_write", "")."
Please report at http://coq.inria.fr/bugs/.

File "/tmp/tactician.tmp.KzuMtE/opam-root/bench/lib/coq/user-contrib/Tactician/Graph2TacConfig.v", line 1, characters 0-32:
Warning: There is no option Tactician Neural Truncate.
[unknown-option,option]
File "./complements_cercle.v", line 221, characters 0-57:
Error:
Anomaly "Uncaught exception Unix.Unix_error(Unix.EPIPE, "single_write", "")."
Please report at http://coq.inria.fr/bugs/.

Traceback (most recent call last):
  File "/tmp/tactician.tmp.KzuMtE/target-source/venv/bin/g2t-server", line 33, in <module>
    sys.exit(load_entry_point('graph2tac==0.1.0', 'console_scripts', 'g2t-server')())
  File "/tmp/tactician.tmp.KzuMtE/target-source/venv/lib/python3.10/site-packages/graph2tac/loader/predict_server.py", line 967, in main
    main_with_return_value()
  File "/tmp/tactician.tmp.KzuMtE/target-source/venv/lib/python3.10/site-packages/graph2tac/loader/predict_server.py", line 922, in main_with_return_value
    model = load_model(config, log_levels)
  File "/tmp/tactician.tmp.KzuMtE/target-source/venv/lib/python3.10/site-packages/graph2tac/loader/predict_server.py", line 871, in load_model
    model = TFGNNPredict(log_dir=Path(config.model).expanduser().absolute(),
  File "/tmp/tactician.tmp.KzuMtE/target-source/venv/lib/python3.10/site-packages/graph2tac/tfgnn/predict.py", line 620, in __init__
    self._compile_network()
  File "/tmp/tactician.tmp.KzuMtE/target-source/venv/lib/python3.10/site-packages/graph2tac/tfgnn/predict.py", line 685, in _compile_network
    inference_model_bare = self.prediction_task.create_inference_model(
  File "/tmp/tactician.tmp.KzuMtE/target-source/venv/lib/python3.10/site-packages/graph2tac/tfgnn/tasks.py", line 1343, in create_inference_model
    tactic, top_k_values = self._top_k_tactics(tactic_logits=tactic_logits,
  File "/tmp/tactician.tmp.KzuMtE/target-source/venv/lib/python3.10/site-packages/graph2tac/tfgnn/tasks.py", line 561, in _top_k_tactics
    top_k = tf.math.top_k(tactic_logits, k=tactic_expand_bound)
  File "/tmp/tactician.tmp.KzuMtE/target-source/venv/lib/python3.10/site-packages/tensorflow/python/util/traceback_utils.py", line 153, in error_handler
    raise e.with_traceback(filtered_tb) from None
  File "/tmp/tactician.tmp.KzuMtE/target-source/venv/lib/python3.10/site-packages/keras/layers/core/tf_op_layer.py", line 107, in handle
    return TFOpLambda(op)(*args, **kwargs)
  File "/tmp/tactician.tmp.KzuMtE/target-source/venv/lib/python3.10/site-packages/keras/utils/traceback_utils.py", line 67, in error_handler
    raise e.with_traceback(filtered_tb) from None
ValueError: Exception encountered when calling layer "tf.math.top_k" (type TFOpLambda).

input must have last dimension >= k = 2048 but is 1247 for '{{node tf.math.top_k/TopKV2}} = TopKV2[T=DT_FLOAT, sorted=true](Placeholder, tf.math.top_k/TopKV2/k)' with input shapes: [?,1247], [] and with computed input tensors: input[1] = <2048>.

Call arguments received by layer "tf.math.top_k" (type TFOpLambda):
  • input=tf.Tensor(shape=(None, 1247), dtype=float32)
  • k=2048
  • sorted=True
  • name=None
File "./orientation.v", line 228, characters 0-34:
Error:
Anomaly "Uncaught exception Unix.Unix_error(Unix.EPIPE, "single_write", "")."
Please report at http://coq.inria.fr/bugs/.

File "./triangles_semblables.v", line 134, characters 0-14:
Error:
Anomaly "Uncaught exception Unix.Unix_error(Unix.EPIPE, "single_write", "")."
Please report at http://coq.inria.fr/bugs/.

File "/tmp/tactician.tmp.KzuMtE/opam-root/bench/lib/coq/user-contrib/Tactician/Graph2TacConfig.v", line 1, characters 0-32:
Warning: There is no option Tactician Neural Truncate.
[unknown-option,option]
File "/tmp/tactician.tmp.KzuMtE/opam-root/bench/lib/coq/user-contrib/Tactician/Graph2TacConfig.v", line 1, characters 0-32:
Warning: There is no option Tactician Neural Truncate.
[unknown-option,option]
File "./formes_complexes.v", line 223, characters 0-7:
Error:
Anomaly "Uncaught exception Unix.Unix_error(Unix.EPIPE, "single_write", "")."
Please report at http://coq.inria.fr/bugs/.

Traceback (most recent call last):
  File "/tmp/tactician.tmp.KzuMtE/target-source/venv/bin/g2t-server", line 33, in <module>
    sys.exit(load_entry_point('graph2tac==0.1.0', 'console_scripts', 'g2t-server')())
  File "/tmp/tactician.tmp.KzuMtE/target-source/venv/lib/python3.10/site-packages/graph2tac/loader/predict_server.py", line 967, in main
    main_with_return_value()
  File "/tmp/tactician.tmp.KzuMtE/target-source/venv/lib/python3.10/site-packages/graph2tac/loader/predict_server.py", line 922, in main_with_return_value
    model = load_model(config, log_levels)
  File "/tmp/tactician.tmp.KzuMtE/target-source/venv/lib/python3.10/site-packages/graph2tac/loader/predict_server.py", line 871, in load_model
    model = TFGNNPredict(log_dir=Path(config.model).expanduser().absolute(),
  File "/tmp/tactician.tmp.KzuMtE/target-source/venv/lib/python3.10/site-packages/graph2tac/tfgnn/predict.py", line 620, in __init__
    self._compile_network()
  File "/tmp/tactician.tmp.KzuMtE/target-source/venv/lib/python3.10/site-packages/graph2tac/tfgnn/predict.py", line 685, in _compile_network
    inference_model_bare = self.prediction_task.create_inference_model(
  File "/tmp/tactician.tmp.KzuMtE/target-source/venv/lib/python3.10/site-packages/graph2tac/tfgnn/tasks.py", line 1343, in create_inference_model
    tactic, top_k_values = self._top_k_tactics(tactic_logits=tactic_logits,
  File "/tmp/tactician.tmp.KzuMtE/target-source/venv/lib/python3.10/site-packages/graph2tac/tfgnn/tasks.py", line 561, in _top_k_tactics
    top_k = tf.math.top_k(tactic_logits, k=tactic_expand_bound)
  File "/tmp/tactician.tmp.KzuMtE/target-source/venv/lib/python3.10/site-packages/tensorflow/python/util/traceback_utils.py", line 153, in error_handler
    raise e.with_traceback(filtered_tb) from None
  File "/tmp/tactician.tmp.KzuMtE/target-source/venv/lib/python3.10/site-packages/keras/layers/core/tf_op_layer.py", line 107, in handle
    return TFOpLambda(op)(*args, **kwargs)
  File "/tmp/tactician.tmp.KzuMtE/target-source/venv/lib/python3.10/site-packages/keras/utils/traceback_utils.py", line 67, in error_handler
    raise e.with_traceback(filtered_tb) from None
ValueError: Exception encountered when calling layer "tf.math.top_k" (type TFOpLambda).

input must have last dimension >= k = 2048 but is 1247 for '{{node tf.math.top_k/TopKV2}} = TopKV2[T=DT_FLOAT, sorted=true](Placeholder, tf.math.top_k/TopKV2/k)' with input shapes: [?,1247], [] and with computed input tensors: input[1] = <2048>.

Call arguments received by layer "tf.math.top_k" (type TFOpLambda):
  • input=tf.Tensor(shape=(None, 1247), dtype=float32)
  • k=2048
  • sorted=True
  • name=None
Traceback (most recent call last):
  File "/tmp/tactician.tmp.KzuMtE/target-source/venv/bin/g2t-server", line 33, in <module>
    sys.exit(load_entry_point('graph2tac==0.1.0', 'console_scripts', 'g2t-server')())
  File "/tmp/tactician.tmp.KzuMtE/target-source/venv/lib/python3.10/site-packages/graph2tac/loader/predict_server.py", line 967, in main
    main_with_return_value()
  File "/tmp/tactician.tmp.KzuMtE/target-source/venv/lib/python3.10/site-packages/graph2tac/loader/predict_server.py", line 922, in main_with_return_value
    model = load_model(config, log_levels)
  File "/tmp/tactician.tmp.KzuMtE/target-source/venv/lib/python3.10/site-packages/graph2tac/loader/predict_server.py", line 871, in load_model
    model = TFGNNPredict(log_dir=Path(config.model).expanduser().absolute(),
  File "/tmp/tactician.tmp.KzuMtE/target-source/venv/lib/python3.10/site-packages/graph2tac/tfgnn/predict.py", line 620, in __init__
    self._compile_network()
  File "/tmp/tactician.tmp.KzuMtE/target-source/venv/lib/python3.10/site-packages/graph2tac/tfgnn/predict.py", line 685, in _compile_network
    inference_model_bare = self.prediction_task.create_inference_model(
  File "/tmp/tactician.tmp.KzuMtE/target-source/venv/lib/python3.10/site-packages/graph2tac/tfgnn/tasks.py", line 1343, in create_inference_model
    tactic, top_k_values = self._top_k_tactics(tactic_logits=tactic_logits,
  File "/tmp/tactician.tmp.KzuMtE/target-source/venv/lib/python3.10/site-packages/graph2tac/tfgnn/tasks.py", line 561, in _top_k_tactics
    top_k = tf.math.top_k(tactic_logits, k=tactic_expand_bound)
  File "/tmp/tactician.tmp.KzuMtE/target-source/venv/lib/python3.10/site-packages/tensorflow/python/util/traceback_utils.py", line 153, in error_handler
    raise e.with_traceback(filtered_tb) from None
  File "/tmp/tactician.tmp.KzuMtE/target-source/venv/lib/python3.10/site-packages/keras/layers/core/tf_op_layer.py", line 107, in handle
    return TFOpLambda(op)(*args, **kwargs)
  File "/tmp/tactician.tmp.KzuMtE/target-source/venv/lib/python3.10/site-packages/keras/utils/traceback_utils.py", line 67, in error_handler
    raise e.with_traceback(filtered_tb) from None
ValueError: Exception encountered when calling layer "tf.math.top_k" (type TFOpLambda).

input must have last dimension >= k = 2048 but is 1247 for '{{node tf.math.top_k/TopKV2}} = TopKV2[T=DT_FLOAT, sorted=true](Placeholder, tf.math.top_k/TopKV2/k)' with input shapes: [?,1247], [] and with computed input tensors: input[1] = <2048>.

Call arguments received by layer "tf.math.top_k" (type TFOpLambda):
  • input=tf.Tensor(shape=(None, 1247), dtype=float32)
  • k=2048
  • sorted=True
  • name=None
File "./operations_complexes.v", line 193, characters 0-7:
Error:
Anomaly "Uncaught exception Unix.Unix_error(Unix.EPIPE, "single_write", "")."
Please report at http://coq.inria.fr/bugs/.

File "/tmp/tactician.tmp.KzuMtE/opam-root/bench/lib/coq/user-contrib/Tactician/Graph2TacConfig.v", line 1, characters 0-32:
Warning: There is no option Tactician Neural Truncate.
[unknown-option,option]
Traceback (most recent call last):
  File "/tmp/tactician.tmp.KzuMtE/target-source/venv/bin/g2t-server", line 33, in <module>
    sys.exit(load_entry_point('graph2tac==0.1.0', 'console_scripts', 'g2t-server')())
  File "/tmp/tactician.tmp.KzuMtE/target-source/venv/lib/python3.10/site-packages/graph2tac/loader/predict_server.py", line 967, in main
    main_with_return_value()
  File "/tmp/tactician.tmp.KzuMtE/target-source/venv/lib/python3.10/site-packages/graph2tac/loader/predict_server.py", line 922, in main_with_return_value
    model = load_model(config, log_levels)
  File "/tmp/tactician.tmp.KzuMtE/target-source/venv/lib/python3.10/site-packages/graph2tac/loader/predict_server.py", line 871, in load_model
    model = TFGNNPredict(log_dir=Path(config.model).expanduser().absolute(),
  File "/tmp/tactician.tmp.KzuMtE/target-source/venv/lib/python3.10/site-packages/graph2tac/tfgnn/predict.py", line 620, in __init__
    self._compile_network()
  File "/tmp/tactician.tmp.KzuMtE/target-source/venv/lib/python3.10/site-packages/graph2tac/tfgnn/predict.py", line 685, in _compile_network
    inference_model_bare = self.prediction_task.create_inference_model(
  File "/tmp/tactician.tmp.KzuMtE/target-source/venv/lib/python3.10/site-packages/graph2tac/tfgnn/tasks.py", line 1343, in create_inference_model
    tactic, top_k_values = self._top_k_tactics(tactic_logits=tactic_logits,
  File "/tmp/tactician.tmp.KzuMtE/target-source/venv/lib/python3.10/site-packages/graph2tac/tfgnn/tasks.py", line 561, in _top_k_tactics
    top_k = tf.math.top_k(tactic_logits, k=tactic_expand_bound)
  File "/tmp/tactician.tmp.KzuMtE/target-source/venv/lib/python3.10/site-packages/tensorflow/python/util/traceback_utils.py", line 153, in error_handler
    raise e.with_traceback(filtered_tb) from None
  File "/tmp/tactician.tmp.KzuMtE/target-source/venv/lib/python3.10/site-packages/keras/layers/core/tf_op_layer.py", line 107, in handle
    return TFOpLambda(op)(*args, **kwargs)
  File "/tmp/tactician.tmp.KzuMtE/target-source/venv/lib/python3.10/site-packages/keras/utils/traceback_utils.py", line 67, in error_handler
    raise e.with_traceback(filtered_tb) from None
ValueError: Exception encountered when calling layer "tf.math.top_k" (type TFOpLambda).

input must have last dimension >= k = 2048 but is 1247 for '{{node tf.math.top_k/TopKV2}} = TopKV2[T=DT_FLOAT, sorted=true](Placeholder, tf.math.top_k/TopKV2/k)' with input shapes: [?,1247], [] and with computed input tensors: input[1] = <2048>.

Call arguments received by layer "tf.math.top_k" (type TFOpLambda):
  • input=tf.Tensor(shape=(None, 1247), dtype=float32)
  • k=2048
  • sorted=True
  • name=None
File "/tmp/tactician.tmp.KzuMtE/opam-root/bench/lib/coq/user-contrib/Tactician/Graph2TacConfig.v", line 1, characters 0-32:
Warning: There is no option Tactician Neural Truncate.
[unknown-option,option]
File "./orthocentre.v", line 98, characters 0-7:
Error:
Anomaly "Uncaught exception Unix.Unix_error(Unix.EPIPE, "single_write", "")."
Please report at http://coq.inria.fr/bugs/.

Traceback (most recent call last):
  File "/tmp/tactician.tmp.KzuMtE/target-source/venv/bin/g2t-server", line 33, in <module>
    sys.exit(load_entry_point('graph2tac==0.1.0', 'console_scripts', 'g2t-server')())
  File "/tmp/tactician.tmp.KzuMtE/target-source/venv/lib/python3.10/site-packages/graph2tac/loader/predict_server.py", line 967, in main
    main_with_return_value()
  File "/tmp/tactician.tmp.KzuMtE/target-source/venv/lib/python3.10/site-packages/graph2tac/loader/predict_server.py", line 922, in main_with_return_value
    model = load_model(config, log_levels)
  File "/tmp/tactician.tmp.KzuMtE/target-source/venv/lib/python3.10/site-packages/graph2tac/loader/predict_server.py", line 871, in load_model
    model = TFGNNPredict(log_dir=Path(config.model).expanduser().absolute(),
  File "/tmp/tactician.tmp.KzuMtE/target-source/venv/lib/python3.10/site-packages/graph2tac/tfgnn/predict.py", line 620, in __init__
    self._compile_network()
  File "/tmp/tactician.tmp.KzuMtE/target-source/venv/lib/python3.10/site-packages/graph2tac/tfgnn/predict.py", line 685, in _compile_network
    inference_model_bare = self.prediction_task.create_inference_model(
  File "/tmp/tactician.tmp.KzuMtE/target-source/venv/lib/python3.10/site-packages/graph2tac/tfgnn/tasks.py", line 1343, in create_inference_model
    tactic, top_k_values = self._top_k_tactics(tactic_logits=tactic_logits,
  File "/tmp/tactician.tmp.KzuMtE/target-source/venv/lib/python3.10/site-packages/graph2tac/tfgnn/tasks.py", line 561, in _top_k_tactics
    top_k = tf.math.top_k(tactic_logits, k=tactic_expand_bound)
  File "/tmp/tactician.tmp.KzuMtE/target-source/venv/lib/python3.10/site-packages/tensorflow/python/util/traceback_utils.py", line 153, in error_handler
    raise e.with_traceback(filtered_tb) from None
  File "/tmp/tactician.tmp.KzuMtE/target-source/venv/lib/python3.10/site-packages/keras/layers/core/tf_op_layer.py", line 107, in handle
    return TFOpLambda(op)(*args, **kwargs)
  File "/tmp/tactician.tmp.KzuMtE/target-source/venv/lib/python3.10/site-packages/keras/utils/traceback_utils.py", line 67, in error_handler
    raise e.with_traceback(filtered_tb) from None
ValueError: Exception encountered when calling layer "tf.math.top_k" (type TFOpLambda).

input must have last dimension >= k = 2048 but is 1247 for '{{node tf.math.top_k/TopKV2}} = TopKV2[T=DT_FLOAT, sorted=true](Placeholder, tf.math.top_k/TopKV2/k)' with input shapes: [?,1247], [] and with computed input tensors: input[1] = <2048>.

Call arguments received by layer "tf.math.top_k" (type TFOpLambda):
  • input=tf.Tensor(shape=(None, 1247), dtype=float32)
  • k=2048
  • sorted=True
  • name=None
File "./metrique_triangle.v", line 633, characters 0-7:
Error:
Anomaly "Uncaught exception Unix.Unix_error(Unix.EPIPE, "single_write", "")."
Please report at http://coq.inria.fr/bugs/.

File "./aire_signee.v", line 469, characters 0-7:
Error:
Anomaly "Uncaught exception Unix.Unix_error(Unix.EPIPE, "single_write", "")."
Please report at http://coq.inria.fr/bugs/.

File "./determinant.v", line 59, characters 0-7:
Error:
Anomaly "Uncaught exception Unix.Unix_error(Unix.EPIPE, "single_write", "")."
Please report at http://coq.inria.fr/bugs/.

File "./complexes.v", line 33, characters 0-17:
Error:
Anomaly "Uncaught exception Unix.Unix_error(Unix.EPIPE, "single_write", "")."
Please report at http://coq.inria.fr/bugs/.

File "/tmp/tactician.tmp.KzuMtE/opam-root/bench/lib/coq/user-contrib/Tactician/Graph2TacConfig.v", line 1, characters 0-32:
Warning: There is no option Tactician Neural Truncate.
[unknown-option,option]
Traceback (most recent call last):
  File "/tmp/tactician.tmp.KzuMtE/target-source/venv/bin/g2t-server", line 33, in <module>
    sys.exit(load_entry_point('graph2tac==0.1.0', 'console_scripts', 'g2t-server')())
  File "/tmp/tactician.tmp.KzuMtE/target-source/venv/lib/python3.10/site-packages/graph2tac/loader/predict_server.py", line 967, in main
    main_with_return_value()
  File "/tmp/tactician.tmp.KzuMtE/target-source/venv/lib/python3.10/site-packages/graph2tac/loader/predict_server.py", line 922, in main_with_return_value
    model = load_model(config, log_levels)
  File "/tmp/tactician.tmp.KzuMtE/target-source/venv/lib/python3.10/site-packages/graph2tac/loader/predict_server.py", line 871, in load_model
    model = TFGNNPredict(log_dir=Path(config.model).expanduser().absolute(),
  File "/tmp/tactician.tmp.KzuMtE/target-source/venv/lib/python3.10/site-packages/graph2tac/tfgnn/predict.py", line 620, in __init__
    self._compile_network()
  File "/tmp/tactician.tmp.KzuMtE/target-source/venv/lib/python3.10/site-packages/graph2tac/tfgnn/predict.py", line 685, in _compile_network
    inference_model_bare = self.prediction_task.create_inference_model(
  File "/tmp/tactician.tmp.KzuMtE/target-source/venv/lib/python3.10/site-packages/graph2tac/tfgnn/tasks.py", line 1343, in create_inference_model
    tactic, top_k_values = self._top_k_tactics(tactic_logits=tactic_logits,
  File "/tmp/tactician.tmp.KzuMtE/target-source/venv/lib/python3.10/site-packages/graph2tac/tfgnn/tasks.py", line 561, in _top_k_tactics
    top_k = tf.math.top_k(tactic_logits, k=tactic_expand_bound)
  File "/tmp/tactician.tmp.KzuMtE/target-source/venv/lib/python3.10/site-packages/tensorflow/python/util/traceback_utils.py", line 153, in error_handler
    raise e.with_traceback(filtered_tb) from None
  File "/tmp/tactician.tmp.KzuMtE/target-source/venv/lib/python3.10/site-packages/keras/layers/core/tf_op_layer.py", line 107, in handle
    return TFOpLambda(op)(*args, **kwargs)
  File "/tmp/tactician.tmp.KzuMtE/target-source/venv/lib/python3.10/site-packages/keras/utils/traceback_utils.py", line 67, in error_handler
    raise e.with_traceback(filtered_tb) from None
ValueError: Exception encountered when calling layer "tf.math.top_k" (type TFOpLambda).

input must have last dimension >= k = 2048 but is 1247 for '{{node tf.math.top_k/TopKV2}} = TopKV2[T=DT_FLOAT, sorted=true](Placeholder, tf.math.top_k/TopKV2/k)' with input shapes: [?,1247], [] and with computed input tensors: input[1] = <2048>.

Call arguments received by layer "tf.math.top_k" (type TFOpLambda):
  • input=tf.Tensor(shape=(None, 1247), dtype=float32)
  • k=2048
  • sorted=True
  • name=None
File "./orientation.v", line 425, characters 0-27:
Error:
Anomaly "Uncaught exception Unix.Unix_error(Unix.EPIPE, "single_write", "")."
Please report at http://coq.inria.fr/bugs/.

File "./trigo.v", line 244, characters 0-88:
Error:
Anomaly "Uncaught exception Unix.Unix_error(Unix.EPIPE, "single_write", "")."
Please report at http://coq.inria.fr/bugs/.

File "./triangles_semblables.v", line 434, characters 0-21:
Error:
Anomaly "Uncaught exception Unix.Unix_error(Unix.EPIPE, "single_write", "")."
Please report at http://coq.inria.fr/bugs/.

File "./formes_complexes.v", line 242, characters 0-7:
Error:
Anomaly "Uncaught exception Unix.Unix_error(Unix.EPIPE, "single_write", "")."
Please report at http://coq.inria.fr/bugs/.

File "/tmp/tactician.tmp.KzuMtE/opam-root/bench/lib/coq/user-contrib/Tactician/Graph2TacConfig.v", line 1, characters 0-32:
Warning: There is no option Tactician Neural Truncate.
[unknown-option,option]
Traceback (most recent call last):
  File "/tmp/tactician.tmp.KzuMtE/target-source/venv/bin/g2t-server", line 33, in <module>
    sys.exit(load_entry_point('graph2tac==0.1.0', 'console_scripts', 'g2t-server')())
  File "/tmp/tactician.tmp.KzuMtE/target-source/venv/lib/python3.10/site-packages/graph2tac/loader/predict_server.py", line 967, in main
    main_with_return_value()
  File "/tmp/tactician.tmp.KzuMtE/target-source/venv/lib/python3.10/site-packages/graph2tac/loader/predict_server.py", line 922, in main_with_return_value
    model = load_model(config, log_levels)
  File "/tmp/tactician.tmp.KzuMtE/target-source/venv/lib/python3.10/site-packages/graph2tac/loader/predict_server.py", line 871, in load_model
    model = TFGNNPredict(log_dir=Path(config.model).expanduser().absolute(),
  File "/tmp/tactician.tmp.KzuMtE/target-source/venv/lib/python3.10/site-packages/graph2tac/tfgnn/predict.py", line 620, in __init__
    self._compile_network()
  File "/tmp/tactician.tmp.KzuMtE/target-source/venv/lib/python3.10/site-packages/graph2tac/tfgnn/predict.py", line 685, in _compile_network
    inference_model_bare = self.prediction_task.create_inference_model(
  File "/tmp/tactician.tmp.KzuMtE/target-source/venv/lib/python3.10/site-packages/graph2tac/tfgnn/tasks.py", line 1343, in create_inference_model
    tactic, top_k_values = self._top_k_tactics(tactic_logits=tactic_logits,
  File "/tmp/tactician.tmp.KzuMtE/target-source/venv/lib/python3.10/site-packages/graph2tac/tfgnn/tasks.py", line 561, in _top_k_tactics
    top_k = tf.math.top_k(tactic_logits, k=tactic_expand_bound)
  File "/tmp/tactician.tmp.KzuMtE/target-source/venv/lib/python3.10/site-packages/tensorflow/python/util/traceback_utils.py", line 153, in error_handler
    raise e.with_traceback(filtered_tb) from None
  File "/tmp/tactician.tmp.KzuMtE/target-source/venv/lib/python3.10/site-packages/keras/layers/core/tf_op_layer.py", line 107, in handle
    return TFOpLambda(op)(*args, **kwargs)
  File "/tmp/tactician.tmp.KzuMtE/target-source/venv/lib/python3.10/site-packages/keras/utils/traceback_utils.py", line 67, in error_handler
    raise e.with_traceback(filtered_tb) from None
ValueError: Exception encountered when calling layer "tf.math.top_k" (type TFOpLambda).

input must have last dimension >= k = 2048 but is 1247 for '{{node tf.math.top_k/TopKV2}} = TopKV2[T=DT_FLOAT, sorted=true](Placeholder, tf.math.top_k/TopKV2/k)' with input shapes: [?,1247], [] and with computed input tensors: input[1] = <2048>.

Call arguments received by layer "tf.math.top_k" (type TFOpLambda):
  • input=tf.Tensor(shape=(None, 1247), dtype=float32)
  • k=2048
  • sorted=True
  • name=None
File "/tmp/tactician.tmp.KzuMtE/opam-root/bench/lib/coq/user-contrib/Tactician/Graph2TacConfig.v", line 1, characters 0-32:
Warning: There is no option Tactician Neural Truncate.
[unknown-option,option]
File "/tmp/tactician.tmp.KzuMtE/opam-root/bench/lib/coq/user-contrib/Tactician/Graph2TacConfig.v", line 1, characters 0-32:
Warning: There is no option Tactician Neural Truncate.
[unknown-option,option]
Traceback (most recent call last):
  File "/tmp/tactician.tmp.KzuMtE/target-source/venv/bin/g2t-server", line 33, in <module>
    sys.exit(load_entry_point('graph2tac==0.1.0', 'console_scripts', 'g2t-server')())
  File "/tmp/tactician.tmp.KzuMtE/target-source/venv/lib/python3.10/site-packages/graph2tac/loader/predict_server.py", line 967, in main
    main_with_return_value()
  File "/tmp/tactician.tmp.KzuMtE/target-source/venv/lib/python3.10/site-packages/graph2tac/loader/predict_server.py", line 922, in main_with_return_value
    model = load_model(config, log_levels)
  File "/tmp/tactician.tmp.KzuMtE/target-source/venv/lib/python3.10/site-packages/graph2tac/loader/predict_server.py", line 871, in load_model
    model = TFGNNPredict(log_dir=Path(config.model).expanduser().absolute(),
  File "/tmp/tactician.tmp.KzuMtE/target-source/venv/lib/python3.10/site-packages/graph2tac/tfgnn/predict.py", line 620, in __init__
    self._compile_network()
  File "/tmp/tactician.tmp.KzuMtE/target-source/venv/lib/python3.10/site-packages/graph2tac/tfgnn/predict.py", line 685, in _compile_network
    inference_model_bare = self.prediction_task.create_inference_model(
  File "/tmp/tactician.tmp.KzuMtE/target-source/venv/lib/python3.10/site-packages/graph2tac/tfgnn/tasks.py", line 1343, in create_inference_model
    tactic, top_k_values = self._top_k_tactics(tactic_logits=tactic_logits,
  File "/tmp/tactician.tmp.KzuMtE/target-source/venv/lib/python3.10/site-packages/graph2tac/tfgnn/tasks.py", line 561, in _top_k_tactics
    top_k = tf.math.top_k(tactic_logits, k=tactic_expand_bound)
  File "/tmp/tactician.tmp.KzuMtE/target-source/venv/lib/python3.10/site-packages/tensorflow/python/util/traceback_utils.py", line 153, in error_handler
    raise e.with_traceback(filtered_tb) from None
  File "/tmp/tactician.tmp.KzuMtE/target-source/venv/lib/python3.10/site-packages/keras/layers/core/tf_op_layer.py", line 107, in handle
    return TFOpLambda(op)(*args, **kwargs)
  File "/tmp/tactician.tmp.KzuMtE/target-source/venv/lib/python3.10/site-packages/keras/utils/traceback_utils.py", line 67, in error_handler
    raise e.with_traceback(filtered_tb) from None
ValueError: Exception encountered when calling layer "tf.math.top_k" (type TFOpLambda).

input must have last dimension >= k = 2048 but is 1247 for '{{node tf.math.top_k/TopKV2}} = TopKV2[T=DT_FLOAT, sorted=true](Placeholder, tf.math.top_k/TopKV2/k)' with input shapes: [?,1247], [] and with computed input tensors: input[1] = <2048>.

Call arguments received by layer "tf.math.top_k" (type TFOpLambda):
  • input=tf.Tensor(shape=(None, 1247), dtype=float32)
  • k=2048
  • sorted=True
  • name=None
File "/tmp/tactician.tmp.KzuMtE/opam-root/bench/lib/coq/user-contrib/Tactician/Graph2TacConfig.v", line 1, characters 0-32:
Warning: There is no option Tactician Neural Truncate.
[unknown-option,option]
Traceback (most recent call last):
  File "/tmp/tactician.tmp.KzuMtE/target-source/venv/bin/g2t-server", line 33, in <module>
    sys.exit(load_entry_point('graph2tac==0.1.0', 'console_scripts', 'g2t-server')())
  File "/tmp/tactician.tmp.KzuMtE/target-source/venv/lib/python3.10/site-packages/graph2tac/loader/predict_server.py", line 967, in main
    main_with_return_value()
  File "/tmp/tactician.tmp.KzuMtE/target-source/venv/lib/python3.10/site-packages/graph2tac/loader/predict_server.py", line 922, in main_with_return_value
    model = load_model(config, log_levels)
  File "/tmp/tactician.tmp.KzuMtE/target-source/venv/lib/python3.10/site-packages/graph2tac/loader/predict_server.py", line 871, in load_model
    model = TFGNNPredict(log_dir=Path(config.model).expanduser().absolute(),
  File "/tmp/tactician.tmp.KzuMtE/target-source/venv/lib/python3.10/site-packages/graph2tac/tfgnn/predict.py", line 620, in __init__
    self._compile_network()
  File "/tmp/tactician.tmp.KzuMtE/target-source/venv/lib/python3.10/site-packages/graph2tac/tfgnn/predict.py", line 685, in _compile_network
    inference_model_bare = self.prediction_task.create_inference_model(
  File "/tmp/tactician.tmp.KzuMtE/target-source/venv/lib/python3.10/site-packages/graph2tac/tfgnn/tasks.py", line 1343, in create_inference_model
    tactic, top_k_values = self._top_k_tactics(tactic_logits=tactic_logits,
  File "/tmp/tactician.tmp.KzuMtE/target-source/venv/lib/python3.10/site-packages/graph2tac/tfgnn/tasks.py", line 561, in _top_k_tactics
    top_k = tf.math.top_k(tactic_logits, k=tactic_expand_bound)
  File "/tmp/tactician.tmp.KzuMtE/target-source/venv/lib/python3.10/site-packages/tensorflow/python/util/traceback_utils.py", line 153, in error_handler
    raise e.with_traceback(filtered_tb) from None
  File "/tmp/tactician.tmp.KzuMtE/target-source/venv/lib/python3.10/site-packages/keras/layers/core/tf_op_layer.py", line 107, in handle
    return TFOpLambda(op)(*args, **kwargs)
  File "/tmp/tactician.tmp.KzuMtE/target-source/venv/lib/python3.10/site-packages/keras/utils/traceback_utils.py", line 67, in error_handler
    raise e.with_traceback(filtered_tb) from None
ValueError: Exception encountered when calling layer "tf.math.top_k" (type TFOpLambda).

input must have last dimension >= k = 2048 but is 1247 for '{{node tf.math.top_k/TopKV2}} = TopKV2[T=DT_FLOAT, sorted=true](Placeholder, tf.math.top_k/TopKV2/k)' with input shapes: [?,1247], [] and with computed input tensors: input[1] = <2048>.

Call arguments received by layer "tf.math.top_k" (type TFOpLambda):
  • input=tf.Tensor(shape=(None, 1247), dtype=float32)
  • k=2048
  • sorted=True
  • name=None
File "./exercice_espace.v", line 37, characters 0-7:
Error:
Anomaly "Uncaught exception Unix.Unix_error(Unix.EPIPE, "single_write", "")."
Please report at http://coq.inria.fr/bugs/.

Traceback (most recent call last):
  File "/tmp/tactician.tmp.KzuMtE/target-source/venv/bin/g2t-server", line 33, in <module>
    sys.exit(load_entry_point('graph2tac==0.1.0', 'console_scripts', 'g2t-server')())
  File "/tmp/tactician.tmp.KzuMtE/target-source/venv/lib/python3.10/site-packages/graph2tac/loader/predict_server.py", line 967, in main
    main_with_return_value()
  File "/tmp/tactician.tmp.KzuMtE/target-source/venv/lib/python3.10/site-packages/graph2tac/loader/predict_server.py", line 922, in main_with_return_value
    model = load_model(config, log_levels)
  File "/tmp/tactician.tmp.KzuMtE/target-source/venv/lib/python3.10/site-packages/graph2tac/loader/predict_server.py", line 871, in load_model
    model = TFGNNPredict(log_dir=Path(config.model).expanduser().absolute(),
  File "/tmp/tactician.tmp.KzuMtE/target-source/venv/lib/python3.10/site-packages/graph2tac/tfgnn/predict.py", line 620, in __init__
    self._compile_network()
  File "/tmp/tactician.tmp.KzuMtE/target-source/venv/lib/python3.10/site-packages/graph2tac/tfgnn/predict.py", line 685, in _compile_network
    inference_model_bare = self.prediction_task.create_inference_model(
  File "/tmp/tactician.tmp.KzuMtE/target-source/venv/lib/python3.10/site-packages/graph2tac/tfgnn/tasks.py", line 1343, in create_inference_model
    tactic, top_k_values = self._top_k_tactics(tactic_logits=tactic_logits,
  File "/tmp/tactician.tmp.KzuMtE/target-source/venv/lib/python3.10/site-packages/graph2tac/tfgnn/tasks.py", line 561, in _top_k_tactics
    top_k = tf.math.top_k(tactic_logits, k=tactic_expand_bound)
  File "/tmp/tactician.tmp.KzuMtE/target-source/venv/lib/python3.10/site-packages/tensorflow/python/util/traceback_utils.py", line 153, in error_handler
    raise e.with_traceback(filtered_tb) from None
  File "/tmp/tactician.tmp.KzuMtE/target-source/venv/lib/python3.10/site-packages/keras/layers/core/tf_op_layer.py", line 107, in handle
    return TFOpLambda(op)(*args, **kwargs)
  File "/tmp/tactician.tmp.KzuMtE/target-source/venv/lib/python3.10/site-packages/keras/utils/traceback_utils.py", line 67, in error_handler
    raise e.with_traceback(filtered_tb) from None
ValueError: Exception encountered when calling layer "tf.math.top_k" (type TFOpLambda).

input must have last dimension >= k = 2048 but is 1247 for '{{node tf.math.top_k/TopKV2}} = TopKV2[T=DT_FLOAT, sorted=true](Placeholder, tf.math.top_k/TopKV2/k)' with input shapes: [?,1247], [] and with computed input tensors: input[1] = <2048>.

Call arguments received by layer "tf.math.top_k" (type TFOpLambda):
  • input=tf.Tensor(shape=(None, 1247), dtype=float32)
  • k=2048
  • sorted=True
  • name=None
File "./determinant.v", line 144, characters 0-7:
Error:
Anomaly "Uncaught exception Unix.Unix_error(Unix.EPIPE, "single_write", "")."
Please report at http://coq.inria.fr/bugs/.

File "./angles_vecteurs.v", line 274, characters 0-7:
Error:
Anomaly "Uncaught exception Unix.Unix_error(Unix.EPIPE, "single_write", "")."
Please report at http://coq.inria.fr/bugs/.

File "./repere_ortho_plan.v", line 141, characters 0-42:
Error:
Anomaly "Uncaught exception Unix.Unix_error(Unix.EPIPE, "single_write", "")."
Please report at http://coq.inria.fr/bugs/.

File "./complexes.v", line 39, characters 0-17:
Error:
Anomaly "Uncaught exception Unix.Unix_error(Unix.EPIPE, "single_write", "")."
Please report at http://coq.inria.fr/bugs/.

File "./distance_euclidienne.v", line 126, characters 0-53:
Error:
Anomaly "Uncaught exception Unix.Unix_error(Unix.EPIPE, "single_write", "")."
Please report at http://coq.inria.fr/bugs/.

File "/tmp/tactician.tmp.KzuMtE/opam-root/bench/lib/coq/user-contrib/Tactician/Graph2TacConfig.v", line 1, characters 0-32:
Warning: There is no option Tactician Neural Truncate.
[unknown-option,option]
File "./trigo.v", line 262, characters 0-88:
Error:
Anomaly "Uncaught exception Unix.Unix_error(Unix.EPIPE, "single_write", "")."
Please report at http://coq.inria.fr/bugs/.

File "./orientation.v", line 875, characters 0-23:
Error:
Anomaly "Uncaught exception Unix.Unix_error(Unix.EPIPE, "single_write", "")."
Please report at http://coq.inria.fr/bugs/.

Traceback (most recent call last):
  File "/tmp/tactician.tmp.KzuMtE/target-source/venv/bin/g2t-server", line 33, in <module>
    sys.exit(load_entry_point('graph2tac==0.1.0', 'console_scripts', 'g2t-server')())
  File "/tmp/tactician.tmp.KzuMtE/target-source/venv/lib/python3.10/site-packages/graph2tac/loader/predict_server.py", line 967, in main
    main_with_return_value()
  File "/tmp/tactician.tmp.KzuMtE/target-source/venv/lib/python3.10/site-packages/graph2tac/loader/predict_server.py", line 922, in main_with_return_value
    model = load_model(config, log_levels)
  File "/tmp/tactician.tmp.KzuMtE/target-source/venv/lib/python3.10/site-packages/graph2tac/loader/predict_server.py", line 871, in load_model
    model = TFGNNPredict(log_dir=Path(config.model).expanduser().absolute(),
  File "/tmp/tactician.tmp.KzuMtE/target-source/venv/lib/python3.10/site-packages/graph2tac/tfgnn/predict.py", line 620, in __init__
    self._compile_network()
  File "/tmp/tactician.tmp.KzuMtE/target-source/venv/lib/python3.10/site-packages/graph2tac/tfgnn/predict.py", line 685, in _compile_network
    inference_model_bare = self.prediction_task.create_inference_model(
  File "/tmp/tactician.tmp.KzuMtE/target-source/venv/lib/python3.10/site-packages/graph2tac/tfgnn/tasks.py", line 1343, in create_inference_model
    tactic, top_k_values = self._top_k_tactics(tactic_logits=tactic_logits,
  File "/tmp/tactician.tmp.KzuMtE/target-source/venv/lib/python3.10/site-packages/graph2tac/tfgnn/tasks.py", line 561, in _top_k_tactics
    top_k = tf.math.top_k(tactic_logits, k=tactic_expand_bound)
  File "/tmp/tactician.tmp.KzuMtE/target-source/venv/lib/python3.10/site-packages/tensorflow/python/util/traceback_utils.py", line 153, in error_handler
    raise e.with_traceback(filtered_tb) from None
  File "/tmp/tactician.tmp.KzuMtE/target-source/venv/lib/python3.10/site-packages/keras/layers/core/tf_op_layer.py", line 107, in handle
    return TFOpLambda(op)(*args, **kwargs)
  File "/tmp/tactician.tmp.KzuMtE/target-source/venv/lib/python3.10/site-packages/keras/utils/traceback_utils.py", line 67, in error_handler
    raise e.with_traceback(filtered_tb) from None
ValueError: Exception encountered when calling layer "tf.math.top_k" (type TFOpLambda).

input must have last dimension >= k = 2048 but is 1247 for '{{node tf.math.top_k/TopKV2}} = TopKV2[T=DT_FLOAT, sorted=true](Placeholder, tf.math.top_k/TopKV2/k)' with input shapes: [?,1247], [] and with computed input tensors: input[1] = <2048>.

Call arguments received by layer "tf.math.top_k" (type TFOpLambda):
  • input=tf.Tensor(shape=(None, 1247), dtype=float32)
  • k=2048
  • sorted=True
  • name=None
File "./formes_complexes.v", line 329, characters 0-7:
Error:
Anomaly "Uncaught exception Unix.Unix_error(Unix.EPIPE, "single_write", "")."
Please report at http://coq.inria.fr/bugs/.

File "./composee_dilatations.v", line 130, characters 0-34:
Error:
Anomaly "Uncaught exception Unix.Unix_error(Unix.EPIPE, "single_write", "")."
Please report at http://coq.inria.fr/bugs/.

File "/tmp/tactician.tmp.KzuMtE/opam-root/bench/lib/coq/user-contrib/Tactician/Graph2TacConfig.v", line 1, characters 0-32:
Warning: There is no option Tactician Neural Truncate.
[unknown-option,option]
Traceback (most recent call last):
  File "/tmp/tactician.tmp.KzuMtE/target-source/venv/bin/g2t-server", line 33, in <module>
    sys.exit(load_entry_point('graph2tac==0.1.0', 'console_scripts', 'g2t-server')())
  File "/tmp/tactician.tmp.KzuMtE/target-source/venv/lib/python3.10/site-packages/graph2tac/loader/predict_server.py", line 967, in main
    main_with_return_value()
  File "/tmp/tactician.tmp.KzuMtE/target-source/venv/lib/python3.10/site-packages/graph2tac/loader/predict_server.py", line 922, in main_with_return_value
    model = load_model(config, log_levels)
  File "/tmp/tactician.tmp.KzuMtE/target-source/venv/lib/python3.10/site-packages/graph2tac/loader/predict_server.py", line 871, in load_model
    model = TFGNNPredict(log_dir=Path(config.model).expanduser().absolute(),
  File "/tmp/tactician.tmp.KzuMtE/target-source/venv/lib/python3.10/site-packages/graph2tac/tfgnn/predict.py", line 620, in __init__
    self._compile_network()
  File "/tmp/tactician.tmp.KzuMtE/target-source/venv/lib/python3.10/site-packages/graph2tac/tfgnn/predict.py", line 685, in _compile_network
    inference_model_bare = self.prediction_task.create_inference_model(
  File "/tmp/tactician.tmp.KzuMtE/target-source/venv/lib/python3.10/site-packages/graph2tac/tfgnn/tasks.py", line 1343, in create_inference_model
    tactic, top_k_values = self._top_k_tactics(tactic_logits=tactic_logits,
  File "/tmp/tactician.tmp.KzuMtE/target-source/venv/lib/python3.10/site-packages/graph2tac/tfgnn/tasks.py", line 561, in _top_k_tactics
    top_k = tf.math.top_k(tactic_logits, k=tactic_expand_bound)
  File "/tmp/tactician.tmp.KzuMtE/target-source/venv/lib/python3.10/site-packages/tensorflow/python/util/traceback_utils.py", line 153, in error_handler
    raise e.with_traceback(filtered_tb) from None
  File "/tmp/tactician.tmp.KzuMtE/target-source/venv/lib/python3.10/site-packages/keras/layers/core/tf_op_layer.py", line 107, in handle
    return TFOpLambda(op)(*args, **kwargs)
  File "/tmp/tactician.tmp.KzuMtE/target-source/venv/lib/python3.10/site-packages/keras/utils/traceback_utils.py", line 67, in error_handler
    raise e.with_traceback(filtered_tb) from None
ValueError: Exception encountered when calling layer "tf.math.top_k" (type TFOpLambda).

input must have last dimension >= k = 2048 but is 1247 for '{{node tf.math.top_k/TopKV2}} = TopKV2[T=DT_FLOAT, sorted=true](Placeholder, tf.math.top_k/TopKV2/k)' with input shapes: [?,1247], [] and with computed input tensors: input[1] = <2048>.

Call arguments received by layer "tf.math.top_k" (type TFOpLambda):
  • input=tf.Tensor(shape=(None, 1247), dtype=float32)
  • k=2048
  • sorted=True
  • name=None
File "/tmp/tactician.tmp.KzuMtE/opam-root/bench/lib/coq/user-contrib/Tactician/Graph2TacConfig.v", line 1, characters 0-32:
Warning: There is no option Tactician Neural Truncate.
[unknown-option,option]
File "./determinant.v", line 175, characters 0-7:
Error:
Anomaly "Uncaught exception Unix.Unix_error(Unix.EPIPE, "single_write", "")."
Please report at http://coq.inria.fr/bugs/.

Traceback (most recent call last):
  File "/tmp/tactician.tmp.KzuMtE/target-source/venv/bin/g2t-server", line 33, in <module>
    sys.exit(load_entry_point('graph2tac==0.1.0', 'console_scripts', 'g2t-server')())
  File "/tmp/tactician.tmp.KzuMtE/target-source/venv/lib/python3.10/site-packages/graph2tac/loader/predict_server.py", line 967, in main
    main_with_return_value()
  File "/tmp/tactician.tmp.KzuMtE/target-source/venv/lib/python3.10/site-packages/graph2tac/loader/predict_server.py", line 922, in main_with_return_value
    model = load_model(config, log_levels)
  File "/tmp/tactician.tmp.KzuMtE/target-source/venv/lib/python3.10/site-packages/graph2tac/loader/predict_server.py", line 871, in load_model
    model = TFGNNPredict(log_dir=Path(config.model).expanduser().absolute(),
  File "/tmp/tactician.tmp.KzuMtE/target-source/venv/lib/python3.10/site-packages/graph2tac/tfgnn/predict.py", line 620, in __init__
    self._compile_network()
  File "/tmp/tactician.tmp.KzuMtE/target-source/venv/lib/python3.10/site-packages/graph2tac/tfgnn/predict.py", line 685, in _compile_network
    inference_model_bare = self.prediction_task.create_inference_model(
  File "/tmp/tactician.tmp.KzuMtE/target-source/venv/lib/python3.10/site-packages/graph2tac/tfgnn/tasks.py", line 1343, in create_inference_model
    tactic, top_k_values = self._top_k_tactics(tactic_logits=tactic_logits,
  File "/tmp/tactician.tmp.KzuMtE/target-source/venv/lib/python3.10/site-packages/graph2tac/tfgnn/tasks.py", line 561, in _top_k_tactics
    top_k = tf.math.top_k(tactic_logits, k=tactic_expand_bound)
  File "/tmp/tactician.tmp.KzuMtE/target-source/venv/lib/python3.10/site-packages/tensorflow/python/util/traceback_utils.py", line 153, in error_handler
    raise e.with_traceback(filtered_tb) from None
  File "/tmp/tactician.tmp.KzuMtE/target-source/venv/lib/python3.10/site-packages/keras/layers/core/tf_op_layer.py", line 107, in handle
    return TFOpLambda(op)(*args, **kwargs)
  File "/tmp/tactician.tmp.KzuMtE/target-source/venv/lib/python3.10/site-packages/keras/utils/traceback_utils.py", line 67, in error_handler
    raise e.with_traceback(filtered_tb) from None
ValueError: Exception encountered when calling layer "tf.math.top_k" (type TFOpLambda).

input must have last dimension >= k = 2048 but is 1247 for '{{node tf.math.top_k/TopKV2}} = TopKV2[T=DT_FLOAT, sorted=true](Placeholder, tf.math.top_k/TopKV2/k)' with input shapes: [?,1247], [] and with computed input tensors: input[1] = <2048>.

Call arguments received by layer "tf.math.top_k" (type TFOpLambda):
  • input=tf.Tensor(shape=(None, 1247), dtype=float32)
  • k=2048
  • sorted=True
  • name=None
File "./repere_ortho_plan.v", line 195, characters 0-32:
Error:
Anomaly "Uncaught exception Unix.Unix_error(Unix.EPIPE, "single_write", "")."
Please report at http://coq.inria.fr/bugs/.

File "./Droite_plan_espace.v", line 57, characters 0-53:
Error:
Anomaly "Uncaught exception Unix.Unix_error(Unix.EPIPE, "single_write", "")."
Please report at http://coq.inria.fr/bugs/.

File "./complexes.v", line 45, characters 0-54:
Error:
Anomaly "Uncaught exception Unix.Unix_error(Unix.EPIPE, "single_write", "")."
Please report at http://coq.inria.fr/bugs/.

File "./distance_euclidienne.v", line 216, characters 0-7:
Error:
Anomaly "Uncaught exception Unix.Unix_error(Unix.EPIPE, "single_write", "")."
Please report at http://coq.inria.fr/bugs/.

File "./affine_classiques.v", line 49, characters 0-19:
Error:
Anomaly "Uncaught exception Unix.Unix_error(Unix.EPIPE, "single_write", "")."
Please report at http://coq.inria.fr/bugs/.

File "/tmp/tactician.tmp.KzuMtE/opam-root/bench/lib/coq/user-contrib/Tactician/Graph2TacConfig.v", line 1, characters 0-32:
Warning: There is no option Tactician Neural Truncate.
[unknown-option,option]
Traceback (most recent call last):
  File "/tmp/tactician.tmp.KzuMtE/target-source/venv/bin/g2t-server", line 33, in <module>
    sys.exit(load_entry_point('graph2tac==0.1.0', 'console_scripts', 'g2t-server')())
  File "/tmp/tactician.tmp.KzuMtE/target-source/venv/lib/python3.10/site-packages/graph2tac/loader/predict_server.py", line 967, in main
    main_with_return_value()
  File "/tmp/tactician.tmp.KzuMtE/target-source/venv/lib/python3.10/site-packages/graph2tac/loader/predict_server.py", line 922, in main_with_return_value
    model = load_model(config, log_levels)
  File "/tmp/tactician.tmp.KzuMtE/target-source/venv/lib/python3.10/site-packages/graph2tac/loader/predict_server.py", line 871, in load_model
    model = TFGNNPredict(log_dir=Path(config.model).expanduser().absolute(),
  File "/tmp/tactician.tmp.KzuMtE/target-source/venv/lib/python3.10/site-packages/graph2tac/tfgnn/predict.py", line 620, in __init__
    self._compile_network()
  File "/tmp/tactician.tmp.KzuMtE/target-source/venv/lib/python3.10/site-packages/graph2tac/tfgnn/predict.py", line 685, in _compile_network
    inference_model_bare = self.prediction_task.create_inference_model(
  File "/tmp/tactician.tmp.KzuMtE/target-source/venv/lib/python3.10/site-packages/graph2tac/tfgnn/tasks.py", line 1343, in create_inference_model
    tactic, top_k_values = self._top_k_tactics(tactic_logits=tactic_logits,
  File "/tmp/tactician.tmp.KzuMtE/target-source/venv/lib/python3.10/site-packages/graph2tac/tfgnn/tasks.py", line 561, in _top_k_tactics
    top_k = tf.math.top_k(tactic_logits, k=tactic_expand_bound)
  File "/tmp/tactician.tmp.KzuMtE/target-source/venv/lib/python3.10/site-packages/tensorflow/python/util/traceback_utils.py", line 153, in error_handler
    raise e.with_traceback(filtered_tb) from None
  File "/tmp/tactician.tmp.KzuMtE/target-source/venv/lib/python3.10/site-packages/keras/layers/core/tf_op_layer.py", line 107, in handle
    return TFOpLambda(op)(*args, **kwargs)
  File "/tmp/tactician.tmp.KzuMtE/target-source/venv/lib/python3.10/site-packages/keras/utils/traceback_utils.py", line 67, in error_handler
    raise e.with_traceback(filtered_tb) from None
ValueError: Exception encountered when calling layer "tf.math.top_k" (type TFOpLambda).

input must have last dimension >= k = 2048 but is 1247 for '{{node tf.math.top_k/TopKV2}} = TopKV2[T=DT_FLOAT, sorted=true](Placeholder, tf.math.top_k/TopKV2/k)' with input shapes: [?,1247], [] and with computed input tensors: input[1] = <2048>.

Call arguments received by layer "tf.math.top_k" (type TFOpLambda):
  • input=tf.Tensor(shape=(None, 1247), dtype=float32)
  • k=2048
  • sorted=True
  • name=None
File "./trigo.v", line 491, characters 0-7:
Error:
Anomaly "Uncaught exception Unix.Unix_error(Unix.EPIPE, "single_write", "")."
Please report at http://coq.inria.fr/bugs/.

File "/tmp/tactician.tmp.KzuMtE/opam-root/bench/lib/coq/user-contrib/Tactician/Graph2TacConfig.v", line 1, characters 0-32:
Warning: There is no option Tactician Neural Truncate.
[unknown-option,option]
Traceback (most recent call last):
  File "/tmp/tactician.tmp.KzuMtE/target-source/venv/bin/g2t-server", line 33, in <module>
    sys.exit(load_entry_point('graph2tac==0.1.0', 'console_scripts', 'g2t-server')())
  File "/tmp/tactician.tmp.KzuMtE/target-source/venv/lib/python3.10/site-packages/graph2tac/loader/predict_server.py", line 967, in main
    main_with_return_value()
  File "/tmp/tactician.tmp.KzuMtE/target-source/venv/lib/python3.10/site-packages/graph2tac/loader/predict_server.py", line 922, in main_with_return_value
    model = load_model(config, log_levels)
  File "/tmp/tactician.tmp.KzuMtE/target-source/venv/lib/python3.10/site-packages/graph2tac/loader/predict_server.py", line 871, in load_model
    model = TFGNNPredict(log_dir=Path(config.model).expanduser().absolute(),
  File "/tmp/tactician.tmp.KzuMtE/target-source/venv/lib/python3.10/site-packages/graph2tac/tfgnn/predict.py", line 620, in __init__
    self._compile_network()
  File "/tmp/tactician.tmp.KzuMtE/target-source/venv/lib/python3.10/site-packages/graph2tac/tfgnn/predict.py", line 685, in _compile_network
    inference_model_bare = self.prediction_task.create_inference_model(
  File "/tmp/tactician.tmp.KzuMtE/target-source/venv/lib/python3.10/site-packages/graph2tac/tfgnn/tasks.py", line 1343, in create_inference_model
    tactic, top_k_values = self._top_k_tactics(tactic_logits=tactic_logits,
  File "/tmp/tactician.tmp.KzuMtE/target-source/venv/lib/python3.10/site-packages/graph2tac/tfgnn/tasks.py", line 561, in _top_k_tactics
    top_k = tf.math.top_k(tactic_logits, k=tactic_expand_bound)
  File "/tmp/tactician.tmp.KzuMtE/target-source/venv/lib/python3.10/site-packages/tensorflow/python/util/traceback_utils.py", line 153, in error_handler
    raise e.with_traceback(filtered_tb) from None
  File "/tmp/tactician.tmp.KzuMtE/target-source/venv/lib/python3.10/site-packages/keras/layers/core/tf_op_layer.py", line 107, in handle
    return TFOpLambda(op)(*args, **kwargs)
  File "/tmp/tactician.tmp.KzuMtE/target-source/venv/lib/python3.10/site-packages/keras/utils/traceback_utils.py", line 67, in error_handler
    raise e.with_traceback(filtered_tb) from None
ValueError: Exception encountered when calling layer "tf.math.top_k" (type TFOpLambda).

input must have last dimension >= k = 2048 but is 1247 for '{{node tf.math.top_k/TopKV2}} = TopKV2[T=DT_FLOAT, sorted=true](Placeholder, tf.math.top_k/TopKV2/k)' with input shapes: [?,1247], [] and with computed input tensors: input[1] = <2048>.

Call arguments received by layer "tf.math.top_k" (type TFOpLambda):
  • input=tf.Tensor(shape=(None, 1247), dtype=float32)
  • k=2048
  • sorted=True
  • name=None
File "/tmp/tactician.tmp.KzuMtE/opam-root/bench/lib/coq/user-contrib/Tactician/Graph2TacConfig.v", line 1, characters 0-32:
Warning: There is no option Tactician Neural Truncate.
[unknown-option,option]
File "./dilatations.v", line 403, characters 0-7:
Error:
Anomaly "Uncaught exception Unix.Unix_error(Unix.EPIPE, "single_write", "")."
Please report at http://coq.inria.fr/bugs/.

Traceback (most recent call last):
  File "/tmp/tactician.tmp.KzuMtE/target-source/venv/bin/g2t-server", line 33, in <module>
    sys.exit(load_entry_point('graph2tac==0.1.0', 'console_scripts', 'g2t-server')())
  File "/tmp/tactician.tmp.KzuMtE/target-source/venv/lib/python3.10/site-packages/graph2tac/loader/predict_server.py", line 967, in main
    main_with_return_value()
  File "/tmp/tactician.tmp.KzuMtE/target-source/venv/lib/python3.10/site-packages/graph2tac/loader/predict_server.py", line 922, in main_with_return_value
    model = load_model(config, log_levels)
  File "/tmp/tactician.tmp.KzuMtE/target-source/venv/lib/python3.10/site-packages/graph2tac/loader/predict_server.py", line 871, in load_model
    model = TFGNNPredict(log_dir=Path(config.model).expanduser().absolute(),
  File "/tmp/tactician.tmp.KzuMtE/target-source/venv/lib/python3.10/site-packages/graph2tac/tfgnn/predict.py", line 620, in __init__
    self._compile_network()
  File "/tmp/tactician.tmp.KzuMtE/target-source/venv/lib/python3.10/site-packages/graph2tac/tfgnn/predict.py", line 685, in _compile_network
    inference_model_bare = self.prediction_task.create_inference_model(
  File "/tmp/tactician.tmp.KzuMtE/target-source/venv/lib/python3.10/site-packages/graph2tac/tfgnn/tasks.py", line 1343, in create_inference_model
    tactic, top_k_values = self._top_k_tactics(tactic_logits=tactic_logits,
  File "/tmp/tactician.tmp.KzuMtE/target-source/venv/lib/python3.10/site-packages/graph2tac/tfgnn/tasks.py", line 561, in _top_k_tactics
    top_k = tf.math.top_k(tactic_logits, k=tactic_expand_bound)
  File "/tmp/tactician.tmp.KzuMtE/target-source/venv/lib/python3.10/site-packages/tensorflow/python/util/traceback_utils.py", line 153, in error_handler
    raise e.with_traceback(filtered_tb) from None
  File "/tmp/tactician.tmp.KzuMtE/target-source/venv/lib/python3.10/site-packages/keras/layers/core/tf_op_layer.py", line 107, in handle
    return TFOpLambda(op)(*args, **kwargs)
  File "/tmp/tactician.tmp.KzuMtE/target-source/venv/lib/python3.10/site-packages/keras/utils/traceback_utils.py", line 67, in error_handler
    raise e.with_traceback(filtered_tb) from None
ValueError: Exception encountered when calling layer "tf.math.top_k" (type TFOpLambda).

input must have last dimension >= k = 2048 but is 1247 for '{{node tf.math.top_k/TopKV2}} = TopKV2[T=DT_FLOAT, sorted=true](Placeholder, tf.math.top_k/TopKV2/k)' with input shapes: [?,1247], [] and with computed input tensors: input[1] = <2048>.

Call arguments received by layer "tf.math.top_k" (type TFOpLambda):
  • input=tf.Tensor(shape=(None, 1247), dtype=float32)
  • k=2048
  • sorted=True
  • name=None
File "./parallelisme_concours.v", line 94, characters 0-51:
Error:
Anomaly "Uncaught exception Unix.Unix_error(Unix.EPIPE, "single_write", "")."
Please report at http://coq.inria.fr/bugs/.

File "/tmp/tactician.tmp.KzuMtE/opam-root/bench/lib/coq/user-contrib/Tactician/Graph2TacConfig.v", line 1, characters 0-32:
Warning: There is no option Tactician Neural Truncate.
[unknown-option,option]
File "/tmp/tactician.tmp.KzuMtE/opam-root/bench/lib/coq/user-contrib/Tactician/Graph2TacConfig.v", line 1, characters 0-32:
Warning: There is no option Tactician Neural Truncate.
[unknown-option,option]
File "/tmp/tactician.tmp.KzuMtE/opam-root/bench/lib/coq/user-contrib/Tactician/Graph2TacConfig.v", line 1, characters 0-32:
Warning: There is no option Tactician Neural Truncate.
[unknown-option,option]
Traceback (most recent call last):
  File "/tmp/tactician.tmp.KzuMtE/target-source/venv/bin/g2t-server", line 33, in <module>
    sys.exit(load_entry_point('graph2tac==0.1.0', 'console_scripts', 'g2t-server')())
  File "/tmp/tactician.tmp.KzuMtE/target-source/venv/lib/python3.10/site-packages/graph2tac/loader/predict_server.py", line 967, in main
    main_with_return_value()
  File "/tmp/tactician.tmp.KzuMtE/target-source/venv/lib/python3.10/site-packages/graph2tac/loader/predict_server.py", line 922, in main_with_return_value
    model = load_model(config, log_levels)
  File "/tmp/tactician.tmp.KzuMtE/target-source/venv/lib/python3.10/site-packages/graph2tac/loader/predict_server.py", line 871, in load_model
    model = TFGNNPredict(log_dir=Path(config.model).expanduser().absolute(),
  File "/tmp/tactician.tmp.KzuMtE/target-source/venv/lib/python3.10/site-packages/graph2tac/tfgnn/predict.py", line 620, in __init__
    self._compile_network()
  File "/tmp/tactician.tmp.KzuMtE/target-source/venv/lib/python3.10/site-packages/graph2tac/tfgnn/predict.py", line 685, in _compile_network
    inference_model_bare = self.prediction_task.create_inference_model(
  File "/tmp/tactician.tmp.KzuMtE/target-source/venv/lib/python3.10/site-packages/graph2tac/tfgnn/tasks.py", line 1343, in create_inference_model
    tactic, top_k_values = self._top_k_tactics(tactic_logits=tactic_logits,
  File "/tmp/tactician.tmp.KzuMtE/target-source/venv/lib/python3.10/site-packages/graph2tac/tfgnn/tasks.py", line 561, in _top_k_tactics
    top_k = tf.math.top_k(tactic_logits, k=tactic_expand_bound)
  File "/tmp/tactician.tmp.KzuMtE/target-source/venv/lib/python3.10/site-packages/tensorflow/python/util/traceback_utils.py", line 153, in error_handler
    raise e.with_traceback(filtered_tb) from None
  File "/tmp/tactician.tmp.KzuMtE/target-source/venv/lib/python3.10/site-packages/keras/layers/core/tf_op_layer.py", line 107, in handle
    return TFOpLambda(op)(*args, **kwargs)
  File "/tmp/tactician.tmp.KzuMtE/target-source/venv/lib/python3.10/site-packages/keras/utils/traceback_utils.py", line 67, in error_handler
    raise e.with_traceback(filtered_tb) from None
ValueError: Exception encountered when calling layer "tf.math.top_k" (type TFOpLambda).

input must have last dimension >= k = 2048 but is 1247 for '{{node tf.math.top_k/TopKV2}} = TopKV2[T=DT_FLOAT, sorted=true](Placeholder, tf.math.top_k/TopKV2/k)' with input shapes: [?,1247], [] and with computed input tensors: input[1] = <2048>.

Call arguments received by layer "tf.math.top_k" (type TFOpLambda):
  • input=tf.Tensor(shape=(None, 1247), dtype=float32)
  • k=2048
  • sorted=True
  • name=None
File "./milieu.v", line 86, characters 0-27:
Error:
Anomaly "Uncaught exception Unix.Unix_error(Unix.EPIPE, "single_write", "")."
Please report at http://coq.inria.fr/bugs/.

File "/tmp/tactician.tmp.KzuMtE/opam-root/bench/lib/coq/user-contrib/Tactician/Graph2TacConfig.v", line 1, characters 0-32:
Warning: There is no option Tactician Neural Truncate.
[unknown-option,option]
File "/tmp/tactician.tmp.KzuMtE/opam-root/bench/lib/coq/user-contrib/Tactician/Graph2TacConfig.v", line 1, characters 0-32:
Warning: There is no option Tactician Neural Truncate.
[unknown-option,option]
Traceback (most recent call last):
  File "/tmp/tactician.tmp.KzuMtE/target-source/venv/bin/g2t-server", line 33, in <module>
    sys.exit(load_entry_point('graph2tac==0.1.0', 'console_scripts', 'g2t-server')())
  File "/tmp/tactician.tmp.KzuMtE/target-source/venv/lib/python3.10/site-packages/graph2tac/loader/predict_server.py", line 967, in main
    main_with_return_value()
  File "/tmp/tactician.tmp.KzuMtE/target-source/venv/lib/python3.10/site-packages/graph2tac/loader/predict_server.py", line 922, in main_with_return_value
    model = load_model(config, log_levels)
  File "/tmp/tactician.tmp.KzuMtE/target-source/venv/lib/python3.10/site-packages/graph2tac/loader/predict_server.py", line 871, in load_model
    model = TFGNNPredict(log_dir=Path(config.model).expanduser().absolute(),
  File "/tmp/tactician.tmp.KzuMtE/target-source/venv/lib/python3.10/site-packages/graph2tac/tfgnn/predict.py", line 620, in __init__
    self._compile_network()
  File "/tmp/tactician.tmp.KzuMtE/target-source/venv/lib/python3.10/site-packages/graph2tac/tfgnn/predict.py", line 685, in _compile_network
    inference_model_bare = self.prediction_task.create_inference_model(
  File "/tmp/tactician.tmp.KzuMtE/target-source/venv/lib/python3.10/site-packages/graph2tac/tfgnn/tasks.py", line 1343, in create_inference_model
    tactic, top_k_values = self._top_k_tactics(tactic_logits=tactic_logits,
  File "/tmp/tactician.tmp.KzuMtE/target-source/venv/lib/python3.10/site-packages/graph2tac/tfgnn/tasks.py", line 561, in _top_k_tactics
    top_k = tf.math.top_k(tactic_logits, k=tactic_expand_bound)
  File "/tmp/tactician.tmp.KzuMtE/target-source/venv/lib/python3.10/site-packages/tensorflow/python/util/traceback_utils.py", line 153, in error_handler
    raise e.with_traceback(filtered_tb) from None
  File "/tmp/tactician.tmp.KzuMtE/target-source/venv/lib/python3.10/site-packages/keras/layers/core/tf_op_layer.py", line 107, in handle
    return TFOpLambda(op)(*args, **kwargs)
  File "/tmp/tactician.tmp.KzuMtE/target-source/venv/lib/python3.10/site-packages/keras/utils/traceback_utils.py", line 67, in error_handler
    raise e.with_traceback(filtered_tb) from None
ValueError: Exception encountered when calling layer "tf.math.top_k" (type TFOpLambda).

input must have last dimension >= k = 2048 but is 1247 for '{{node tf.math.top_k/TopKV2}} = TopKV2[T=DT_FLOAT, sorted=true](Placeholder, tf.math.top_k/TopKV2/k)' with input shapes: [?,1247], [] and with computed input tensors: input[1] = <2048>.

Call arguments received by layer "tf.math.top_k" (type TFOpLambda):
  • input=tf.Tensor(shape=(None, 1247), dtype=float32)
  • k=2048
  • sorted=True
  • name=None
Traceback (most recent call last):
  File "/tmp/tactician.tmp.KzuMtE/target-source/venv/bin/g2t-server", line 33, in <module>
    sys.exit(load_entry_point('graph2tac==0.1.0', 'console_scripts', 'g2t-server')())
  File "/tmp/tactician.tmp.KzuMtE/target-source/venv/lib/python3.10/site-packages/graph2tac/loader/predict_server.py", line 967, in main
    main_with_return_value()
  File "/tmp/tactician.tmp.KzuMtE/target-source/venv/lib/python3.10/site-packages/graph2tac/loader/predict_server.py", line 922, in main_with_return_value
    model = load_model(config, log_levels)
  File "/tmp/tactician.tmp.KzuMtE/target-source/venv/lib/python3.10/site-packages/graph2tac/loader/predict_server.py", line 871, in load_model
    model = TFGNNPredict(log_dir=Path(config.model).expanduser().absolute(),
  File "/tmp/tactician.tmp.KzuMtE/target-source/venv/lib/python3.10/site-packages/graph2tac/tfgnn/predict.py", line 620, in __init__
    self._compile_network()
  File "/tmp/tactician.tmp.KzuMtE/target-source/venv/lib/python3.10/site-packages/graph2tac/tfgnn/predict.py", line 685, in _compile_network
    inference_model_bare = self.prediction_task.create_inference_model(
  File "/tmp/tactician.tmp.KzuMtE/target-source/venv/lib/python3.10/site-packages/graph2tac/tfgnn/tasks.py", line 1343, in create_inference_model
    tactic, top_k_values = self._top_k_tactics(tactic_logits=tactic_logits,
  File "/tmp/tactician.tmp.KzuMtE/target-source/venv/lib/python3.10/site-packages/graph2tac/tfgnn/tasks.py", line 561, in _top_k_tactics
    top_k = tf.math.top_k(tactic_logits, k=tactic_expand_bound)
  File "/tmp/tactician.tmp.KzuMtE/target-source/venv/lib/python3.10/site-packages/tensorflow/python/util/traceback_utils.py", line 153, in error_handler
    raise e.with_traceback(filtered_tb) from None
  File "/tmp/tactician.tmp.KzuMtE/target-source/venv/lib/python3.10/site-packages/keras/layers/core/tf_op_layer.py", line 107, in handle
    return TFOpLambda(op)(*args, **kwargs)
  File "/tmp/tactician.tmp.KzuMtE/target-source/venv/lib/python3.10/site-packages/keras/utils/traceback_utils.py", line 67, in error_handler
    raise e.with_traceback(filtered_tb) from None
ValueError: Exception encountered when calling layer "tf.math.top_k" (type TFOpLambda).

input must have last dimension >= k = 2048 but is 1247 for '{{node tf.math.top_k/TopKV2}} = TopKV2[T=DT_FLOAT, sorted=true](Placeholder, tf.math.top_k/TopKV2/k)' with input shapes: [?,1247], [] and with computed input tensors: input[1] = <2048>.

Call arguments received by layer "tf.math.top_k" (type TFOpLambda):
  • input=tf.Tensor(shape=(None, 1247), dtype=float32)
  • k=2048
  • sorted=True
  • name=None
Traceback (most recent call last):
  File "/tmp/tactician.tmp.KzuMtE/target-source/venv/bin/g2t-server", line 33, in <module>
    sys.exit(load_entry_point('graph2tac==0.1.0', 'console_scripts', 'g2t-server')())
  File "/tmp/tactician.tmp.KzuMtE/target-source/venv/lib/python3.10/site-packages/graph2tac/loader/predict_server.py", line 967, in main
    main_with_return_value()
  File "/tmp/tactician.tmp.KzuMtE/target-source/venv/lib/python3.10/site-packages/graph2tac/loader/predict_server.py", line 922, in main_with_return_value
    model = load_model(config, log_levels)
  File "/tmp/tactician.tmp.KzuMtE/target-source/venv/lib/python3.10/site-packages/graph2tac/loader/predict_server.py", line 871, in load_model
    model = TFGNNPredict(log_dir=Path(config.model).expanduser().absolute(),
  File "/tmp/tactician.tmp.KzuMtE/target-source/venv/lib/python3.10/site-packages/graph2tac/tfgnn/predict.py", line 620, in __init__
    self._compile_network()
  File "/tmp/tactician.tmp.KzuMtE/target-source/venv/lib/python3.10/site-packages/graph2tac/tfgnn/predict.py", line 685, in _compile_network
    inference_model_bare = self.prediction_task.create_inference_model(
  File "/tmp/tactician.tmp.KzuMtE/target-source/venv/lib/python3.10/site-packages/graph2tac/tfgnn/tasks.py", line 1343, in create_inference_model
    tactic, top_k_values = self._top_k_tactics(tactic_logits=tactic_logits,
  File "/tmp/tactician.tmp.KzuMtE/target-source/venv/lib/python3.10/site-packages/graph2tac/tfgnn/tasks.py", line 561, in _top_k_tactics
    top_k = tf.math.top_k(tactic_logits, k=tactic_expand_bound)
  File "/tmp/tactician.tmp.KzuMtE/target-source/venv/lib/python3.10/site-packages/tensorflow/python/util/traceback_utils.py", line 153, in error_handler
    raise e.with_traceback(filtered_tb) from None
  File "/tmp/tactician.tmp.KzuMtE/target-source/venv/lib/python3.10/site-packages/keras/layers/core/tf_op_layer.py", line 107, in handle
    return TFOpLambda(op)(*args, **kwargs)
  File "/tmp/tactician.tmp.KzuMtE/target-source/venv/lib/python3.10/site-packages/keras/utils/traceback_utils.py", line 67, in error_handler
    raise e.with_traceback(filtered_tb) from None
ValueError: Exception encountered when calling layer "tf.math.top_k" (type TFOpLambda).

input must have last dimension >= k = 2048 but is 1247 for '{{node tf.math.top_k/TopKV2}} = TopKV2[T=DT_FLOAT, sorted=true](Placeholder, tf.math.top_k/TopKV2/k)' with input shapes: [?,1247], [] and with computed input tensors: input[1] = <2048>.

Call arguments received by layer "tf.math.top_k" (type TFOpLambda):
  • input=tf.Tensor(shape=(None, 1247), dtype=float32)
  • k=2048
  • sorted=True
  • name=None
Traceback (most recent call last):
  File "/tmp/tactician.tmp.KzuMtE/target-source/venv/bin/g2t-server", line 33, in <module>
    sys.exit(load_entry_point('graph2tac==0.1.0', 'console_scripts', 'g2t-server')())
  File "/tmp/tactician.tmp.KzuMtE/target-source/venv/lib/python3.10/site-packages/graph2tac/loader/predict_server.py", line 967, in main
    main_with_return_value()
  File "/tmp/tactician.tmp.KzuMtE/target-source/venv/lib/python3.10/site-packages/graph2tac/loader/predict_server.py", line 922, in main_with_return_value
    model = load_model(config, log_levels)
  File "/tmp/tactician.tmp.KzuMtE/target-source/venv/lib/python3.10/site-packages/graph2tac/loader/predict_server.py", line 871, in load_model
    model = TFGNNPredict(log_dir=Path(config.model).expanduser().absolute(),
  File "/tmp/tactician.tmp.KzuMtE/target-source/venv/lib/python3.10/site-packages/graph2tac/tfgnn/predict.py", line 620, in __init__
    self._compile_network()
  File "/tmp/tactician.tmp.KzuMtE/target-source/venv/lib/python3.10/site-packages/graph2tac/tfgnn/predict.py", line 685, in _compile_network
    inference_model_bare = self.prediction_task.create_inference_model(
  File "/tmp/tactician.tmp.KzuMtE/target-source/venv/lib/python3.10/site-packages/graph2tac/tfgnn/tasks.py", line 1343, in create_inference_model
    tactic, top_k_values = self._top_k_tactics(tactic_logits=tactic_logits,
  File "/tmp/tactician.tmp.KzuMtE/target-source/venv/lib/python3.10/site-packages/graph2tac/tfgnn/tasks.py", line 561, in _top_k_tactics
    top_k = tf.math.top_k(tactic_logits, k=tactic_expand_bound)
  File "/tmp/tactician.tmp.KzuMtE/target-source/venv/lib/python3.10/site-packages/tensorflow/python/util/traceback_utils.py", line 153, in error_handler
    raise e.with_traceback(filtered_tb) from None
  File "/tmp/tactician.tmp.KzuMtE/target-source/venv/lib/python3.10/site-packages/keras/layers/core/tf_op_layer.py", line 107, in handle
    return TFOpLambda(op)(*args, **kwargs)
  File "/tmp/tactician.tmp.KzuMtE/target-source/venv/lib/python3.10/site-packages/keras/utils/traceback_utils.py", line 67, in error_handler
    raise e.with_traceback(filtered_tb) from None
ValueError: Exception encountered when calling layer "tf.math.top_k" (type TFOpLambda).

input must have last dimension >= k = 2048 but is 1247 for '{{node tf.math.top_k/TopKV2}} = TopKV2[T=DT_FLOAT, sorted=true](Placeholder, tf.math.top_k/TopKV2/k)' with input shapes: [?,1247], [] and with computed input tensors: input[1] = <2048>.

Call arguments received by layer "tf.math.top_k" (type TFOpLambda):
  • input=tf.Tensor(shape=(None, 1247), dtype=float32)
  • k=2048
  • sorted=True
  • name=None
File "./repere_plan.v", line 167, characters 0-7:
Error:
Anomaly "Uncaught exception Unix.Unix_error(Unix.EPIPE, "single_write", "")."
Please report at http://coq.inria.fr/bugs/.

File "./vecteur.v", line 72, characters 0-27:
Error:
Anomaly "Uncaught exception Unix.Unix_error(Unix.EPIPE, "single_write", "")."
Please report at http://coq.inria.fr/bugs/.

File "./barycentre.v", line 221, characters 0-7:
Error:
Anomaly "Uncaught exception Unix.Unix_error(Unix.EPIPE, "single_write", "")."
Please report at http://coq.inria.fr/bugs/.

File "./affine_classiques.v", line 89, characters 0-43:
Error:
Anomaly "Uncaught exception Unix.Unix_error(Unix.EPIPE, "single_write", "")."
Please report at http://coq.inria.fr/bugs/.

File "./Field_affine.v", line 142, characters 0-15:
Error:
Anomaly "Uncaught exception Unix.Unix_error(Unix.EPIPE, "single_write", "")."
Please report at http://coq.inria.fr/bugs/.

File "./Rutile.v", line 199, characters 0-4:
Error:
Anomaly "Uncaught exception Unix.Unix_error(Unix.EPIPE, "single_write", "")."
Please report at http://coq.inria.fr/bugs/.

File "/tmp/tactician.tmp.KzuMtE/opam-root/bench/lib/coq/user-contrib/Tactician/Graph2TacConfig.v", line 1, characters 0-32:
Warning: There is no option Tactician Neural Truncate.
[unknown-option,option]
Traceback (most recent call last):
  File "/tmp/tactician.tmp.KzuMtE/target-source/venv/bin/g2t-server", line 33, in <module>
    sys.exit(load_entry_point('graph2tac==0.1.0', 'console_scripts', 'g2t-server')())
  File "/tmp/tactician.tmp.KzuMtE/target-source/venv/lib/python3.10/site-packages/graph2tac/loader/predict_server.py", line 967, in main
    main_with_return_value()
  File "/tmp/tactician.tmp.KzuMtE/target-source/venv/lib/python3.10/site-packages/graph2tac/loader/predict_server.py", line 922, in main_with_return_value
    model = load_model(config, log_levels)
  File "/tmp/tactician.tmp.KzuMtE/target-source/venv/lib/python3.10/site-packages/graph2tac/loader/predict_server.py", line 871, in load_model
    model = TFGNNPredict(log_dir=Path(config.model).expanduser().absolute(),
  File "/tmp/tactician.tmp.KzuMtE/target-source/venv/lib/python3.10/site-packages/graph2tac/tfgnn/predict.py", line 620, in __init__
    self._compile_network()
  File "/tmp/tactician.tmp.KzuMtE/target-source/venv/lib/python3.10/site-packages/graph2tac/tfgnn/predict.py", line 685, in _compile_network
    inference_model_bare = self.prediction_task.create_inference_model(
  File "/tmp/tactician.tmp.KzuMtE/target-source/venv/lib/python3.10/site-packages/graph2tac/tfgnn/tasks.py", line 1343, in create_inference_model
    tactic, top_k_values = self._top_k_tactics(tactic_logits=tactic_logits,
  File "/tmp/tactician.tmp.KzuMtE/target-source/venv/lib/python3.10/site-packages/graph2tac/tfgnn/tasks.py", line 561, in _top_k_tactics
    top_k = tf.math.top_k(tactic_logits, k=tactic_expand_bound)
  File "/tmp/tactician.tmp.KzuMtE/target-source/venv/lib/python3.10/site-packages/tensorflow/python/util/traceback_utils.py", line 153, in error_handler
    raise e.with_traceback(filtered_tb) from None
  File "/tmp/tactician.tmp.KzuMtE/target-source/venv/lib/python3.10/site-packages/keras/layers/core/tf_op_layer.py", line 107, in handle
    return TFOpLambda(op)(*args, **kwargs)
  File "/tmp/tactician.tmp.KzuMtE/target-source/venv/lib/python3.10/site-packages/keras/utils/traceback_utils.py", line 67, in error_handler
    raise e.with_traceback(filtered_tb) from None
ValueError: Exception encountered when calling layer "tf.math.top_k" (type TFOpLambda).

input must have last dimension >= k = 2048 but is 1247 for '{{node tf.math.top_k/TopKV2}} = TopKV2[T=DT_FLOAT, sorted=true](Placeholder, tf.math.top_k/TopKV2/k)' with input shapes: [?,1247], [] and with computed input tensors: input[1] = <2048>.

Call arguments received by layer "tf.math.top_k" (type TFOpLambda):
  • input=tf.Tensor(shape=(None, 1247), dtype=float32)
  • k=2048
  • sorted=True
  • name=None
File "./theories/Data/Map/FMapAList.v", line 82, characters 6-31:
Error:
Anomaly "Uncaught exception Unix.Unix_error(Unix.EPIPE, "single_write", "")."
Please report at http://coq.inria.fr/bugs/.

File "/tmp/tactician.tmp.KzuMtE/opam-root/bench/lib/coq/user-contrib/Tactician/Graph2TacConfig.v", line 1, characters 0-32:
Warning: There is no option Tactician Neural Truncate.
[unknown-option,option]
Traceback (most recent call last):
  File "/tmp/tactician.tmp.KzuMtE/target-source/venv/bin/g2t-server", line 33, in <module>
    sys.exit(load_entry_point('graph2tac==0.1.0', 'console_scripts', 'g2t-server')())
  File "/tmp/tactician.tmp.KzuMtE/target-source/venv/lib/python3.10/site-packages/graph2tac/loader/predict_server.py", line 967, in main
    main_with_return_value()
  File "/tmp/tactician.tmp.KzuMtE/target-source/venv/lib/python3.10/site-packages/graph2tac/loader/predict_server.py", line 922, in main_with_return_value
    model = load_model(config, log_levels)
  File "/tmp/tactician.tmp.KzuMtE/target-source/venv/lib/python3.10/site-packages/graph2tac/loader/predict_server.py", line 871, in load_model
    model = TFGNNPredict(log_dir=Path(config.model).expanduser().absolute(),
  File "/tmp/tactician.tmp.KzuMtE/target-source/venv/lib/python3.10/site-packages/graph2tac/tfgnn/predict.py", line 620, in __init__
    self._compile_network()
  File "/tmp/tactician.tmp.KzuMtE/target-source/venv/lib/python3.10/site-packages/graph2tac/tfgnn/predict.py", line 685, in _compile_network
    inference_model_bare = self.prediction_task.create_inference_model(
  File "/tmp/tactician.tmp.KzuMtE/target-source/venv/lib/python3.10/site-packages/graph2tac/tfgnn/tasks.py", line 1343, in create_inference_model
    tactic, top_k_values = self._top_k_tactics(tactic_logits=tactic_logits,
  File "/tmp/tactician.tmp.KzuMtE/target-source/venv/lib/python3.10/site-packages/graph2tac/tfgnn/tasks.py", line 561, in _top_k_tactics
    top_k = tf.math.top_k(tactic_logits, k=tactic_expand_bound)
  File "/tmp/tactician.tmp.KzuMtE/target-source/venv/lib/python3.10/site-packages/tensorflow/python/util/traceback_utils.py", line 153, in error_handler
    raise e.with_traceback(filtered_tb) from None
  File "/tmp/tactician.tmp.KzuMtE/target-source/venv/lib/python3.10/site-packages/keras/layers/core/tf_op_layer.py", line 107, in handle
    return TFOpLambda(op)(*args, **kwargs)
  File "/tmp/tactician.tmp.KzuMtE/target-source/venv/lib/python3.10/site-packages/keras/utils/traceback_utils.py", line 67, in error_handler
    raise e.with_traceback(filtered_tb) from None
ValueError: Exception encountered when calling layer "tf.math.top_k" (type TFOpLambda).

input must have last dimension >= k = 2048 but is 1247 for '{{node tf.math.top_k/TopKV2}} = TopKV2[T=DT_FLOAT, sorted=true](Placeholder, tf.math.top_k/TopKV2/k)' with input shapes: [?,1247], [] and with computed input tensors: input[1] = <2048>.

Call arguments received by layer "tf.math.top_k" (type TFOpLambda):
  • input=tf.Tensor(shape=(None, 1247), dtype=float32)
  • k=2048
  • sorted=True
  • name=None
File "./theories/Data/List.v", line 84, characters 7-13:
Error:
Anomaly "Uncaught exception Unix.Unix_error(Unix.EPIPE, "single_write", "")."
Please report at http://coq.inria.fr/bugs/.

File "./parallelisme_concours.v", line 278, characters 0-28:
Error:
Anomaly "Uncaught exception Unix.Unix_error(Unix.EPIPE, "single_write", "")."
Please report at http://coq.inria.fr/bugs/.

File "./milieu.v", line 134, characters 0-29:
Error:
Anomaly "Uncaught exception Unix.Unix_error(Unix.EPIPE, "single_write", "")."
Please report at http://coq.inria.fr/bugs/.

File "/tmp/tactician.tmp.KzuMtE/opam-root/bench/lib/coq/user-contrib/Tactician/Graph2TacConfig.v", line 1, characters 0-32:
Warning: There is no option Tactician Neural Truncate.
[unknown-option,option]
Traceback (most recent call last):
  File "/tmp/tactician.tmp.KzuMtE/target-source/venv/bin/g2t-server", line 33, in <module>
    sys.exit(load_entry_point('graph2tac==0.1.0', 'console_scripts', 'g2t-server')())
  File "/tmp/tactician.tmp.KzuMtE/target-source/venv/lib/python3.10/site-packages/graph2tac/loader/predict_server.py", line 967, in main
    main_with_return_value()
  File "/tmp/tactician.tmp.KzuMtE/target-source/venv/lib/python3.10/site-packages/graph2tac/loader/predict_server.py", line 922, in main_with_return_value
    model = load_model(config, log_levels)
  File "/tmp/tactician.tmp.KzuMtE/target-source/venv/lib/python3.10/site-packages/graph2tac/loader/predict_server.py", line 871, in load_model
    model = TFGNNPredict(log_dir=Path(config.model).expanduser().absolute(),
  File "/tmp/tactician.tmp.KzuMtE/target-source/venv/lib/python3.10/site-packages/graph2tac/tfgnn/predict.py", line 620, in __init__
    self._compile_network()
  File "/tmp/tactician.tmp.KzuMtE/target-source/venv/lib/python3.10/site-packages/graph2tac/tfgnn/predict.py", line 685, in _compile_network
    inference_model_bare = self.prediction_task.create_inference_model(
  File "/tmp/tactician.tmp.KzuMtE/target-source/venv/lib/python3.10/site-packages/graph2tac/tfgnn/tasks.py", line 1343, in create_inference_model
    tactic, top_k_values = self._top_k_tactics(tactic_logits=tactic_logits,
  File "/tmp/tactician.tmp.KzuMtE/target-source/venv/lib/python3.10/site-packages/graph2tac/tfgnn/tasks.py", line 561, in _top_k_tactics
    top_k = tf.math.top_k(tactic_logits, k=tactic_expand_bound)
  File "/tmp/tactician.tmp.KzuMtE/target-source/venv/lib/python3.10/site-packages/tensorflow/python/util/traceback_utils.py", line 153, in error_handler
    raise e.with_traceback(filtered_tb) from None
  File "/tmp/tactician.tmp.KzuMtE/target-source/venv/lib/python3.10/site-packages/keras/layers/core/tf_op_layer.py", line 107, in handle
    return TFOpLambda(op)(*args, **kwargs)
  File "/tmp/tactician.tmp.KzuMtE/target-source/venv/lib/python3.10/site-packages/keras/utils/traceback_utils.py", line 67, in error_handler
    raise e.with_traceback(filtered_tb) from None
ValueError: Exception encountered when calling layer "tf.math.top_k" (type TFOpLambda).

input must have last dimension >= k = 2048 but is 1247 for '{{node tf.math.top_k/TopKV2}} = TopKV2[T=DT_FLOAT, sorted=true](Placeholder, tf.math.top_k/TopKV2/k)' with input shapes: [?,1247], [] and with computed input tensors: input[1] = <2048>.

Call arguments received by layer "tf.math.top_k" (type TFOpLambda):
  • input=tf.Tensor(shape=(None, 1247), dtype=float32)
  • k=2048
  • sorted=True
  • name=None
File "./theories/Data/SumN.v", line 131, characters 2-25:
Error:
Anomaly "Uncaught exception Unix.Unix_error(Unix.EPIPE, "single_write", "")."
Please report at http://coq.inria.fr/bugs/.

File "./vecteur.v", line 122, characters 0-27:
Error:
Anomaly "Uncaught exception Unix.Unix_error(Unix.EPIPE, "single_write", "")."
Please report at http://coq.inria.fr/bugs/.

File "./affine_classiques.v", line 216, characters 0-51:
Error:
Anomaly "Uncaught exception Unix.Unix_error(Unix.EPIPE, "single_write", "")."
Please report at http://coq.inria.fr/bugs/.

File "./Field_affine.v", line 146, characters 0-15:
Error:
Anomaly "Uncaught exception Unix.Unix_error(Unix.EPIPE, "single_write", "")."
Please report at http://coq.inria.fr/bugs/.

File "./Rutile.v", line 203, characters 0-4:
Error:
Anomaly "Uncaught exception Unix.Unix_error(Unix.EPIPE, "single_write", "")."
Please report at http://coq.inria.fr/bugs/.

File "./barycentre.v", line 559, characters 0-27:
Error:
Anomaly "Uncaught exception Unix.Unix_error(Unix.EPIPE, "single_write", "")."
Please report at http://coq.inria.fr/bugs/.

File "./theories/Data/Map/FMapAList.v", line 173, characters 6-38:
Error:
Anomaly "Uncaught exception Unix.Unix_error(Unix.EPIPE, "single_write", "")."
Please report at http://coq.inria.fr/bugs/.

File "/tmp/tactician.tmp.KzuMtE/opam-root/bench/lib/coq/user-contrib/Tactician/Graph2TacConfig.v", line 1, characters 0-32:
Warning: There is no option Tactician Neural Truncate.
[unknown-option,option]
Traceback (most recent call last):
  File "/tmp/tactician.tmp.KzuMtE/target-source/venv/bin/g2t-server", line 33, in <module>
    sys.exit(load_entry_point('graph2tac==0.1.0', 'console_scripts', 'g2t-server')())
  File "/tmp/tactician.tmp.KzuMtE/target-source/venv/lib/python3.10/site-packages/graph2tac/loader/predict_server.py", line 967, in main
    main_with_return_value()
  File "/tmp/tactician.tmp.KzuMtE/target-source/venv/lib/python3.10/site-packages/graph2tac/loader/predict_server.py", line 922, in main_with_return_value
    model = load_model(config, log_levels)
  File "/tmp/tactician.tmp.KzuMtE/target-source/venv/lib/python3.10/site-packages/graph2tac/loader/predict_server.py", line 871, in load_model
    model = TFGNNPredict(log_dir=Path(config.model).expanduser().absolute(),
  File "/tmp/tactician.tmp.KzuMtE/target-source/venv/lib/python3.10/site-packages/graph2tac/tfgnn/predict.py", line 620, in __init__
    self._compile_network()
  File "/tmp/tactician.tmp.KzuMtE/target-source/venv/lib/python3.10/site-packages/graph2tac/tfgnn/predict.py", line 685, in _compile_network
    inference_model_bare = self.prediction_task.create_inference_model(
  File "/tmp/tactician.tmp.KzuMtE/target-source/venv/lib/python3.10/site-packages/graph2tac/tfgnn/tasks.py", line 1343, in create_inference_model
    tactic, top_k_values = self._top_k_tactics(tactic_logits=tactic_logits,
  File "/tmp/tactician.tmp.KzuMtE/target-source/venv/lib/python3.10/site-packages/graph2tac/tfgnn/tasks.py", line 561, in _top_k_tactics
    top_k = tf.math.top_k(tactic_logits, k=tactic_expand_bound)
  File "/tmp/tactician.tmp.KzuMtE/target-source/venv/lib/python3.10/site-packages/tensorflow/python/util/traceback_utils.py", line 153, in error_handler
    raise e.with_traceback(filtered_tb) from None
  File "/tmp/tactician.tmp.KzuMtE/target-source/venv/lib/python3.10/site-packages/keras/layers/core/tf_op_layer.py", line 107, in handle
    return TFOpLambda(op)(*args, **kwargs)
  File "/tmp/tactician.tmp.KzuMtE/target-source/venv/lib/python3.10/site-packages/keras/utils/traceback_utils.py", line 67, in error_handler
    raise e.with_traceback(filtered_tb) from None
ValueError: Exception encountered when calling layer "tf.math.top_k" (type TFOpLambda).

input must have last dimension >= k = 2048 but is 1247 for '{{node tf.math.top_k/TopKV2}} = TopKV2[T=DT_FLOAT, sorted=true](Placeholder, tf.math.top_k/TopKV2/k)' with input shapes: [?,1247], [] and with computed input tensors: input[1] = <2048>.

Call arguments received by layer "tf.math.top_k" (type TFOpLambda):
  • input=tf.Tensor(shape=(None, 1247), dtype=float32)
  • k=2048
  • sorted=True
  • name=None
File "./theories/Data/Z.v", line 24, characters 2-21:
Error:
Anomaly "Uncaught exception Unix.Unix_error(Unix.EPIPE, "single_write", "")."
Please report at http://coq.inria.fr/bugs/.

File "/tmp/tactician.tmp.KzuMtE/opam-root/bench/lib/coq/user-contrib/Tactician/Graph2TacConfig.v", line 1, characters 0-32:
Warning: There is no option Tactician Neural Truncate.
[unknown-option,option]
File "./parallelisme_concours.v", line 316, characters 0-44:
Error:
Anomaly "Uncaught exception Unix.Unix_error(Unix.EPIPE, "single_write", "")."
Please report at http://coq.inria.fr/bugs/.

Traceback (most recent call last):
  File "/tmp/tactician.tmp.KzuMtE/target-source/venv/bin/g2t-server", line 33, in <module>
    sys.exit(load_entry_point('graph2tac==0.1.0', 'console_scripts', 'g2t-server')())
  File "/tmp/tactician.tmp.KzuMtE/target-source/venv/lib/python3.10/site-packages/graph2tac/loader/predict_server.py", line 967, in main
    main_with_return_value()
  File "/tmp/tactician.tmp.KzuMtE/target-source/venv/lib/python3.10/site-packages/graph2tac/loader/predict_server.py", line 922, in main_with_return_value
    model = load_model(config, log_levels)
  File "/tmp/tactician.tmp.KzuMtE/target-source/venv/lib/python3.10/site-packages/graph2tac/loader/predict_server.py", line 871, in load_model
    model = TFGNNPredict(log_dir=Path(config.model).expanduser().absolute(),
  File "/tmp/tactician.tmp.KzuMtE/target-source/venv/lib/python3.10/site-packages/graph2tac/tfgnn/predict.py", line 620, in __init__
    self._compile_network()
  File "/tmp/tactician.tmp.KzuMtE/target-source/venv/lib/python3.10/site-packages/graph2tac/tfgnn/predict.py", line 685, in _compile_network
    inference_model_bare = self.prediction_task.create_inference_model(
  File "/tmp/tactician.tmp.KzuMtE/target-source/venv/lib/python3.10/site-packages/graph2tac/tfgnn/tasks.py", line 1343, in create_inference_model
    tactic, top_k_values = self._top_k_tactics(tactic_logits=tactic_logits,
  File "/tmp/tactician.tmp.KzuMtE/target-source/venv/lib/python3.10/site-packages/graph2tac/tfgnn/tasks.py", line 561, in _top_k_tactics
    top_k = tf.math.top_k(tactic_logits, k=tactic_expand_bound)
  File "/tmp/tactician.tmp.KzuMtE/target-source/venv/lib/python3.10/site-packages/tensorflow/python/util/traceback_utils.py", line 153, in error_handler
    raise e.with_traceback(filtered_tb) from None
  File "/tmp/tactician.tmp.KzuMtE/target-source/venv/lib/python3.10/site-packages/keras/layers/core/tf_op_layer.py", line 107, in handle
    return TFOpLambda(op)(*args, **kwargs)
  File "/tmp/tactician.tmp.KzuMtE/target-source/venv/lib/python3.10/site-packages/keras/utils/traceback_utils.py", line 67, in error_handler
    raise e.with_traceback(filtered_tb) from None
ValueError: Exception encountered when calling layer "tf.math.top_k" (type TFOpLambda).

input must have last dimension >= k = 2048 but is 1247 for '{{node tf.math.top_k/TopKV2}} = TopKV2[T=DT_FLOAT, sorted=true](Placeholder, tf.math.top_k/TopKV2/k)' with input shapes: [?,1247], [] and with computed input tensors: input[1] = <2048>.

Call arguments received by layer "tf.math.top_k" (type TFOpLambda):
  • input=tf.Tensor(shape=(None, 1247), dtype=float32)
  • k=2048
  • sorted=True
  • name=None
File "./theories/Data/Nat.v", line 30, characters 2-21:
Error:
Anomaly "Uncaught exception Unix.Unix_error(Unix.EPIPE, "single_write", "")."
Please report at http://coq.inria.fr/bugs/.

File "/tmp/tactician.tmp.KzuMtE/opam-root/bench/lib/coq/user-contrib/Tactician/Graph2TacConfig.v", line 1, characters 0-32:
Warning: There is no option Tactician Neural Truncate.
[unknown-option,option]
File "/tmp/tactician.tmp.KzuMtE/opam-root/bench/lib/coq/user-contrib/Tactician/Graph2TacConfig.v", line 1, characters 0-32:
Warning: There is no option Tactician Neural Truncate.
[unknown-option,option]
File "/tmp/tactician.tmp.KzuMtE/opam-root/bench/lib/coq/user-contrib/Tactician/Graph2TacConfig.v", line 1, characters 0-32:
Warning: There is no option Tactician Neural Truncate.
[unknown-option,option]
Traceback (most recent call last):
  File "/tmp/tactician.tmp.KzuMtE/target-source/venv/bin/g2t-server", line 33, in <module>
    sys.exit(load_entry_point('graph2tac==0.1.0', 'console_scripts', 'g2t-server')())
  File "/tmp/tactician.tmp.KzuMtE/target-source/venv/lib/python3.10/site-packages/graph2tac/loader/predict_server.py", line 967, in main
    main_with_return_value()
  File "/tmp/tactician.tmp.KzuMtE/target-source/venv/lib/python3.10/site-packages/graph2tac/loader/predict_server.py", line 922, in main_with_return_value
    model = load_model(config, log_levels)
  File "/tmp/tactician.tmp.KzuMtE/target-source/venv/lib/python3.10/site-packages/graph2tac/loader/predict_server.py", line 871, in load_model
    model = TFGNNPredict(log_dir=Path(config.model).expanduser().absolute(),
  File "/tmp/tactician.tmp.KzuMtE/target-source/venv/lib/python3.10/site-packages/graph2tac/tfgnn/predict.py", line 620, in __init__
    self._compile_network()
  File "/tmp/tactician.tmp.KzuMtE/target-source/venv/lib/python3.10/site-packages/graph2tac/tfgnn/predict.py", line 685, in _compile_network
    inference_model_bare = self.prediction_task.create_inference_model(
  File "/tmp/tactician.tmp.KzuMtE/target-source/venv/lib/python3.10/site-packages/graph2tac/tfgnn/tasks.py", line 1343, in create_inference_model
    tactic, top_k_values = self._top_k_tactics(tactic_logits=tactic_logits,
  File "/tmp/tactician.tmp.KzuMtE/target-source/venv/lib/python3.10/site-packages/graph2tac/tfgnn/tasks.py", line 561, in _top_k_tactics
    top_k = tf.math.top_k(tactic_logits, k=tactic_expand_bound)
  File "/tmp/tactician.tmp.KzuMtE/target-source/venv/lib/python3.10/site-packages/tensorflow/python/util/traceback_utils.py", line 153, in error_handler
    raise e.with_traceback(filtered_tb) from None
  File "/tmp/tactician.tmp.KzuMtE/target-source/venv/lib/python3.10/site-packages/keras/layers/core/tf_op_layer.py", line 107, in handle
    return TFOpLambda(op)(*args, **kwargs)
  File "/tmp/tactician.tmp.KzuMtE/target-source/venv/lib/python3.10/site-packages/keras/utils/traceback_utils.py", line 67, in error_handler
    raise e.with_traceback(filtered_tb) from None
ValueError: Exception encountered when calling layer "tf.math.top_k" (type TFOpLambda).

input must have last dimension >= k = 2048 but is 1247 for '{{node tf.math.top_k/TopKV2}} = TopKV2[T=DT_FLOAT, sorted=true](Placeholder, tf.math.top_k/TopKV2/k)' with input shapes: [?,1247], [] and with computed input tensors: input[1] = <2048>.

Call arguments received by layer "tf.math.top_k" (type TFOpLambda):
  • input=tf.Tensor(shape=(None, 1247), dtype=float32)
  • k=2048
  • sorted=True
  • name=None
File "/tmp/tactician.tmp.KzuMtE/opam-root/bench/lib/coq/user-contrib/Tactician/Graph2TacConfig.v", line 1, characters 0-32:
Warning: There is no option Tactician Neural Truncate.
[unknown-option,option]
File "./theories/Data/Char.v", line 34, characters 2-19:
Error:
Anomaly "Uncaught exception Unix.Unix_error(Unix.EPIPE, "single_write", "")."
Please report at http://coq.inria.fr/bugs/.

Traceback (most recent call last):
  File "/tmp/tactician.tmp.KzuMtE/target-source/venv/bin/g2t-server", line 33, in <module>
    sys.exit(load_entry_point('graph2tac==0.1.0', 'console_scripts', 'g2t-server')())
  File "/tmp/tactician.tmp.KzuMtE/target-source/venv/lib/python3.10/site-packages/graph2tac/loader/predict_server.py", line 967, in main
    main_with_return_value()
  File "/tmp/tactician.tmp.KzuMtE/target-source/venv/lib/python3.10/site-packages/graph2tac/loader/predict_server.py", line 922, in main_with_return_value
    model = load_model(config, log_levels)
  File "/tmp/tactician.tmp.KzuMtE/target-source/venv/lib/python3.10/site-packages/graph2tac/loader/predict_server.py", line 871, in load_model
    model = TFGNNPredict(log_dir=Path(config.model).expanduser().absolute(),
  File "/tmp/tactician.tmp.KzuMtE/target-source/venv/lib/python3.10/site-packages/graph2tac/tfgnn/predict.py", line 620, in __init__
    self._compile_network()
  File "/tmp/tactician.tmp.KzuMtE/target-source/venv/lib/python3.10/site-packages/graph2tac/tfgnn/predict.py", line 685, in _compile_network
    inference_model_bare = self.prediction_task.create_inference_model(
  File "/tmp/tactician.tmp.KzuMtE/target-source/venv/lib/python3.10/site-packages/graph2tac/tfgnn/tasks.py", line 1343, in create_inference_model
    tactic, top_k_values = self._top_k_tactics(tactic_logits=tactic_logits,
  File "/tmp/tactician.tmp.KzuMtE/target-source/venv/lib/python3.10/site-packages/graph2tac/tfgnn/tasks.py", line 561, in _top_k_tactics
    top_k = tf.math.top_k(tactic_logits, k=tactic_expand_bound)
  File "/tmp/tactician.tmp.KzuMtE/target-source/venv/lib/python3.10/site-packages/tensorflow/python/util/traceback_utils.py", line 153, in error_handler
    raise e.with_traceback(filtered_tb) from None
  File "/tmp/tactician.tmp.KzuMtE/target-source/venv/lib/python3.10/site-packages/keras/layers/core/tf_op_layer.py", line 107, in handle
    return TFOpLambda(op)(*args, **kwargs)
  File "/tmp/tactician.tmp.KzuMtE/target-source/venv/lib/python3.10/site-packages/keras/utils/traceback_utils.py", line 67, in error_handler
    raise e.with_traceback(filtered_tb) from None
ValueError: Exception encountered when calling layer "tf.math.top_k" (type TFOpLambda).

input must have last dimension >= k = 2048 but is 1247 for '{{node tf.math.top_k/TopKV2}} = TopKV2[T=DT_FLOAT, sorted=true](Placeholder, tf.math.top_k/TopKV2/k)' with input shapes: [?,1247], [] and with computed input tensors: input[1] = <2048>.

Call arguments received by layer "tf.math.top_k" (type TFOpLambda):
  • input=tf.Tensor(shape=(None, 1247), dtype=float32)
  • k=2048
  • sorted=True
  • name=None
File "./theories/Tactics/Consider.v", line 73, characters 4-52:
Error:
Anomaly "Uncaught exception Unix.Unix_error(Unix.EPIPE, "single_write", "")."
Please report at http://coq.inria.fr/bugs/.

File "/tmp/tactician.tmp.KzuMtE/opam-root/bench/lib/coq/user-contrib/Tactician/Graph2TacConfig.v", line 1, characters 0-32:
Warning: There is no option Tactician Neural Truncate.
[unknown-option,option]
Traceback (most recent call last):
  File "/tmp/tactician.tmp.KzuMtE/target-source/venv/bin/g2t-server", line 33, in <module>
    sys.exit(load_entry_point('graph2tac==0.1.0', 'console_scripts', 'g2t-server')())
  File "/tmp/tactician.tmp.KzuMtE/target-source/venv/lib/python3.10/site-packages/graph2tac/loader/predict_server.py", line 967, in main
    main_with_return_value()
  File "/tmp/tactician.tmp.KzuMtE/target-source/venv/lib/python3.10/site-packages/graph2tac/loader/predict_server.py", line 922, in main_with_return_value
    model = load_model(config, log_levels)
  File "/tmp/tactician.tmp.KzuMtE/target-source/venv/lib/python3.10/site-packages/graph2tac/loader/predict_server.py", line 871, in load_model
    model = TFGNNPredict(log_dir=Path(config.model).expanduser().absolute(),
  File "/tmp/tactician.tmp.KzuMtE/target-source/venv/lib/python3.10/site-packages/graph2tac/tfgnn/predict.py", line 620, in __init__
    self._compile_network()
  File "/tmp/tactician.tmp.KzuMtE/target-source/venv/lib/python3.10/site-packages/graph2tac/tfgnn/predict.py", line 685, in _compile_network
    inference_model_bare = self.prediction_task.create_inference_model(
  File "/tmp/tactician.tmp.KzuMtE/target-source/venv/lib/python3.10/site-packages/graph2tac/tfgnn/tasks.py", line 1343, in create_inference_model
    tactic, top_k_values = self._top_k_tactics(tactic_logits=tactic_logits,
  File "/tmp/tactician.tmp.KzuMtE/target-source/venv/lib/python3.10/site-packages/graph2tac/tfgnn/tasks.py", line 561, in _top_k_tactics
    top_k = tf.math.top_k(tactic_logits, k=tactic_expand_bound)
  File "/tmp/tactician.tmp.KzuMtE/target-source/venv/lib/python3.10/site-packages/tensorflow/python/util/traceback_utils.py", line 153, in error_handler
    raise e.with_traceback(filtered_tb) from None
  File "/tmp/tactician.tmp.KzuMtE/target-source/venv/lib/python3.10/site-packages/keras/layers/core/tf_op_layer.py", line 107, in handle
    return TFOpLambda(op)(*args, **kwargs)
  File "/tmp/tactician.tmp.KzuMtE/target-source/venv/lib/python3.10/site-packages/keras/utils/traceback_utils.py", line 67, in error_handler
    raise e.with_traceback(filtered_tb) from None
ValueError: Exception encountered when calling layer "tf.math.top_k" (type TFOpLambda).

input must have last dimension >= k = 2048 but is 1247 for '{{node tf.math.top_k/TopKV2}} = TopKV2[T=DT_FLOAT, sorted=true](Placeholder, tf.math.top_k/TopKV2/k)' with input shapes: [?,1247], [] and with computed input tensors: input[1] = <2048>.

Call arguments received by layer "tf.math.top_k" (type TFOpLambda):
  • input=tf.Tensor(shape=(None, 1247), dtype=float32)
  • k=2048
  • sorted=True
  • name=None
File "./theories/Data/Eq.v", line 56, characters 2-9:
Error:
Anomaly "Uncaught exception Unix.Unix_error(Unix.EPIPE, "single_write", "")."
Please report at http://coq.inria.fr/bugs/.

Traceback (most recent call last):
  File "/tmp/tactician.tmp.KzuMtE/target-source/venv/bin/g2t-server", line 33, in <module>
    sys.exit(load_entry_point('graph2tac==0.1.0', 'console_scripts', 'g2t-server')())
  File "/tmp/tactician.tmp.KzuMtE/target-source/venv/lib/python3.10/site-packages/graph2tac/loader/predict_server.py", line 967, in main
    main_with_return_value()
  File "/tmp/tactician.tmp.KzuMtE/target-source/venv/lib/python3.10/site-packages/graph2tac/loader/predict_server.py", line 922, in main_with_return_value
    model = load_model(config, log_levels)
  File "/tmp/tactician.tmp.KzuMtE/target-source/venv/lib/python3.10/site-packages/graph2tac/loader/predict_server.py", line 871, in load_model
    model = TFGNNPredict(log_dir=Path(config.model).expanduser().absolute(),
  File "/tmp/tactician.tmp.KzuMtE/target-source/venv/lib/python3.10/site-packages/graph2tac/tfgnn/predict.py", line 620, in __init__
    self._compile_network()
  File "/tmp/tactician.tmp.KzuMtE/target-source/venv/lib/python3.10/site-packages/graph2tac/tfgnn/predict.py", line 685, in _compile_network
    inference_model_bare = self.prediction_task.create_inference_model(
  File "/tmp/tactician.tmp.KzuMtE/target-source/venv/lib/python3.10/site-packages/graph2tac/tfgnn/tasks.py", line 1343, in create_inference_model
    tactic, top_k_values = self._top_k_tactics(tactic_logits=tactic_logits,
  File "/tmp/tactician.tmp.KzuMtE/target-source/venv/lib/python3.10/site-packages/graph2tac/tfgnn/tasks.py", line 561, in _top_k_tactics
    top_k = tf.math.top_k(tactic_logits, k=tactic_expand_bound)
  File "/tmp/tactician.tmp.KzuMtE/target-source/venv/lib/python3.10/site-packages/tensorflow/python/util/traceback_utils.py", line 153, in error_handler
    raise e.with_traceback(filtered_tb) from None
  File "/tmp/tactician.tmp.KzuMtE/target-source/venv/lib/python3.10/site-packages/keras/layers/core/tf_op_layer.py", line 107, in handle
    return TFOpLambda(op)(*args, **kwargs)
  File "/tmp/tactician.tmp.KzuMtE/target-source/venv/lib/python3.10/site-packages/keras/utils/traceback_utils.py", line 67, in error_handler
    raise e.with_traceback(filtered_tb) from None
ValueError: Exception encountered when calling layer "tf.math.top_k" (type TFOpLambda).

input must have last dimension >= k = 2048 but is 1247 for '{{node tf.math.top_k/TopKV2}} = TopKV2[T=DT_FLOAT, sorted=true](Placeholder, tf.math.top_k/TopKV2/k)' with input shapes: [?,1247], [] and with computed input tensors: input[1] = <2048>.

Call arguments received by layer "tf.math.top_k" (type TFOpLambda):
  • input=tf.Tensor(shape=(None, 1247), dtype=float32)
  • k=2048
  • sorted=True
  • name=None
File "./theories/Core/RelDec.v", line 50, characters 9-60:
Error:
Anomaly "Uncaught exception Unix.Unix_error(Unix.EPIPE, "single_write", "")."
Please report at http://coq.inria.fr/bugs/.

File "./Field_affine.v", line 210, characters 0-7:
Error:
Anomaly "Uncaught exception Unix.Unix_error(Unix.EPIPE, "single_write", "")."
Please report at http://coq.inria.fr/bugs/.

Traceback (most recent call last):
  File "/tmp/tactician.tmp.KzuMtE/target-source/venv/bin/g2t-server", line 33, in <module>
    sys.exit(load_entry_point('graph2tac==0.1.0', 'console_scripts', 'g2t-server')())
  File "/tmp/tactician.tmp.KzuMtE/target-source/venv/lib/python3.10/site-packages/graph2tac/loader/predict_server.py", line 967, in main
    main_with_return_value()
  File "/tmp/tactician.tmp.KzuMtE/target-source/venv/lib/python3.10/site-packages/graph2tac/loader/predict_server.py", line 922, in main_with_return_value
    model = load_model(config, log_levels)
  File "/tmp/tactician.tmp.KzuMtE/target-source/venv/lib/python3.10/site-packages/graph2tac/loader/predict_server.py", line 871, in load_model
    model = TFGNNPredict(log_dir=Path(config.model).expanduser().absolute(),
  File "/tmp/tactician.tmp.KzuMtE/target-source/venv/lib/python3.10/site-packages/graph2tac/tfgnn/predict.py", line 620, in __init__
    self._compile_network()
  File "/tmp/tactician.tmp.KzuMtE/target-source/venv/lib/python3.10/site-packages/graph2tac/tfgnn/predict.py", line 685, in _compile_network
    inference_model_bare = self.prediction_task.create_inference_model(
  File "/tmp/tactician.tmp.KzuMtE/target-source/venv/lib/python3.10/site-packages/graph2tac/tfgnn/tasks.py", line 1343, in create_inference_model
    tactic, top_k_values = self._top_k_tactics(tactic_logits=tactic_logits,
  File "/tmp/tactician.tmp.KzuMtE/target-source/venv/lib/python3.10/site-packages/graph2tac/tfgnn/tasks.py", line 561, in _top_k_tactics
    top_k = tf.math.top_k(tactic_logits, k=tactic_expand_bound)
  File "/tmp/tactician.tmp.KzuMtE/target-source/venv/lib/python3.10/site-packages/tensorflow/python/util/traceback_utils.py", line 153, in error_handler
    raise e.with_traceback(filtered_tb) from None
  File "/tmp/tactician.tmp.KzuMtE/target-source/venv/lib/python3.10/site-packages/keras/layers/core/tf_op_layer.py", line 107, in handle
    return TFOpLambda(op)(*args, **kwargs)
  File "/tmp/tactician.tmp.KzuMtE/target-source/venv/lib/python3.10/site-packages/keras/utils/traceback_utils.py", line 67, in error_handler
    raise e.with_traceback(filtered_tb) from None
ValueError: Exception encountered when calling layer "tf.math.top_k" (type TFOpLambda).

input must have last dimension >= k = 2048 but is 1247 for '{{node tf.math.top_k/TopKV2}} = TopKV2[T=DT_FLOAT, sorted=true](Placeholder, tf.math.top_k/TopKV2/k)' with input shapes: [?,1247], [] and with computed input tensors: input[1] = <2048>.

Call arguments received by layer "tf.math.top_k" (type TFOpLambda):
  • input=tf.Tensor(shape=(None, 1247), dtype=float32)
  • k=2048
  • sorted=True
  • name=None
File "./theories/Data/Z.v", line 30, characters 2-21:
Error:
Anomaly "Uncaught exception Unix.Unix_error(Unix.EPIPE, "single_write", "")."
Please report at http://coq.inria.fr/bugs/.

File "/tmp/tactician.tmp.KzuMtE/opam-root/bench/lib/coq/user-contrib/Tactician/Graph2TacConfig.v", line 1, characters 0-32:
Warning: There is no option Tactician Neural Truncate.
[unknown-option,option]
Traceback (most recent call last):
  File "/tmp/tactician.tmp.KzuMtE/target-source/venv/bin/g2t-server", line 33, in <module>
    sys.exit(load_entry_point('graph2tac==0.1.0', 'console_scripts', 'g2t-server')())
  File "/tmp/tactician.tmp.KzuMtE/target-source/venv/lib/python3.10/site-packages/graph2tac/loader/predict_server.py", line 967, in main
    main_with_return_value()
  File "/tmp/tactician.tmp.KzuMtE/target-source/venv/lib/python3.10/site-packages/graph2tac/loader/predict_server.py", line 922, in main_with_return_value
    model = load_model(config, log_levels)
  File "/tmp/tactician.tmp.KzuMtE/target-source/venv/lib/python3.10/site-packages/graph2tac/loader/predict_server.py", line 871, in load_model
    model = TFGNNPredict(log_dir=Path(config.model).expanduser().absolute(),
  File "/tmp/tactician.tmp.KzuMtE/target-source/venv/lib/python3.10/site-packages/graph2tac/tfgnn/predict.py", line 620, in __init__
    self._compile_network()
  File "/tmp/tactician.tmp.KzuMtE/target-source/venv/lib/python3.10/site-packages/graph2tac/tfgnn/predict.py", line 685, in _compile_network
    inference_model_bare = self.prediction_task.create_inference_model(
  File "/tmp/tactician.tmp.KzuMtE/target-source/venv/lib/python3.10/site-packages/graph2tac/tfgnn/tasks.py", line 1343, in create_inference_model
    tactic, top_k_values = self._top_k_tactics(tactic_logits=tactic_logits,
  File "/tmp/tactician.tmp.KzuMtE/target-source/venv/lib/python3.10/site-packages/graph2tac/tfgnn/tasks.py", line 561, in _top_k_tactics
    top_k = tf.math.top_k(tactic_logits, k=tactic_expand_bound)
  File "/tmp/tactician.tmp.KzuMtE/target-source/venv/lib/python3.10/site-packages/tensorflow/python/util/traceback_utils.py", line 153, in error_handler
    raise e.with_traceback(filtered_tb) from None
  File "/tmp/tactician.tmp.KzuMtE/target-source/venv/lib/python3.10/site-packages/keras/layers/core/tf_op_layer.py", line 107, in handle
    return TFOpLambda(op)(*args, **kwargs)
  File "/tmp/tactician.tmp.KzuMtE/target-source/venv/lib/python3.10/site-packages/keras/utils/traceback_utils.py", line 67, in error_handler
    raise e.with_traceback(filtered_tb) from None
ValueError: Exception encountered when calling layer "tf.math.top_k" (type TFOpLambda).

input must have last dimension >= k = 2048 but is 1247 for '{{node tf.math.top_k/TopKV2}} = TopKV2[T=DT_FLOAT, sorted=true](Placeholder, tf.math.top_k/TopKV2/k)' with input shapes: [?,1247], [] and with computed input tensors: input[1] = <2048>.

Call arguments received by layer "tf.math.top_k" (type TFOpLambda):
  • input=tf.Tensor(shape=(None, 1247), dtype=float32)
  • k=2048
  • sorted=True
  • name=None
File "./theories/Data/Nat.v", line 35, characters 2-21:
Error:
Anomaly "Uncaught exception Unix.Unix_error(Unix.EPIPE, "single_write", "")."
Please report at http://coq.inria.fr/bugs/.

File "./theories/Data/Z.v", line 38, characters 2-21:
Error:
Anomaly "Uncaught exception Unix.Unix_error(Unix.EPIPE, "single_write", "")."
Please report at http://coq.inria.fr/bugs/.

File "./parallelisme_concours.v", line 452, characters 0-34:
Error:
Anomaly "Uncaught exception Unix.Unix_error(Unix.EPIPE, "single_write", "")."
Please report at http://coq.inria.fr/bugs/.

File "./theories/Data/Nat.v", line 40, characters 2-21:
Error:
Anomaly "Uncaught exception Unix.Unix_error(Unix.EPIPE, "single_write", "")."
Please report at http://coq.inria.fr/bugs/.

File "/tmp/tactician.tmp.KzuMtE/opam-root/bench/lib/coq/user-contrib/Tactician/Graph2TacConfig.v", line 1, characters 0-32:
Warning: There is no option Tactician Neural Truncate.
[unknown-option,option]
File "/tmp/tactician.tmp.KzuMtE/opam-root/bench/lib/coq/user-contrib/Tactician/Graph2TacConfig.v", line 1, characters 0-32:
Warning: There is no option Tactician Neural Truncate.
[unknown-option,option]
File "./theories/Tactics/Consider.v", line 99, characters 4-26:
Error:
Anomaly "Uncaught exception Unix.Unix_error(Unix.EPIPE, "single_write", "")."
Please report at http://coq.inria.fr/bugs/.

File "/tmp/tactician.tmp.KzuMtE/opam-root/bench/lib/coq/user-contrib/Tactician/Graph2TacConfig.v", line 1, characters 0-32:
Warning: There is no option Tactician Neural Truncate.
[unknown-option,option]
File "/tmp/tactician.tmp.KzuMtE/opam-root/bench/lib/coq/user-contrib/Tactician/Graph2TacConfig.v", line 1, characters 0-32:
Warning: There is no option Tactician Neural Truncate.
[unknown-option,option]
Traceback (most recent call last):
  File "/tmp/tactician.tmp.KzuMtE/target-source/venv/bin/g2t-server", line 33, in <module>
    sys.exit(load_entry_point('graph2tac==0.1.0', 'console_scripts', 'g2t-server')())
  File "/tmp/tactician.tmp.KzuMtE/target-source/venv/lib/python3.10/site-packages/graph2tac/loader/predict_server.py", line 967, in main
    main_with_return_value()
  File "/tmp/tactician.tmp.KzuMtE/target-source/venv/lib/python3.10/site-packages/graph2tac/loader/predict_server.py", line 922, in main_with_return_value
    model = load_model(config, log_levels)
  File "/tmp/tactician.tmp.KzuMtE/target-source/venv/lib/python3.10/site-packages/graph2tac/loader/predict_server.py", line 871, in load_model
    model = TFGNNPredict(log_dir=Path(config.model).expanduser().absolute(),
  File "/tmp/tactician.tmp.KzuMtE/target-source/venv/lib/python3.10/site-packages/graph2tac/tfgnn/predict.py", line 620, in __init__
    self._compile_network()
  File "/tmp/tactician.tmp.KzuMtE/target-source/venv/lib/python3.10/site-packages/graph2tac/tfgnn/predict.py", line 685, in _compile_network
    inference_model_bare = self.prediction_task.create_inference_model(
  File "/tmp/tactician.tmp.KzuMtE/target-source/venv/lib/python3.10/site-packages/graph2tac/tfgnn/tasks.py", line 1343, in create_inference_model
    tactic, top_k_values = self._top_k_tactics(tactic_logits=tactic_logits,
  File "/tmp/tactician.tmp.KzuMtE/target-source/venv/lib/python3.10/site-packages/graph2tac/tfgnn/tasks.py", line 561, in _top_k_tactics
    top_k = tf.math.top_k(tactic_logits, k=tactic_expand_bound)
  File "/tmp/tactician.tmp.KzuMtE/target-source/venv/lib/python3.10/site-packages/tensorflow/python/util/traceback_utils.py", line 153, in error_handler
    raise e.with_traceback(filtered_tb) from None
  File "/tmp/tactician.tmp.KzuMtE/target-source/venv/lib/python3.10/site-packages/keras/layers/core/tf_op_layer.py", line 107, in handle
    return TFOpLambda(op)(*args, **kwargs)
  File "/tmp/tactician.tmp.KzuMtE/target-source/venv/lib/python3.10/site-packages/keras/utils/traceback_utils.py", line 67, in error_handler
    raise e.with_traceback(filtered_tb) from None
ValueError: Exception encountered when calling layer "tf.math.top_k" (type TFOpLambda).

input must have last dimension >= k = 2048 but is 1247 for '{{node tf.math.top_k/TopKV2}} = TopKV2[T=DT_FLOAT, sorted=true](Placeholder, tf.math.top_k/TopKV2/k)' with input shapes: [?,1247], [] and with computed input tensors: input[1] = <2048>.

Call arguments received by layer "tf.math.top_k" (type TFOpLambda):
  • input=tf.Tensor(shape=(None, 1247), dtype=float32)
  • k=2048
  • sorted=True
  • name=None
File "./theories/Tactics/Consider.v", line 83, characters 4-39:
Error:
Anomaly "Uncaught exception Unix.Unix_error(Unix.EPIPE, "single_write", "")."
Please report at http://coq.inria.fr/bugs/.

Traceback (most recent call last):
  File "/tmp/tactician.tmp.KzuMtE/target-source/venv/bin/g2t-server", line 33, in <module>
    sys.exit(load_entry_point('graph2tac==0.1.0', 'console_scripts', 'g2t-server')())
  File "/tmp/tactician.tmp.KzuMtE/target-source/venv/lib/python3.10/site-packages/graph2tac/loader/predict_server.py", line 967, in main
    main_with_return_value()
  File "/tmp/tactician.tmp.KzuMtE/target-source/venv/lib/python3.10/site-packages/graph2tac/loader/predict_server.py", line 922, in main_with_return_value
    model = load_model(config, log_levels)
  File "/tmp/tactician.tmp.KzuMtE/target-source/venv/lib/python3.10/site-packages/graph2tac/loader/predict_server.py", line 871, in load_model
    model = TFGNNPredict(log_dir=Path(config.model).expanduser().absolute(),
  File "/tmp/tactician.tmp.KzuMtE/target-source/venv/lib/python3.10/site-packages/graph2tac/tfgnn/predict.py", line 620, in __init__
    self._compile_network()
  File "/tmp/tactician.tmp.KzuMtE/target-source/venv/lib/python3.10/site-packages/graph2tac/tfgnn/predict.py", line 685, in _compile_network
    inference_model_bare = self.prediction_task.create_inference_model(
  File "/tmp/tactician.tmp.KzuMtE/target-source/venv/lib/python3.10/site-packages/graph2tac/tfgnn/tasks.py", line 1343, in create_inference_model
    tactic, top_k_values = self._top_k_tactics(tactic_logits=tactic_logits,
  File "/tmp/tactician.tmp.KzuMtE/target-source/venv/lib/python3.10/site-packages/graph2tac/tfgnn/tasks.py", line 561, in _top_k_tactics
    top_k = tf.math.top_k(tactic_logits, k=tactic_expand_bound)
  File "/tmp/tactician.tmp.KzuMtE/target-source/venv/lib/python3.10/site-packages/tensorflow/python/util/traceback_utils.py", line 153, in error_handler
    raise e.with_traceback(filtered_tb) from None
  File "/tmp/tactician.tmp.KzuMtE/target-source/venv/lib/python3.10/site-packages/keras/layers/core/tf_op_layer.py", line 107, in handle
    return TFOpLambda(op)(*args, **kwargs)
  File "/tmp/tactician.tmp.KzuMtE/target-source/venv/lib/python3.10/site-packages/keras/utils/traceback_utils.py", line 67, in error_handler
    raise e.with_traceback(filtered_tb) from None
ValueError: Exception encountered when calling layer "tf.math.top_k" (type TFOpLambda).

input must have last dimension >= k = 2048 but is 1247 for '{{node tf.math.top_k/TopKV2}} = TopKV2[T=DT_FLOAT, sorted=true](Placeholder, tf.math.top_k/TopKV2/k)' with input shapes: [?,1247], [] and with computed input tensors: input[1] = <2048>.

Call arguments received by layer "tf.math.top_k" (type TFOpLambda):
  • input=tf.Tensor(shape=(None, 1247), dtype=float32)
  • k=2048
  • sorted=True
  • name=None
Traceback (most recent call last):
  File "/tmp/tactician.tmp.KzuMtE/target-source/venv/bin/g2t-server", line 33, in <module>
    sys.exit(load_entry_point('graph2tac==0.1.0', 'console_scripts', 'g2t-server')())
  File "/tmp/tactician.tmp.KzuMtE/target-source/venv/lib/python3.10/site-packages/graph2tac/loader/predict_server.py", line 967, in main
    main_with_return_value()
  File "/tmp/tactician.tmp.KzuMtE/target-source/venv/lib/python3.10/site-packages/graph2tac/loader/predict_server.py", line 922, in main_with_return_value
    model = load_model(config, log_levels)
  File "/tmp/tactician.tmp.KzuMtE/target-source/venv/lib/python3.10/site-packages/graph2tac/loader/predict_server.py", line 871, in load_model
    model = TFGNNPredict(log_dir=Path(config.model).expanduser().absolute(),
  File "/tmp/tactician.tmp.KzuMtE/target-source/venv/lib/python3.10/site-packages/graph2tac/tfgnn/predict.py", line 620, in __init__
    self._compile_network()
  File "/tmp/tactician.tmp.KzuMtE/target-source/venv/lib/python3.10/site-packages/graph2tac/tfgnn/predict.py", line 685, in _compile_network
    inference_model_bare = self.prediction_task.create_inference_model(
  File "/tmp/tactician.tmp.KzuMtE/target-source/venv/lib/python3.10/site-packages/graph2tac/tfgnn/tasks.py", line 1343, in create_inference_model
    tactic, top_k_values = self._top_k_tactics(tactic_logits=tactic_logits,
  File "/tmp/tactician.tmp.KzuMtE/target-source/venv/lib/python3.10/site-packages/graph2tac/tfgnn/tasks.py", line 561, in _top_k_tactics
    top_k = tf.math.top_k(tactic_logits, k=tactic_expand_bound)
  File "/tmp/tactician.tmp.KzuMtE/target-source/venv/lib/python3.10/site-packages/tensorflow/python/util/traceback_utils.py", line 153, in error_handler
    raise e.with_traceback(filtered_tb) from None
  File "/tmp/tactician.tmp.KzuMtE/target-source/venv/lib/python3.10/site-packages/keras/layers/core/tf_op_layer.py", line 107, in handle
    return TFOpLambda(op)(*args, **kwargs)
  File "/tmp/tactician.tmp.KzuMtE/target-source/venv/lib/python3.10/site-packages/keras/utils/traceback_utils.py", line 67, in error_handler
    raise e.with_traceback(filtered_tb) from None
ValueError: Exception encountered when calling layer "tf.math.top_k" (type TFOpLambda).

input must have last dimension >= k = 2048 but is 1247 for '{{node tf.math.top_k/TopKV2}} = TopKV2[T=DT_FLOAT, sorted=true](Placeholder, tf.math.top_k/TopKV2/k)' with input shapes: [?,1247], [] and with computed input tensors: input[1] = <2048>.

Call arguments received by layer "tf.math.top_k" (type TFOpLambda):
  • input=tf.Tensor(shape=(None, 1247), dtype=float32)
  • k=2048
  • sorted=True
  • name=None
Traceback (most recent call last):
  File "/tmp/tactician.tmp.KzuMtE/target-source/venv/bin/g2t-server", line 33, in <module>
    sys.exit(load_entry_point('graph2tac==0.1.0', 'console_scripts', 'g2t-server')())
  File "/tmp/tactician.tmp.KzuMtE/target-source/venv/lib/python3.10/site-packages/graph2tac/loader/predict_server.py", line 967, in main
    main_with_return_value()
  File "/tmp/tactician.tmp.KzuMtE/target-source/venv/lib/python3.10/site-packages/graph2tac/loader/predict_server.py", line 922, in main_with_return_value
    model = load_model(config, log_levels)
  File "/tmp/tactician.tmp.KzuMtE/target-source/venv/lib/python3.10/site-packages/graph2tac/loader/predict_server.py", line 871, in load_model
    model = TFGNNPredict(log_dir=Path(config.model).expanduser().absolute(),
  File "/tmp/tactician.tmp.KzuMtE/target-source/venv/lib/python3.10/site-packages/graph2tac/tfgnn/predict.py", line 620, in __init__
    self._compile_network()
  File "/tmp/tactician.tmp.KzuMtE/target-source/venv/lib/python3.10/site-packages/graph2tac/tfgnn/predict.py", line 685, in _compile_network
    inference_model_bare = self.prediction_task.create_inference_model(
  File "/tmp/tactician.tmp.KzuMtE/target-source/venv/lib/python3.10/site-packages/graph2tac/tfgnn/tasks.py", line 1343, in create_inference_model
    tactic, top_k_values = self._top_k_tactics(tactic_logits=tactic_logits,
  File "/tmp/tactician.tmp.KzuMtE/target-source/venv/lib/python3.10/site-packages/graph2tac/tfgnn/tasks.py", line 561, in _top_k_tactics
    top_k = tf.math.top_k(tactic_logits, k=tactic_expand_bound)
  File "/tmp/tactician.tmp.KzuMtE/target-source/venv/lib/python3.10/site-packages/tensorflow/python/util/traceback_utils.py", line 153, in error_handler
    raise e.with_traceback(filtered_tb) from None
  File "/tmp/tactician.tmp.KzuMtE/target-source/venv/lib/python3.10/site-packages/keras/layers/core/tf_op_layer.py", line 107, in handle
    return TFOpLambda(op)(*args, **kwargs)
  File "/tmp/tactician.tmp.KzuMtE/target-source/venv/lib/python3.10/site-packages/keras/utils/traceback_utils.py", line 67, in error_handler
    raise e.with_traceback(filtered_tb) from None
ValueError: Exception encountered when calling layer "tf.math.top_k" (type TFOpLambda).

input must have last dimension >= k = 2048 but is 1247 for '{{node tf.math.top_k/TopKV2}} = TopKV2[T=DT_FLOAT, sorted=true](Placeholder, tf.math.top_k/TopKV2/k)' with input shapes: [?,1247], [] and with computed input tensors: input[1] = <2048>.

Call arguments received by layer "tf.math.top_k" (type TFOpLambda):
  • input=tf.Tensor(shape=(None, 1247), dtype=float32)
  • k=2048
  • sorted=True
  • name=None
File "./theories/Data/Z.v", line 46, characters 2-21:
Error:
Anomaly "Uncaught exception Unix.Unix_error(Unix.EPIPE, "single_write", "")."
Please report at http://coq.inria.fr/bugs/.

File "/tmp/tactician.tmp.KzuMtE/opam-root/bench/lib/coq/user-contrib/Tactician/Graph2TacConfig.v", line 1, characters 0-32:
Warning: There is no option Tactician Neural Truncate.
[unknown-option,option]
File "./theories/Data/Nat.v", line 45, characters 2-21:
Error:
Anomaly "Uncaught exception Unix.Unix_error(Unix.EPIPE, "single_write", "")."
Please report at http://coq.inria.fr/bugs/.

File "./theories/Data/Z.v", line 54, characters 2-21:
Error:
Anomaly "Uncaught exception Unix.Unix_error(Unix.EPIPE, "single_write", "")."
Please report at http://coq.inria.fr/bugs/.

Traceback (most recent call last):
  File "/tmp/tactician.tmp.KzuMtE/target-source/venv/bin/g2t-server", line 33, in <module>
    sys.exit(load_entry_point('graph2tac==0.1.0', 'console_scripts', 'g2t-server')())
  File "/tmp/tactician.tmp.KzuMtE/target-source/venv/lib/python3.10/site-packages/graph2tac/loader/predict_server.py", line 967, in main
    main_with_return_value()
  File "/tmp/tactician.tmp.KzuMtE/target-source/venv/lib/python3.10/site-packages/graph2tac/loader/predict_server.py", line 922, in main_with_return_value
    model = load_model(config, log_levels)
  File "/tmp/tactician.tmp.KzuMtE/target-source/venv/lib/python3.10/site-packages/graph2tac/loader/predict_server.py", line 871, in load_model
    model = TFGNNPredict(log_dir=Path(config.model).expanduser().absolute(),
  File "/tmp/tactician.tmp.KzuMtE/target-source/venv/lib/python3.10/site-packages/graph2tac/tfgnn/predict.py", line 620, in __init__
    self._compile_network()
  File "/tmp/tactician.tmp.KzuMtE/target-source/venv/lib/python3.10/site-packages/graph2tac/tfgnn/predict.py", line 685, in _compile_network
    inference_model_bare = self.prediction_task.create_inference_model(
  File "/tmp/tactician.tmp.KzuMtE/target-source/venv/lib/python3.10/site-packages/graph2tac/tfgnn/tasks.py", line 1343, in create_inference_model
    tactic, top_k_values = self._top_k_tactics(tactic_logits=tactic_logits,
  File "/tmp/tactician.tmp.KzuMtE/target-source/venv/lib/python3.10/site-packages/graph2tac/tfgnn/tasks.py", line 561, in _top_k_tactics
    top_k = tf.math.top_k(tactic_logits, k=tactic_expand_bound)
  File "/tmp/tactician.tmp.KzuMtE/target-source/venv/lib/python3.10/site-packages/tensorflow/python/util/traceback_utils.py", line 153, in error_handler
    raise e.with_traceback(filtered_tb) from None
  File "/tmp/tactician.tmp.KzuMtE/target-source/venv/lib/python3.10/site-packages/keras/layers/core/tf_op_layer.py", line 107, in handle
    return TFOpLambda(op)(*args, **kwargs)
  File "/tmp/tactician.tmp.KzuMtE/target-source/venv/lib/python3.10/site-packages/keras/utils/traceback_utils.py", line 67, in error_handler
    raise e.with_traceback(filtered_tb) from None
ValueError: Exception encountered when calling layer "tf.math.top_k" (type TFOpLambda).

input must have last dimension >= k = 2048 but is 1247 for '{{node tf.math.top_k/TopKV2}} = TopKV2[T=DT_FLOAT, sorted=true](Placeholder, tf.math.top_k/TopKV2/k)' with input shapes: [?,1247], [] and with computed input tensors: input[1] = <2048>.

Call arguments received by layer "tf.math.top_k" (type TFOpLambda):
  • input=tf.Tensor(shape=(None, 1247), dtype=float32)
  • k=2048
  • sorted=True
  • name=None
File "./theories/Data/Nat.v", line 51, characters 2-21:
Error:
Anomaly "Uncaught exception Unix.Unix_error(Unix.EPIPE, "single_write", "")."
Please report at http://coq.inria.fr/bugs/.

